Workbook

Sheet Proposta Comercial 
B3: Planilha de Orçamento | Q3: MARGEM DE MATERIAL | Y3: MARGEM DE M.O
B4: Cliente: KABOCABANA Obra: Baia (Sorocaba) Proprietária: Projetos base orçamento: ORÇAMENTO ESTIMATIVO Nós nas redes: https://veksengenharia.com/ https://www.instagram.com/veksengenharia/ | Q4: MARGEM BRUTA | S4: MARGEM LIQUIDA | Y4: MARGEM BRUTA | AA4: MARGEM LIQUIDA
B6: 1.0 - SERVIÇOS - | Q6: 0.35 | S6: 0.15 | Y6: 0.35 | AA6: 0.13
Q7: Cálculo de preço de venda de material | Z7: Cálculo de preço de venda de material | AH7: HOTEL | AI7: DIARIA | AJ7: HOMEM | AK7: TOTAL
B8: ITEM | C8: DESCRIÇÃO | D8: UNID. | E8: QUANT. | F8: CUSTO UNIT. MAT. | G8: CUSTO UNIT. M.O. | H8: R$ TOTAL MAT. | I8: R$ TOTAL M.O. | J8: CUSTO TOTAL | K8: MAT VENDA | L8: M.O. VENDA | M8: TOTAL MATERIAL | N8: TOTAL M.O. | O8: TOTAL | Q8: MARGEM BRUTA | R8: Imposto (%) | S8: Lucro (%) | T8: Preço de custo | U8: Preço de venda | V8: Imposto (R$) | W8: Lucro (R$) | Y8: MARGEM BRUTA | Z8: Imposto (%) | AA8: Lucro (%) | AB8: Preço de custo | AC8: Preço de venda | AD8: Imposto (R$) | AE8: Lucro (R$) | AH8: 90 | AI8: 4 | AJ8: 3 | AK8: =AH8*AJ8*AI8 -> 1080
B9: 1 | C9: Execução de baias
B10: 1.1 | C10: Estrutura em Aço Galvanizado a frio (LSF) Z275 para area de cobertura e muretas. Incluso todos os insumos como fixações, parafusos, etc. | D10: vb | E10: 1 | F10: =(23000*13)+20000 -> 319000 | G10: =7*23000 -> 161000 | H10: =ROUND(F10*E10,2) -> 319000 | I10: =ROUND(G10*E10,2) -> 161000 | J10: =ROUND((F10+G10)*E10,2) -> 480000 | K10: =U10 -> 425333.33 | L10: =AC10 -> 309615.38 | M10: =ROUND(K10*E10,2) -> 425333.33 | N10: =ROUND(L10*E10,2) -> 309615.38 | O10: =ROUND((K10+L10)*E10,2) -> 734948.72 | Q10: =(K10/F10)-1 -> 0.33333333 | S10: 0.25 | T10: =F10 -> 319000 | U10: =T10/(1-S10-R10) -> 425333.33 | V10: =U10*R10 -> 0 | W10: =U10-V10-T10 -> 106333.33 | Y10: =(L10/G10)-1 -> 0.92307692 | Z10: 0.13 | AA10: 0.35 | AB10: =G10 -> 161000 | AC10: =AB10/(1-AA10-Z10) -> 309615.38 | AD10: =AC10*Z10 -> 40250 | AE10: =AC10-AD10-AB10 -> 108365.38
B11: 1.2 | C11: Pintura da estrutura do telhado e fundo de OSB do telhado shingle | D11: m² | E11: 1700 | F11: 0 | G11: 35 | H11: =ROUND(F11*E11,2) -> 0 | I11: =ROUND(G11*E11,2) -> 59500 | J11: =ROUND((F11+G11)*E11,2) -> 59500 | K11: =U11 -> 0 | L11: =AC11 -> 61.403509 | M11: =ROUND(K11*E11,2) -> 0 | N11: =ROUND(L11*E11,2) -> 104385.96 | O11: =ROUND((K11+L11)*E11,2) -> 104385.96 | Q11: =(K11/F11)-1 -> #DIV/0! | S11: 0.2 | T11: =F11 -> 0 | U11: =T11/(1-S11-R11) -> 0 | V11: =U11*R11 -> 0 | W11: =U11-V11-T11 -> 0 | Y11: =(L11/G11)-1 -> 0.75438596 | Z11: 0.13 | AA11: 0.3 | AB11: =G11 -> 35 | AC11: =AB11/(1-AA11-Z11) -> 61.403509 | AD11: =AC11*Z11 -> 7.9824561 | AE11: =AC11-AD11-AB11 -> 18.421053
B12: 1.3 | C12: Fechamento em reguas de pinus nas areas de parede, cercado e portão | D12: m² | E12: 1700 | F12: 0 | G12: 63 | H12: =ROUND(F12*E12,2) -> 0 | I12: =ROUND(G12*E12,2) -> 107100 | J12: =ROUND((F12+G12)*E12,2) -> 107100 | K12: =U12 -> 0 | L12: =AC12 -> 110.52632 | M12: =ROUND(K12*E12,2) -> 0 | N12: =ROUND(L12*E12,2) -> 187894.74 | O12: =ROUND((K12+L12)*E12,2) -> 187894.74 | Q12: =(K12/F12)-1 -> #DIV/0! | S12: 0.2 | T12: =F12 -> 0 | U12: =T12/(1-S12-R12) -> 0 | V12: =U12*R12 -> 0 | W12: =U12-V12-T12 -> 0 | Y12: =(L12/G12)-1 -> 0.75438596 | Z12: 0.13 | AA12: 0.3 | AB12: =G12 -> 63 | AC12: =AB12/(1-AA12-Z12) -> 110.52632 | AD12: =AC12*Z12 -> 14.368421 | AE12: =AC12-AD12-AB12 -> 33.157895
B13: 1.4 | C13: Estruturação e verticalização de Pilares roliços de tronco de eucalipto para apoio da estrutura LSF incluindo sapatas e concreto | D13: vb | E13: 1 | F13: 0 | G13: 50000 | H13: =ROUND(F13*E13,2) -> 0 | I13: =ROUND(G13*E13,2) -> 50000 | J13: =ROUND((F13+G13)*E13,2) -> 50000 | K13: =U13 -> 0 | L13: =AC13 -> 87719.298 | M13: =ROUND(K13*E13,2) -> 0 | N13: =ROUND(L13*E13,2) -> 87719.3 | O13: =ROUND((K13+L13)*E13,2) -> 87719.3 | Q13: =(K13/F13)-1 -> #DIV/0! | S13: 0.2 | T13: =F13 -> 0 | U13: =T13/(1-S13-R13) -> 0 | V13: =U13*R13 -> 0 | W13: =U13-V13-T13 -> 0 | Y13: =(L13/G13)-1 -> 0.75438596 | Z13: 0.13 | AA13: 0.3 | AB13: =G13 -> 50000 | AC13: =AB13/(1-AA13-Z13) -> 87719.298 | AD13: =AC13*Z13 -> 11403.509 | AE13: =AC13-AD13-AB13 -> 26315.789
B14: 1.5 | C14: Corredor de passagem com 2m de largura em concreto desempenado camurçado, incluso concreto | D14: vb | E14: 1 | F14: =1200*24.2 -> 29040 | G14: =484*35 -> 16940 | H14: =ROUND(F14*E14,2) -> 29040 | I14: =ROUND(G14*E14,2) -> 16940 | J14: =ROUND((F14+G14)*E14,2) -> 45980 | K14: =U14 -> 36300 | L14: =AC14 -> 29719.298 | M14: =ROUND(K14*E14,2) -> 36300 | N14: =ROUND(L14*E14,2) -> 29719.3 | O14: =ROUND((K14+L14)*E14,2) -> 66019.3 | Q14: =(K14/F14)-1 -> 0.25 | S14: 0.2 | T14: =F14 -> 29040 | U14: =T14/(1-S14-R14) -> 36300 | V14: =U14*R14 -> 0 | W14: =U14-V14-T14 -> 7260 | Y14: =(L14/G14)-1 -> 0.75438596 | Z14: 0.13 | AA14: 0.3 | AB14: =G14 -> 16940 | AC14: =AB14/(1-AA14-Z14) -> 29719.298 | AD14: =AC14*Z14 -> 3863.5088 | AE14: =AC14-AD14-AB14 -> 8915.7895
B15: 1.6 | C15: Revestimento em pedra moledo em pilares em até 1m de altura | D15: m² | E15: 80 | F15: 0 | G15: 230 | H15: =ROUND(F15*E15,2) -> 0 | I15: =ROUND(G15*E15,2) -> 18400 | J15: =ROUND((F15+G15)*E15,2) -> 18400 | K15: =U15 -> 0 | L15: =AC15 -> 403.50877 | M15: =ROUND(K15*E15,2) -> 0 | N15: =ROUND(L15*E15,2) -> 32280.7 | O15: =ROUND((K15+L15)*E15,2) -> 32280.7 | Q15: =(K15/F15)-1 -> #DIV/0! | S15: 0.2 | T15: =F15 -> 0 | U15: =T15/(1-S15-R15) -> 0 | V15: =U15*R15 -> 0 | W15: =U15-V15-T15 -> 0 | Y15: =(L15/G15)-1 -> 0.75438596 | Z15: 0.13 | AA15: 0.3 | AB15: =G15 -> 230 | AC15: =AB15/(1-AA15-Z15) -> 403.50877 | AD15: =AC15*Z15 -> 52.45614 | AE15: =AC15-AD15-AB15 -> 121.05263
B16: 1.7 | C16: Arandelas de iluminação nos 44 pilares de tronco e 1 ponto de iluminação em cada baia | D16: un. | E16: 1 | F16: 0 | G16: 12000 | H16: =ROUND(F16*E16,2) -> 0 | I16: =ROUND(G16*E16,2) -> 12000 | J16: =ROUND((F16+G16)*E16,2) -> 12000 | K16: =U16 -> 0 | L16: =AC16 -> 21052.632 | M16: =ROUND(K16*E16,2) -> 0 | N16: =ROUND(L16*E16,2) -> 21052.63 | O16: =ROUND((K16+L16)*E16,2) -> 21052.63 | Q16: =(K16/F16)-1 -> #DIV/0! | S16: 0.2 | T16: =F16 -> 0 | U16: =T16/(1-S16-R16) -> 0 | V16: =U16*R16 -> 0 | W16: =U16-V16-T16 -> 0 | Y16: =(L16/G16)-1 -> 0.75438596 | Z16: 0.13 | AA16: 0.3 | AB16: =G16 -> 12000 | AC16: =AB16/(1-AA16-Z16) -> 21052.632 | AD16: =AC16*Z16 -> 2736.8421 | AE16: =AC16-AD16-AB16 -> 6315.7895
H17: =SUM(H9:H16) -> 348040 | I17: =SUM(I9:I16) -> 424940 | J17: =SUM(J9:J16) -> 772980 | M17: =SUM(M9:M16) -> 461633.33 | N17: =SUM(N9:N16) -> 772668.01 | O17: =SUM(O9:O16) -> 1234301.3 | Z17: 0.13
AH18: CUSTO COM TRANSP | AJ18: 1578.8
H19: R$ TOTAL MAT. | I19: R$ TOTAL M.O. | J19: R$ CUSTO TOTAL | M19: TOTAL MATERIAIS | N19: TOTAL MÃO DE OBRA | O19: TOTAL VENDA | Q19: Imposto (16%) | R19: Adm (10%) | S19: Lucro Liquido | T19: Margen Liquida (25%) | U19: BDI | V19: 533.16 | W19: =V19 -> 533.16
V20: =O21/V19 -> 2315.0674 | W20: =J21/W19 -> 1449.8087
B21: Valor Total do Projeto | H21: =H17 -> 348040 | I21: =I17 -> 424940 | J21: =J17 -> 772980 | M21: =M17 -> 461633.33 | N21: =N17 -> 772668.01 | O21: =O17 -> 1234301.3 | Q21: =O21*0.13 -> 160459.18 | R21: =O21*0.1 -> 123430.13 | S21: =O21-J21-Q21-R21-Q25 -> 177432.04 | T21: =S21/O21 -> 0.14375099 | U21: =(O21/J21)-1 -> 0.59680891
B23: Validade da proposta: 10 DIAS
B24: FORMA DE PAGAMENTO: | Q24: comissão 1,5%
B25: Garantia sobre o serviço de 5 anos. ESSE ORÇAMENTO ESTÁ BASEADO EM UMA ESTIMATIVA PRAZO de 50 dias trabalhados | Q25: 0
B28: VEKS ENGENHARIA - ORÇAMENTOS (12) 98863-4553

Sheet Memorial de calculo
B3: PISO - Porcelanato
B4: METRAGEM | C4: 1 | D4: 0.2 | E4: =D4*J6 -> 34.578 | F4: Locais:
B5: Material | C5: valores un | D5: quant p/ un | E5: Prod. | F5: Un. Ultil | H5: Quant. | I5: Preço | J5: Sub Total | K5: Total | L5: Valor por m²
B6: PORCELANATO (m²) | C6: 62.89 | D6: - | E6: 1 | F6: =C4*E6 -> 1 | G6: =D6*B4 -> #VALUE! | H6: =E6*C4 -> 1 | I6: =F6*C6 -> 62.89 | J6: =SUM(I6:I8) -> 172.89 | K6: =J6+E4 -> 207.468 | L6: =K6/C4 -> 207.468
B7: CIMENTO (sc) | C7: 35 | D7: 20 | E7: 8 | F7: =E7*C4 -> 8 | G7: =F7/D7 -> 0.4 | H7: =CEILING(G7,1) -> 1 | I7: =H7*C7 -> 35
B8: REJUNTE (sc) | C8: 75 | D8: 5 | E8: 1 | F8: =E8*C4 -> 1 | G8: =F8/D8 -> 0.2 | H8: =CEILING(G8,1) -> 1 | I8: =H8*C8 -> 75
B10: PAREDE - Revestimento
B11: METRAGEM | C11: 1 | D11: 0.2 | E11: =D11*J13 -> 32.098 | F11: Locais:
B12: Material | C12: valores un | D12: quant p/ un | E12: Prod. | F12: Un. Ultil | H12: Quant. | I12: Preço | J12: Sub Total | K12: Total | L12: Valor por m²
B13: PORCELANATO (m²) | C13: 50.49 | D13: - | E13: 1 | F13: =C11*E13 -> 1 | G13: =D13*B11 -> #VALUE! | H13: =E13*C11 -> 1 | I13: =F13*C13 -> 50.49 | J13: =SUM(I13:I15) -> 160.49 | K13: =J13+E11 -> 192.588 | L13: =K13/C11 -> 192.588
B14: CIMENTO (sc) | C14: 35 | D14: 20 | E14: 8 | F14: =E14*C11 -> 8 | G14: =F14/D14 -> 0.4 | H14: =CEILING(G14,1) -> 1 | I14: =H14*C14 -> 35
B15: REJUNTE (sc) | C15: 75 | D15: 5 | E15: 1 | F15: =E15*C11 -> 1 | G15: =F15/D15 -> 0.2 | H15: =CEILING(G15,1) -> 1 | I15: =H15*C15 -> 75
B19: METRAGEM DE AREAS
B20: DESCRIÇÃO | C20: X | D20: Y | E20: M²
B21: AREA DE CONSTRUÇÃO | C21: 20.2 | D21: 9.71 | E21: =C21*D21 -> 196.142
B22: PLAQUEAMENTO EXTERNO | C22: =(20.2*2)+(9.71*2) -> 59.82 | D22: 5.67 | E22: =C22*D22 -> 339.1794
B23: PLAQUEAMENTO INTERNO | C23: =(9.71*8)+(4*2)+(2.4*2)+(20.2*2)+(2.5*4)+(1.5*2)+(2.5*2)+(1.6*2) -> 152.08 | D23: 4.09 | E23: =C23*D23 -> 622.0072
B24: RU | C24: =(3*2)+(4.2*2)+(2.5*4)+(1.5*4) -> 30.4 | D24: 3.92 | E24: =C24*D24 -> 119.168
B25: ST | C25: =C23-C24 -> 121.68 | D25: - | E25: =E23-E24 -> 502.8392
B26: FORRO | C26: 20.2 | D26: 9.71 | E26: =C26*D26 -> 196.142
B30: TEMPO DE EXECUÇÃO
B31: DESCRIÇÃO | C31: QUANTIDADE | D31: MEDIA | E31: DIAS | F31: TOTAL DIAS | H31: MÊS
B32: RADIER | C32: - | D32: - | E32: 15 | F32: =SUM(E32:E39) -> 88.345533 | G32: =F32/22 -> 4.0157061 | H32: =ROUNDUP(G32/1,0) -> 5
B33: AÇO | C33: 5600 | D33: 700 | E33: =C33/D33 -> 8
B34: FECHAMENTO EXT | C34: =E22 -> 339.1794 | D34: 15 | E34: =C34/D34 -> 22.61196
B35: FECHAMENTO INT | C35: =E23 -> 622.0072 | D35: 30 | E35: =C35/D35 -> 20.733573
B36: ELÉTRICA | C36: - | D36: - | E36: 22
B37: REVESTIMENTO PISO | C37: - | D37: -
B38: REVESTIMENTO PAREDE | C38: - | D38: -
B39: ACESSÓRIOS | C39: - | D39: -
B42: INSTALAÇÕES HIDRAULICAS
B43: DESCRIÇÃO | C43: MEDIDA | D43: QUANT. | E43: V. UNIT. MA | F43: V. TOTAL MA | H43: V. UNIT. MO | I43: V. TOTAL MO | J43: TOTAL
B44: Bacia sanitaria deca com caixa aclopada | C44: UNID | D44: 8 | E44: 610 | F44: =E44*D44 -> 4880 | H44: 150 | I44: =H44*D44 -> 1200 | J44: =I44+F44 -> 6080
B45: Cuba de imbutir oval, deca, cor branca | C45: UNID | D45: 6 | E45: 150 | F45: =E45*D45 -> 900 | H45: 50 | I45: =H45*D45 -> 300 | J45: =I45+F45 -> 1200
B46: Bancada para lavatório em granito cinza andorinha | C46: M² | D46: 4.24 | E46: 838.66 | F46: =E46*D46 -> 3555.9184 | H46: 150 | I46: =H46*D46 -> 636 | J46: =I46+F46 -> 4191.9184
B47: Lavatorio vougle | C47: UNID | D47: 1 | E47: 350 | F47: =E47*D47 -> 350 | H47: 150 | I47: =H47*D47 -> 150 | J47: =I47+F47 -> 500
B48: Torneira para lavatorio de mesa. DECA | C48: UNID | D48: 7 | E48: 200 | F48: =E48*D48 -> 1400 | H48: 5 | I48: =H48*D48 -> 35 | J48: =I48+F48 -> 1435
B49: Mictorio com sifão integrado e entrada de agua embutida | C49: UNID | D49: 2 | E49: 650 | F49: =E49*D49 -> 1300 | H49: 150 | I49: =H49*D49 -> 300 | J49: =I49+F49 -> 1600
B50: Ralo redondo | C50: UNID | D50: 4 | E50: 40 | F50: =E50*D50 -> 160 | H50: 5 | I50: =H50*D50 -> 20 | J50: =I50+F50 -> 180
B51: Dispenser titanium para papel higienico rolão, santher | C51: UNID. | D51: 8 | E51: 115 | F51: =E51*D51 -> 920 | H51: 5 | I51: =H51*D51 -> 40 | J51: =I51+F51 -> 960
...

Sheet RESUMO CUSTOS 
B2: Área Terreno | C2: 0 | D2: m2
B3: Área de Radier | C3: 0 | D3: m2
B4: Área PavimentoTérreo de Obra | C4: 0 | D4: m2
B5: Área Segundo Pavimento | D5: m2
B6: Total | C6: 0 | D6: m2
B8: Local Saída | C8: SJC | D8: 30
B9: Local Obra | C9: Mauá | D9: 30
B10: Custo km rodado por Viagem | D10: 0.8
B11: Custo total de ida | D11: =D10*D9 -> 24
B12: Custo total volta | D12: =D10*D9 -> 24
B13: Custo pedágio ida e volta | D13: 14
B14: Custo total | D14: =SUM(D11:D13) -> 62
B16: HOSPEDAGEM airbnb | C16: VALOR MENSAL | D16: MESES DE OBRA | E16: VALOR TOTAL PELA OBRA
C17: 0 | D17: 1 | E17: =C17*D17 -> 0
B18: TOTAL DIAS EM OBRA | C18: ='Fundação '!C44+'Aço '!C44+Cobertura!C44+'Plaqueamento Interno '!C44+'Revestimento '!C44+Muro!C44+'Instalação Portas'!C44+'Pintura '!C44 -> 156.5
B19: Custo total | E19: =E17 -> 0
B23: Demolição | C23: 7500
B24: FUNDAÇÃO | C24: ='Fundação '!E53 -> 49714 | D24: =C6 -> 0 | E24: =C24/D24 -> #DIV/0!
B25: MONTAGEM AÇO | C25: ='Aço '!D46 -> 145050.55 | D25: =C6 -> 0 | E25: =C25/D25 -> #DIV/0!
B26: COBERTURA | C26: =Cobertura!D46 -> 9277.8182 | D26: =C6 -> 0 | E26: =C26/D26 -> #DIV/0!
B27: PLAQUEAMENTO INTERNO | C27: ='Plaqueamento Interno '!D46 -> 18228.773 | D27: =C6 -> 0 | E27: =C27/D27 -> #DIV/0!
B28: PLAQUEAMENTO EXTERNO | C28: ='Plaqueamento Externo'!D46+20000 -> 41343.273 | D28: =C6 -> 0 | E28: =C28/D28 -> #DIV/0!
B30: HIDR | C30: 15000
B31: ELE | C31: 15000
B34: TOTAL | C34: =SUM(C24:C31) -> 293614.41
C35: =C34/C6 -> #DIV/0!

Sheet Fundação 
B2: Local saída da equipe SJC | C2: 0 | D2: km
B3: Local da obra Mauá | C3: 0 | D3: km
B4: Custo km rodado por Viagem | C4: 0.8
B5: Custo total de ida | C5: =C4*C3 -> 0
B6: Custo total volta | C6: =C4*C3 -> 0
B7: Custo pedágio ida e volta | C7: ='RESUMO CUSTOS '!D13 -> 14
B8: Custo total | C8: =SUM(C5:C7) -> 14
B10: HOSPEDAGEM airbnb | C10: VALOR MENSAL | D10: MESES DE OBRA | E10: VALOR TOTAL PELA OBRA
C11: 0 | D11: 1 | E11: =C11*D11 -> 0
B12: Custo total | E12: =E11 -> 0
C15: DIÁRIA | D15: DIAS TRABALHADOS MÊS | E15: SALÁRIO | F15: REFEIÇÃO | G15: TOTAL
B16: Engenheiro residente | E16: 7500 | F16: =22*50 -> 1100 | G16: =E16+F16 -> 8600
B17: Encarregado | E17: 5500 | F17: =22*50 -> 1100 | G17: =F17+E17 -> 6600
B18: Pedreiro | C18: 200 | D18: 22 | E18: =D18*C18 -> 4400 | F18: =22*50 -> 1100 | G18: =E18+F18 -> 5500
B19: Meio Oficial | C19: 150 | D19: 22 | E19: =D19*C19 -> 3300 | F19: =22*50 -> 1100 | G19: =E19+F19 -> 4400
B20: Ajudante | C20: 120 | D20: 22 | E20: =D20*C20 -> 2640 | F20: =22*50 -> 1100 | G20: =E20+F20 -> 3740
B22: EQUIPE PARA OBRA
B23: Engenheiro residente | E23: 0 | F23: =G16 -> 8600 | G23: =F23*E23 -> 0
B24: Encarregado | E24: 1 | F24: =G17 -> 6600 | G24: =F24*E24 -> 6600
B25: Pedreiro | E25: 2 | F25: =G18 -> 5500 | G25: =F25*E25 -> 11000
B26: Meio Oficial | E26: 1 | F26: =G19 -> 4400 | G26: =F26*E26 -> 4400
B27: Ajudante | E27: 1 | F27: =G20 -> 3740 | G27: =F27*E27 -> 3740
B30: TOTAL MÊS | G30: =SUM(G23:G27) -> 25740
B31: Total dia | G31: =G30/22 -> 1170
B34: TRANSPORTE GUILHERME | C34: km | D34: R$ / km | E34: CUSTO POR KM | F34: IDA E VOLTA | G34: TOTAL
C35: =C3 -> 0 | D35: 1 | E35: =D35*C35 -> 0 | F35: =E35*2 -> 0 | G35: =F35 -> 0
B36: PEDÁGIO | G36: =C7 -> 14
C37: VALOR DA DIÁRIA | D37: DIÁRIAS | E37: HOTEL + REFEIÇÃO
B38: DIÁRIA DA VISITA | C38: 1000 | D38: 2 | E38: 450 | G38: =(C38+E38)*D38 -> 2900
B39: Total visita Guilherme | G39: =SUM(G34:G38) -> 2914
B41: RESUMO | C41: COEFICIENTE | D41: VALOR TOTAL
B42: Viagem de equipe para montagem aço 2 viagens | C42: 0 | D42: =C8*C42 -> 0
B43: Hospedagem | C43: 0 | D43: =E12*C43 -> 0
B44: Equipe | C44: 40 | D44: =G31*C44 -> 46800
B45: Visita Guilherme | C45: 1 | D45: =G39*C45 -> 2914
B46: Custo Geral | C46: 0 | D46: =SUM(D42:D45) -> 49714
C47: =C50 -> 0 | D47: =D46/C47 -> #DIV/0!
B50: Area Radier m² | C50: ='RESUMO CUSTOS '!C3 -> 0 | D50: 0 | E50: =D50*C50 -> 0
B51: Frete para ferramentas km rodado | C51: 0 | D51: 0 | E51: =D51*C51 -> 0
B52: Hospedagem | E52: 0
...

Sheet Aço 
B2: Local saída da equipe SJC | C2: 30 | D2: km | G2: AREA CASA | H2: ='RESUMO CUSTOS '!C6 -> 0
B3: Local da obra Mauá | C3: 30 | D3: km | G3: taxa aço por m2 35kg/m2 | H3: =H2*32 -> 0 | I3: kg de lsf
B4: Custo km rodado por Viagem | C4: 0.8 | H4: =H3/400 -> 0 | I4: dias
B5: Custo total de ida | C5: =C4*C3 -> 24
B6: Custo total volta | C6: =C4*C3 -> 24
B7: Custo pedágio ida e volta | C7: 0
B8: Custo total | C8: =SUM(C5:C7) -> 48
B10: HOSPEDAGEM airbnb | C10: VALOR MENSAL | D10: MESES DE OBRA | E10: VALOR TOTAL PELA OBRA
C11: 3500 | D11: 0 | E11: =C11*D11 -> 0
B12: Custo total | E12: =E11 -> 0
C15: DIÁRIA | D15: DIAS TRABALHADOS MÊS | E15: SALÁRIO | F15: REFEIÇÃO | G15: TOTAL
B16: Engenheiro residente | E16: 7000 | F16: =D18*30 -> 780 | G16: =E16+F16 -> 7780
B17: Encarregado | E17: 5000 | F17: =D18*30 -> 780 | G17: =F17+E17 -> 5780
B18: Montador lider | C18: 250 | D18: 26 | E18: =D18*C18 -> 6500 | F18: =D18*30 -> 780 | G18: =E18+F18 -> 7280
B19: Montador | C19: 180 | D19: 26 | E19: =D19*C19 -> 4680 | F19: =D19*30 -> 780 | G19: =E19+F19 -> 5460
B20: Ajudante | C20: 160 | D20: 26 | E20: =D20*C20 -> 4160 | F20: =D20*30 -> 780 | G20: =E20+F20 -> 4940
B22: EQUIPE PARA OBRA
B23: Engenheiro residente | E23: 1 | F23: =G16 -> 7780 | G23: =F23*E23 -> 7780
B24: Encarregado | E24: 1 | F24: =G17 -> 5780 | G24: =F24*E24 -> 5780
B25: Montador lider | E25: 1 | F25: =G18 -> 7280 | G25: =F25*E25 -> 7280
B26: Montador | E26: 2 | F26: =G19 -> 5460 | G26: =F26*E26 -> 10920
B27: Ajudante | E27: 2 | F27: =G20 -> 4940 | G27: =F27*E27 -> 9880
B30: TOTAL MÊS | G30: =SUM(G23:G27) -> 41640
B31: Total dia | G31: =G30/22 -> 1892.7273
B34: TRANSPORTE GUILHERME | C34: km | D34: R$ / km | E34: CUSTO POR KM | F34: IDA E VOLTA | G34: TOTAL
C35: =C3 -> 30 | D35: 0.8 | E35: =D35*C35 -> 24 | F35: =E35*2 -> 48 | G35: =F35 -> 48
B36: PEDÁGIO | G36: =C7 -> 0
C37: VALOR DA DIÁRIA | D37: DIÁRIAS
B38: DIÁRIA DA VISITA | C38: 500 | D38: 3 | G38: =C38*D38 -> 1500 | I38: =15000/30 -> 500
B39: Total visita Guilherme | G39: =SUM(G34:G38) -> 1548
B41: RESUMO | C41: Nº DE VIAGENS | D41: VALOR TOTAL
B42: Viagem de equipe para montagem aço 2 viagens | C42: 0 | D42: =C8*C42 -> 0
B43: Hospedagem | C43: 0 | D43: =C11*C43 -> 0
B44: Equipe | C44: 75 | D44: =C44*G31 -> 141954.55
B45: Visita Guilherme | C45: 2 | D45: =G39*C45 -> 3096
B46: Custo Geral | D46: =SUM(D42:D45) -> 145050.55
C47: 26000 | D47: =D46/C47 -> 5.5788671
D50: =6*C47 -> 156000

Sheet Cobertura
B2: Local saída da equipe SJC | C2: 0 | D2: km | G2: AREA CASA | H2: 430
B3: Local da obra Mauá | C3: ='RESUMO CUSTOS '!D9 -> 30 | D3: km
B4: Custo km rodado por Viagem | C4: 0.8
B5: Custo total de ida | C5: =C4*C3 -> 24
B6: Custo total volta | C6: =C4*C3 -> 24
B7: Custo pedágio ida e volta | C7: 14
B8: Custo total | C8: =SUM(C5:C7) -> 62
B10: HOSPEDAGEM airbnb | C10: VALOR MENSAL | D10: MESES DE OBRA | E10: VALOR TOTAL PELA OBRA
C11: 3500 | D11: 0 | E11: =C11*D11 -> 0
B12: Custo total | E12: =E11 -> 0
C15: DIÁRIA | D15: DIAS TRABALHADOS MÊS | E15: SALÁRIO | F15: REFEIÇÃO | G15: TOTAL
B16: Engenheiro residente | E16: 7500 | F16: =22*22 -> 484 | G16: =E16+F16 -> 7984
B17: Encarregado | E17: 10000 | F17: =22*22 -> 484 | G17: =F17+E17 -> 10484
B18: Montador lider | C18: 250 | D18: 22 | E18: =D18*C18 -> 5500 | F18: =22*22 -> 484 | G18: =E18+F18 -> 5984
B19: Montador | C19: 180 | D19: 22 | E19: =D19*C19 -> 3960 | F19: =22*22 -> 484 | G19: =E19+F19 -> 4444
B20: Ajudante | C20: 160 | D20: 22 | E20: =D20*C20 -> 3520 | F20: =22*22 -> 484 | G20: =E20+F20 -> 4004
B22: EQUIPE PARA OBRA
B23: Engenheiro residente | E23: 1 | F23: =G16 -> 7984 | G23: =F23*E23 -> 7984
B24: Encarregado | E24: 1 | F24: =G17 -> 10484 | G24: =F24*E24 -> 10484
B25: Montador lider | E25: 1 | F25: =G18 -> 5984 | G25: =F25*E25 -> 5984
B26: Montador | E26: 1 | F26: =G19 -> 4444 | G26: =F26*E26 -> 4444
B27: Ajudante | E27: 1 | F27: =G20 -> 4004 | G27: =F27*E27 -> 4004
B30: TOTAL MÊS | G30: =SUM(G23:G27) -> 32900
B31: Total dia | G31: =G30/22 -> 1495.4545
B34: TRANSPORTE GUILHERME | C34: km | D34: R$ / km | E34: CUSTO POR KM | F34: IDA E VOLTA | G34: TOTAL
C35: =C3 -> 30 | D35: 1 | E35: =D35*C35 -> 30 | F35: =E35*2 -> 60 | G35: =F35 -> 60
B36: PEDÁGIO | G36: =C7 -> 14
C37: VALOR DA DIÁRIA | D37: DIÁRIAS | E37: HOTEL + REFEIÇÃO
B38: DIÁRIA DA VISITA | C38: 1000 | D38: 1 | E38: 450 | G38: =(C38+E38)*D38 -> 1450
B39: Total visita Guilherme | G39: =SUM(G34:G38) -> 1524
B41: RESUMO | C41: COEFICIENTE | D41: VALOR TOTAL
B42: Viagem de equipe para montagem aço 2 viagens | C42: 4 | D42: =C8*C42 -> 248
B43: Hospedagem | C43: 0 | D43: =E12*C43 -> 0
B44: Equipe | C44: 4 | D44: =G31*C44 -> 5981.8182
B45: Visita Guilherme | C45: 2 | D45: =G39*C45 -> 3048
B46: Custo Geral | D46: =SUM(D42:D45) -> 9277.8182
C47: ='RESUMO CUSTOS '!C6 -> 0 | D47: =D46/C47 -> #DIV/0!

Sheet Plaqueamento Interno 
B2: Local saída da equipe SJC | C2: 30 | D2: km | G2: AREA CASA | H2: ='Aço '!H2 -> 0
B3: Local da obra Mauá | C3: 30 | D3: km
B4: Custo km rodado por Viagem | C4: 0.8 | G4: plaqueamento interno terreo | H4: 1502.13 | I4: m2 | K4: plaqueamento interno 2o pav | N4: 0 | O4: m2
B5: Custo total de ida | C5: =C4*C3 -> 24 | G5: 1 homen | H5: =H4/30 -> 50.071 | K5: 1 homen | N5: =N4/30 -> 0
B6: Custo total volta | C6: =C4*C3 -> 24 | G6: 2 homens | H6: =H4/60 -> 25.0355 | K6: 2 homens | N6: =N4/60 -> 0
B7: Custo pedágio ida e volta | C7: 0 | G7: 3 homens | H7: =H4/90 -> 16.690333 | K7: 3 homens | N7: =N4/90 -> 0
B8: Custo total | C8: =SUM(C5:C7) -> 48
G9: plaqueamento interno 3o pav | H9: 0 | I9: m2 | K9: plaqueamento interno 4o pav | N9: 0 | O9: m2
B10: HOSPEDAGEM airbnb | C10: VALOR MENSAL | D10: MESES DE OBRA | E10: VALOR TOTAL PELA OBRA | G10: 1 homen | H10: =H9/30 -> 0 | K10: 1 homen | N10: =N9/30 -> 0
C11: 3500 | D11: 0 | E11: =C11*D11 -> 0 | G11: 2 homens | H11: =H9/60 -> 0 | K11: 2 homens | N11: =N9/60 -> 0
B12: Custo total | E12: =E11 -> 0 | G12: 3 homens | H12: =H9/90 -> 0 | K12: 3 homens | N12: =N9/90 -> 0
C15: DIÁRIA | D15: DIAS TRABALHADOS MÊS | E15: SALÁRIO | F15: REFEIÇÃO | G15: TOTAL | I15: =H4+H9+N9 -> 1502.13 | J15: m2 | M15: =H7+N7+H12+N12 -> 16.690333
B16: Engenheiro residente | E16: 7000 | F16: =D18*30 -> 780 | G16: =E16+F16 -> 7780
B17: Encarregado | E17: 5000 | F17: =D18*30 -> 780 | G17: =F17+E17 -> 5780
B18: Montador lider | C18: 250 | D18: 26 | E18: =D18*C18 -> 6500 | F18: =D18*30 -> 780 | G18: =E18+F18 -> 7280
B19: Montador | C19: 180 | D19: 26 | E19: =D19*C19 -> 4680 | F19: =D19*30 -> 780 | G19: =E19+F19 -> 5460
B20: Ajudante | C20: 160 | D20: 26 | E20: =D20*C20 -> 4160 | F20: =D20*30 -> 780 | G20: =E20+F20 -> 4940
B22: EQUIPE PARA OBRA
B23: Engenheiro residente | E23: 0.15 | F23: =G16 -> 7780 | G23: =F23*E23 -> 1167
B24: Encarregado | E24: 0.5 | F24: =G17 -> 5780 | G24: =F24*E24 -> 2890
B25: Montador lider | E25: 1 | F25: =G18 -> 7280 | G25: =F25*E25 -> 7280
B26: Montador | E26: 1 | F26: =G19 -> 5460 | G26: =F26*E26 -> 5460
B27: Ajudante | E27: 1 | F27: =G20 -> 4940 | G27: =F27*E27 -> 4940
B30: TOTAL MÊS | G30: =SUM(G23:G27) -> 21737
B31: Total dia | G31: =G30/22 -> 988.04545
B34: TRANSPORTE GUILHERME | C34: km | D34: R$ / km | E34: CUSTO POR KM | F34: IDA E VOLTA | G34: TOTAL
C35: =C3 -> 30 | D35: 0.8 | E35: =D35*C35 -> 24 | F35: =E35*2 -> 48 | G35: =F35 -> 48
B36: PEDÁGIO | G36: =C7 -> 0
C37: VALOR DA DIÁRIA | D37: DIÁRIAS
B38: DIÁRIA DA VISITA | C38: 500 | D38: 1 | G38: =C38*D38 -> 500
B39: Total visita Guilherme | G39: =SUM(G34:G38) -> 548
B41: RESUMO | C41: Nº DE VIAGENS | D41: VALOR TOTAL
B42: Viagem de equipe para montagem aço 2 viagens | C42: 7 | D42: =C8*C42 -> 336
B43: Hospedagem | C43: 0 | D43: =C43*C11 -> 0
B44: Equipe | C44: 17 | D44: =G31*C44 -> 16796.773
B45: Visita Guilherme | C45: 2 | D45: =G39*C45 -> 1096
B46: Custo Geral | D46: =SUM(D42:D45) -> 18228.773
C47: 1502.13 | D47: =D46/C47 -> 12.135283
D53: caixa dágua 1
D55: comprimento paredes externas | E55: altura | F55: area externa (m²) | G55: Area interna | H55: Area total
...

Sheet Plaqueamento Externo
B2: Local saída da equipe SJC | C2: 30 | D2: km | G2: AREA CASA | H2: ='Aço '!H2 -> 0
B3: ='Fundação '!B3 -> Local da obra Mauá | C3: 30 | D3: km
B4: Custo km rodado por Viagem | C4: 0.8 | G4: plaqueamento interno | H4: 526.61 | I4: m2
B5: Custo total de ida | C5: =C4*C3 -> 24 | G5: 1 homen | H5: =H4/30 -> 17.553667
B6: Custo total volta | C6: =C4*C3 -> 24 | G6: 2 homens | H6: =H4/60 -> 8.7768333
B7: Custo pedágio ida e volta | C7: 0 | G7: 3 homens | H7: =H4/90 -> 5.8512222
B8: Custo total | C8: =SUM(C5:C7) -> 48
G9: plaqueamento fachada | H9: 0 | I9: m2
B10: HOSPEDAGEM airbnb | C10: VALOR MENSAL | D10: MESES DE OBRA | E10: VALOR TOTAL PELA OBRA | G10: 1 homen | H10: =H9/40 -> 0 | I10: =H10*2 -> 0
C11: 3500 | D11: 0 | E11: =C11*D11 -> 0 | G11: 2 homens | H11: =H9/80 -> 0 | I11: =H11*2 -> 0
B12: Custo total | E12: =E11 -> 0 | G12: 3 homens | H12: =H9/120 -> 0 | I12: =H12*2 -> 0
C15: DIÁRIA | D15: DIAS TRABALHADOS MÊS | E15: SALÁRIO | F15: REFEIÇÃO | G15: TOTAL
B16: Engenheiro residente | E16: 7000 | F16: =D18*22 -> 572 | G16: =E16+F16 -> 7572
B17: Encarregado | E17: 5000 | F17: =D18*22 -> 572 | G17: =F17+E17 -> 5572
B18: Montador lider | C18: 250 | D18: 26 | E18: =D18*C18 -> 6500 | F18: =D18*22 -> 572 | G18: =E18+F18 -> 7072
B19: Montador | C19: 180 | D19: 26 | E19: =D19*C19 -> 4680 | F19: =D19*22 -> 572 | G19: =E19+F19 -> 5252
B20: Ajudante | C20: 160 | D20: 26 | E20: =D20*C20 -> 4160 | F20: =D20*22 -> 572 | G20: =E20+F20 -> 4732
B22: EQUIPE PARA OBRA
B23: Engenheiro residente | E23: 0.3 | F23: =G16 -> 7572 | G23: =F23*E23 -> 2271.6
B24: Encarregado | E24: 0.5 | F24: =G17 -> 5572 | G24: =F24*E24 -> 2786
B25: Montador lider | E25: 1 | F25: =G18 -> 7072 | G25: =F25*E25 -> 7072
B26: Montador | E26: 1 | F26: =G19 -> 5252 | G26: =F26*E26 -> 5252
B27: Ajudante | E27: 1 | F27: =G20 -> 4732 | G27: =F27*E27 -> 4732
B30: TOTAL MÊS | G30: =SUM(G23:G27) -> 22113.6
B31: Total dia | G31: =G30/22 -> 1005.1636
B34: TRANSPORTE GUILHERME | C34: km | D34: R$ / km | E34: CUSTO POR KM | F34: IDA E VOLTA | G34: TOTAL
C35: =C3 -> 30 | D35: 0.8 | E35: =D35*C35 -> 24 | F35: =E35*2 -> 48 | G35: =F35 -> 48
B36: PEDÁGIO | G36: =C7 -> 0
C37: VALOR DA DIÁRIA | D37: DIÁRIAS
B38: DIÁRIA DA VISITA | C38: 500 | D38: 1 | G38: =C38*D38 -> 500
B39: Total visita Guilherme | G39: =SUM(G34:G38) -> 548
B41: RESUMO | C41: Nº DE VIAGENS | D41: VALOR TOTAL
B42: Viagem de equipe para montagem aço 2 viagens | C42: 3 | D42: =C8*C42 -> 144
B43: Hospedagem | C43: 0 | D43: =C43*C11 -> 0
B44: Equipe | C44: 20 | D44: =G31*C44 -> 20103.273 | F44: BASE COALT | G44: =H9 -> 0 | H44: =G44*2 -> 0
B45: Visita Guilherme | C45: 2 | D45: =G39*C45 -> 1096 | G45: =19*6.8 -> 129.2 | H45: =H44+G45 -> 129.2 | I45: =H45*30 -> 3876
B46: Custo Geral | D46: =SUM(D42:D45) -> 21343.273 | G46: =(23+23+6+6)*6 -> 348 | H46: =G46*60 -> 20880
C47: 526.61 | D47: =D46/C47 -> 40.529562
D53: caixa dágua 1
D55: comprimento paredes externas | E55: altura | F55: area externa (m²) | G55: Area interna | H55: Area total
...

Sheet Revestimento 
B2: Local saída da equipe SJC | C2: 0 | D2: km
B3: ='Fundação '!B3 -> Local da obra Mauá | C3: 0 | D3: km
B4: Custo km rodado por Viagem | C4: 0.8
B5: Custo total de ida | C5: =C4*C3 -> 0
B6: Custo total volta | C6: =C4*C3 -> 0
B7: Custo pedágio ida e volta | C7: =91.6*2 -> 183.2
B8: Custo total | C8: =SUM(C5:C7) -> 183.2
B10: HOSPEDAGEM airbnb | C10: VALOR MENSAL | D10: MESES DE OBRA | E10: VALOR TOTAL PELA OBRA
C11: 3500 | D11: 0.5 | E11: =C11*D11 -> 1750
B12: Custo total | E12: =E11 -> 1750
C15: DIÁRIA | D15: DIAS TRABALHADOS MÊS | E15: SALÁRIO | F15: REFEIÇÃO | G15: TOTAL
B16: Engenheiro residente | E16: 4500 | F16: =22*50 -> 1100 | G16: =E16+F16 -> 5600
B17: Encarregado | E17: 10000 | F17: =22*50 -> 1100 | G17: =F17+E17 -> 11100
B18: Montador lider | C18: 180 | D18: 22 | E18: =D18*C18 -> 3960 | F18: =50*30 -> 1500 | G18: =E18+F18 -> 5460
B19: Montador | C19: 160 | D19: 22 | E19: =D19*C19 -> 3520 | F19: =50*30 -> 1500 | G19: =E19+F19 -> 5020
B20: Ajudante | C20: 120 | D20: 22 | E20: =D20*C20 -> 2640 | F20: =50*30 -> 1500 | G20: =E20+F20 -> 4140
B22: EQUIPE PARA OBRA
B23: Engenheiro residente | E23: 0.8 | F23: =G16 -> 5600 | G23: =F23*E23 -> 4480
B24: Encarregado | E24: 0.7 | F24: =G17 -> 11100 | G24: =F24*E24 -> 7770
B25: Montador lider
B26: Montador
B27: Ajudante
B30: TOTAL MÊS | G30: =SUM(G23:G27) -> 12250
B31: Total dia | G31: =G30/22 -> 556.81818
B34: TRANSPORTE GUILHERME | C34: km | D34: R$ / km | E34: CUSTO POR KM | F34: IDA E VOLTA | G34: TOTAL
C35: =C3 -> 0 | D35: 1 | E35: =D35*C35 -> 0 | F35: =E35*2 -> 0 | G35: =F35 -> 0
B36: PEDÁGIO | G36: =C7 -> 183.2
C37: VALOR DA DIÁRIA | D37: DIÁRIAS
B38: DIÁRIA DA VISITA | C38: 1000 | D38: 2 | G38: =C38*D38 -> 2000
B39: Total visita Guilherme | G39: =SUM(G34:G38) -> 2183.2
B41: RESUMO | C41: Nº DE VIAGENS | D41: VALOR TOTAL
B42: Viagem de equipe para montagem aço 2 viagens | C42: 2 | D42: =C8*C42 -> 366.4
B43: Hospedagem | C43: 0.5 | D43: =C11*C43 -> 1750
B44: Equipe | C44: 1.5 | D44: =G30*C44 -> 18375
B45: Visita Guilherme | C45: 1 | D45: =G39*C45 -> 2183.2
B46: Custo Geral | D46: =SUM(D42:D45) -> 22674.6
C47: 360 | D47: =D46/C47 -> 62.985
B49: Piso | C49: 60 | D49: 360 | E49: =D49*C49 -> 21600
B50: transporte | E50: =D42 -> 366.4
E51: =D43 -> 1750
...

Sheet Muro
B2: Local saída da equipe SJC | C2: 0 | D2: km | G2: AREA CASA | H2: 193.17
B3: ='Fundação '!B3 -> Local da obra Mauá | C3: 0 | D3: km | G3: Numero de casas | H3: 1
B4: Custo km rodado por Viagem | C4: 0.8 | G4: Metragem total | H4: =H3*H2 -> 193.17 | I4: m2
B5: Custo total de ida | C5: =C4*C3 -> 0
B6: Custo total volta | C6: =C4*C3 -> 0
B7: Custo pedágio ida e volta | C7: =91.6*2 -> 183.2
B8: Custo total | C8: =SUM(C5:C7) -> 183.2
B10: HOSPEDAGEM airbnb | C10: VALOR MENSAL | D10: MESES DE OBRA | E10: VALOR TOTAL PELA OBRA
C11: 0 | D11: 1 | E11: =C11*D11 -> 0
B12: Custo total | E12: =E11 -> 0
C15: DIÁRIA | D15: DIAS TRABALHADOS MÊS | E15: SALÁRIO | F15: REFEIÇÃO | G15: TOTAL
B16: Engenheiro residente | E16: 7500 | F16: =22*50 -> 1100 | G16: =E16+F16 -> 8600
B17: Encarregado | E17: 5500 | F17: =22*50 -> 1100 | G17: =F17+E17 -> 6600
B18: Pedreiro | C18: 150 | D18: 22 | E18: =D18*C18 -> 3300 | F18: =50*30 -> 1500 | G18: =E18+F18 -> 4800
B19: Meio Oficial | C19: 120 | D19: 22 | E19: =D19*C19 -> 2640 | F19: =50*30 -> 1500 | G19: =E19+F19 -> 4140
B20: Ajudante | C20: 100 | D20: 22 | E20: =D20*C20 -> 2200 | F20: =50*30 -> 1500 | G20: =E20+F20 -> 3700
B22: EQUIPE PARA OBRA
B23: Engenheiro residente | E23: 0 | F23: =G16 -> 8600 | G23: =F23*E23 -> 0
B24: Encarregado | E24: 0 | F24: =G17 -> 6600 | G24: =F24*E24 -> 0
B25: Pedreiro | E25: 3 | F25: =G18 -> 4800 | G25: =F25*E25 -> 14400
B26: Meio Oficial | E26: 1 | F26: =G19 -> 4140 | G26: =F26*E26 -> 4140
B27: Ajudante | E27: 2 | F27: =G20 -> 3700 | G27: =F27*E27 -> 7400
B30: TOTAL MÊS | G30: =SUM(G23:G27) -> 25940
B31: Total dia | G31: =G30/22 -> 1179.0909
B34: TRANSPORTE GUILHERME | C34: km | D34: R$ / km | E34: CUSTO POR KM | F34: IDA E VOLTA | G34: TOTAL
C35: =C3 -> 0 | D35: 1 | E35: =D35*C35 -> 0 | F35: =E35*2 -> 0 | G35: =F35 -> 0
B36: PEDÁGIO | G36: =C7 -> 183.2
C37: VALOR DA DIÁRIA | D37: DIÁRIAS | E37: HOTEL + REFEIÇÃO
B38: DIÁRIA DA VISITA | C38: 1000 | D38: 1 | E38: 450 | G38: =(C38+E38)*D38 -> 1450
B39: Total visita Guilherme | G39: =SUM(G34:G38) -> 1633.2
B41: RESUMO | C41: COEFICIENTE | D41: VALOR TOTAL
B42: Viagem de equipe para montagem aço 2 viagens | C42: 15 | D42: =C8*C42 -> 2748
B43: Hospedagem | C43: 0 | D43: =E12*C43 -> 0
B44: Equipe | C44: 17 | D44: =G31*C44 -> 20044.545
B45: Visita Guilherme | C45: 1 | D45: =G39*C45 -> 1633.2
B46: Custo Geral | C46: 0 | D46: =SUM(D42:D45) -> 24425.745
C47: =H2 -> 193.17 | D47: =D46/C47 -> 126.44689
G48: =90+23 -> 113 | H48: 0.8 | I48: =G48*H48 -> 90.4 | J48: m2
I49: 120
B50: Area Radier m² | C50: 193 | D50: 35 | E50: =D50*C50 -> 6755
...

Sheet Instalação Portas
B2: Local saída da equipe SJC | C2: 0 | D2: km | G2: AREA CASA | H2: 230
B3: ='Fundação '!B3 -> Local da obra Mauá | C3: 0 | D3: km
B4: Custo km rodado por Viagem | C4: 0.8
B5: Custo total de ida | C5: =C4*C3 -> 0
B6: Custo total volta | C6: =C4*C3 -> 0
B7: Custo pedágio ida e volta | C7: =91.6*2 -> 183.2
B8: Custo total | C8: =SUM(C5:C7) -> 183.2
B10: HOSPEDAGEM airbnb | C10: VALOR MENSAL | D10: MESES DE OBRA | E10: VALOR TOTAL PELA OBRA
C11: 3500 | D11: 0.4 | E11: =C11*D11 -> 1400
B12: Custo total | E12: =E11 -> 1400
C15: DIÁRIA | D15: Portas por dia | E15: SALÁRIO | F15: REFEIÇÃO | G15: TOTAL
B16: Engenheiro residente | E16: 7500 | F16: =22*50 -> 1100 | G16: =E16+F16 -> 8600
B17: Encarregado | E17: 10000 | F17: =22*50 -> 1100 | G17: =F17+E17 -> 11100
B18: Instalador porta | C18: 35 | D18: 8 | E18: =D18*C18 -> 280 | F18: =50*30 -> 1500 | G18: =E18+F18 -> 1780
B20: Ajudante
B22: EQUIPE PARA OBRA
B23: Empreitada | C23: 27 portas | D23: =27/8 -> 3.375 | E23: dias finaliza
C24: 27 portas | D24: 45 | G24: =D24*27 -> 1215
B30: TOTAL MÊS | G30: =SUM(G23:G27) -> 1215
B31: Total dia | G31: =G30/22 -> 55.227273
B34: TRANSPORTE GUILHERME | C34: km | D34: R$ / km | E34: CUSTO POR KM | F34: IDA E VOLTA | G34: TOTAL
C35: =C3 -> 0 | D35: 1 | E35: =D35*C35 -> 0 | F35: =E35*2 -> 0 | G35: =F35 -> 0
B36: PEDÁGIO | G36: =C7 -> 183.2
C37: VALOR DA DIÁRIA | D37: DIÁRIAS
B38: DIÁRIA DA VISITA | C38: 1000 | D38: 1 | G38: =C38*D38 -> 1000
B39: Total visita Guilherme | G39: =SUM(G34:G38) -> 1183.2
B41: RESUMO | C41: Nº DE VIAGENS | D41: VALOR TOTAL
B42: Viagem de equipe para montagem aço 2 viagens | C42: 1 | D42: =C8*C42 -> 183.2
B43: Hospedagem | C43: 0.4 | D43: =C43*C11 -> 1400
B44: Equipe | C44: 1 | D44: =G30 -> 1215
B45: Visita Guilherme | C45: 0.3 | D45: =G39*C45 -> 354.96
B46: Custo Geral | D46: =SUM(D42:D45) -> 3153.16
C47: 27 | D47: =D46/C47 -> 116.7837

Sheet Pintura 
B2: Local saída da equipe SJC | C2: 0 | D2: km
B3: ='Fundação '!B3 -> Local da obra Mauá | C3: 0 | D3: km
B4: Custo km rodado por Viagem | C4: 0.8
B5: Custo total de ida | C5: =C4*C3 -> 0
B6: Custo total volta | C6: =C4*C3 -> 0
B7: Custo pedágio ida e volta | C7: =91.6*2 -> 183.2
B8: Custo total | C8: =SUM(C5:C7) -> 183.2
B10: HOSPEDAGEM airbnb | C10: VALOR MENSAL | D10: MESES DE OBRA | E10: VALOR TOTAL PELA OBRA
C11: 3500 | D11: 1 | E11: =C11*D11 -> 3500
B12: Custo total | E12: =E11 -> 3500
C15: DIÁRIA | D15: Portas por dia | E15: SALÁRIO | F15: REFEIÇÃO | G15: TOTAL
B16: Engenheiro residente | E16: 7500 | F16: =22*50 -> 1100 | G16: =E16+F16 -> 8600
B17: Encarregado | E17: 10000 | F17: =22*50 -> 1100 | G17: =F17+E17 -> 11100
B18: Instalador porta | C18: 35 | D18: 8 | E18: =D18*C18 -> 280 | F18: =50*30 -> 1500 | G18: =E18+F18 -> 1780
B20: Ajudante
B22: EQUIPE PARA OBRA
B23: Empreitada | C23: 27 portas | D23: =27/8 -> 3.375 | E23: dias finaliza
C24: 27 portas | D24: 45 | G24: 35000
B30: TOTAL MÊS | G30: =SUM(G23:G27) -> 35000
B31: Total dia | G31: =G30/22 -> 1590.9091
B34: TRANSPORTE GUILHERME | C34: km | D34: R$ / km | E34: CUSTO POR KM | F34: IDA E VOLTA | G34: TOTAL
C35: =C3 -> 0 | D35: 1 | E35: =D35*C35 -> 0 | F35: =E35*2 -> 0 | G35: =F35 -> 0
B36: PEDÁGIO | G36: =C7 -> 183.2
C37: VALOR DA DIÁRIA | D37: DIÁRIAS
B38: DIÁRIA DA VISITA | C38: 1000 | D38: 1 | G38: =C38*D38 -> 1000
B39: Total visita Guilherme | G39: =SUM(G34:G38) -> 1183.2
B41: RESUMO | C41: Nº DE VIAGENS | D41: VALOR TOTAL
B42: Viagem de equipe para montagem aço 2 viagens | C42: 2 | D42: =C8*C42 -> 366.4
B43: Hospedagem | C43: 1 | D43: =C43*C11 -> 3500
B44: Equipe | C44: 1 | D44: =G30 -> 35000
B45: Visita Guilherme | C45: 0.3 | D45: =G39*C45 -> 354.96
B46: Custo Geral | D46: =SUM(D42:D45) -> 39221.36
C47: 360 | D47: =D46/C47 -> 108.94822

Sheet Instalações
B2: Instalações Hidráulicas | D2: Valor total M.O | F2: =G14+D17 -> 2500
D3: Valor total Material | F3: =G15+D15 -> 4275
B6: Bacia Sanitária | C6: 8 | D6: 890 | F6: Instalações Hidráulicas Vereda
B7: Bacia Sanitária PNE | C7: 1 | D7: 1000 | F7: Custo M.O | G7: 15000
B8: Cuba banheiros | C8: 11 | D8: 600 | F8: Custo Material | G8: 13000
B9: Cuba banheiros PNE | C9: 1 | D9: 375
B10: Torneira banheiros PNE | C10: =C9 -> 1 | D10: 130 | F10: m² | G10: =89.8981+79.6445 -> 169.5426
B11: Barra de apoio PNE | C11: 2 | D11: 200 | F11: Valor por m² (M.O.) | G11: =G7/G10 -> 88.473339
B12: Cuba inox | C12: 1 | D12: 750 | F12: Valor por m² (Material) | G12: =G8/G10 -> 76.676894
B13: Torneira banheiros e cozinha | C13: =C12+C8 -> 12 | D13: 150
B14: Tanque | C14: 1 | D14: 180 | F14: Valor M.O. | G14: =G11*'RESUMO CUSTOS '!C6 -> 0
D15: =SUM(D6:D14) -> 4275 | F15: Valor Material | G15: =G12*'RESUMO CUSTOS '!C6 -> 0
B17: Instalação Louças e metais | D17: 2500
D18: não sei qual pode ser esse valor
B22: Instalações Elétricas | D22: Valor total M.O | F22: =D35 -> 0
D23: Valor total Material | F23: =D36 -> 0
B27: Instalações Elétricas Vereda
B28: Custo M.O | D28: 10000
B29: Custo Material | D29: 18000
B31: m² | D31: =89.8981+79.6445 -> 169.5426
B32: Valor por m² (M.O.) | D32: =D28/D31 -> 58.982226
B33: Valor por m² (Material) | D33: =D29/D31 -> 106.16801
B35: Valor M.O. | D35: =D32*'RESUMO CUSTOS '!C6 -> 0
B36: Valor Material | D36: =D33*'RESUMO CUSTOS '!C6 -> 0

Sheet PROJETO
C1: Planilha de formação de preço de venda de serviços
B5: Custo de mão de obra
B6: Descrição | C6: ENGENHEIRO JR. | D6: ENGENHEIRO PL. | E6: ENGENHEIRO SR. | F6: GERENTE PROJ. | G6: SUPERVISOR | H6: DESENHISTA
A7: Resp.: Renan Ruiz | B7: Salário médio | C7: 9150 | D7: 12250 | E7: 15400 | F7: 6420 | G7: 6420 | H7: 5100
A8: Criação: Maio-2021 | B8: Custo CLT mensal | C8: =C7*1.86 -> 17019 | D8: =D7*1.86 -> 22785 | E8: =E7*1.86 -> 28644 | F8: =F7*1.86 -> 11941.2 | G8: =G7*1.86 -> 11941.2 | H8: =H7*1.86 -> 9486
A9: Última revisão: 26/05/2021 | B9: Custo CLT por hora | C9: =C8/220 -> 77.359091 | D9: =D8/220 -> 103.56818 | E9: =E8/220 -> 130.2 | F9: =F8/220 -> 54.278182 | G9: =G8/220 -> 54.278182 | H9: =H8/220 -> 43.118182
A11: Adicional de hora extra | E11: Impostos | F11: Custo administrativo | G11: Horas trabalhadas por dia | H11: Refeição
A12: Sábados | B12: Dom. e fer. | C12: Noturno
A13: 0 | B13: 0 | C13: 0 | E13: 0.129 | F13: 0.08 | G13: 8.75 | H13: 22
A15: ART | E15: Margem sobre HHT da Fundamentos | F15: Margem líquida global = 25% | G15: Deslocamento (Valores unitários)
A16: Até R$ 8.000,00 | B16: Até R$ 15.000,00 | C16: Acima de R$ 15.000,00 | G16: Próprio (por km) | H16: Diária (Básico) | I16: Diária (Completo) | J16: Extras (por Km) | K16: Park (Diária) | L16: Aéreo
A17: 88.78 | B17: 155.38 | C17: 233.94 | E17: 0.69 | F17: =L42 -> #DIV/0! | G17: 1.36 | H17: 125 | I17: 175 | J17: 1 | K17: 25 | L17: 500
A19: Mão de obra
A20: Descrição | B20: Normal | C20: Normal | D20: Normal | E20: Normal
A21: ENGENHEIRO JR.
A22: ENGENHEIRO PL.
A23: ENGENHEIRO SR.
A24: GERENTE PROJ.
A25: SUPERVISOR | G25: Deslocamento (Proposta)
A26: PROJETISTA | G26: Tipo | H26: FALSE | I26: FALSE | J26: FALSE | K26: FALSE | L26: FALSE
G27: Km (ida e volta) | H27: 0 | I27: 0 | J27: 0 | K27: 0 | L27: 0
G28: Tempo (ida e volta) | H28: =H27/70 -> 0
J29: Terceiros | K29: Outros | L29: Deslocamento / hospedagem e refeição
G30: Hospedagem (Valor unitário) | H30: Hospedagem (Proposta) | I30: Emitir ART
A31: Horas a trabalhar | J31: 0 | K31: 0 | L31: =SUM(F36:I36)+L36+H39 -> 0
A32: Dias à trabalhar | G32: 125 | H32: FALSE | I32: FALSE | J32: 0.3 | K32: 0.3 | L32: 0.3
A34: Cálculo do preço de venda - Custos
A35: Descrição | B35: Horas normais | C35: Horas extras - 60% | D35: Horas extras - 100% | E35: Horas noturnas | F35: Deslocamento | G35: Hospedagem | H35: Refeições | I35: Equipamentos | J35: Terceiros | K35: Outros | L35: ART
A36: Total | B36: =SUM(B37:B46) -> 0 | C36: =SUM(C37:C46) -> 0 | D36: =SUM(D37:D46) -> 0 | E36: =SUM(E37:E46) -> 0 | F36: =F38+F40+F42+F44+F46 -> 0 | G36: =IF(H32=FALSE,0,((B32*SUM(B21:B30))+(C32*SUM(C21:C30))+(D32*SUM(D21:D30))+(E32*SUM(E21:E30)))*G32) -> 0 | H36: =IF(H32=FALSE,(B32*SUM(B21:B30)*H13)+(C32*SUM(C21:C30)*H13)+(D32*SUM(D21:D30)*H13)+(E32*SUM(E21:E30)*H13),((B32*SUM(B21:B30)*H13)+(C32*SUM(C21:C30)*H13)+(D32*SUM(D21:D30)*H13)+(E32*SUM(E21:E30)*H13))*2) -> 0 | I36: =((L21*H21)+(L22*H22)+(L23*H23)) -> 0 | J36: =J31 -> 0 | K36: =K31 -> 0 | L36: =IF(I32=FALSE,0,C17)*3 -> 0
A37: ENGENHEIRO JR. | B37: =(B32*B21*$C$9*$G$13)+(B31*B21*$C$9) -> 0 | C37: =((C32*C21*$C$9*$G$13)+(C31*C21*$C$9))*(1+$A$13) -> 0 | D37: =((D32*D21*$C$9*$G$13)+(D31*D21*$C$9))*(1+$B$13) -> 0 | E37: =((E32*E21*$C$9*$G$13)+(E31*E21*$C$9))*(1+$C$13) -> 0 | F37: Próprio
A38: ENGENHEIRO PL. | B38: =(B32*B22*$D$9*$G$13)+(B31*B22*$D$9) -> 0 | C38: =((C32*C22*$D$9*$G$13)+(C31*C22*$D$9))*(1+$A$13) -> 0 | D38: =((D32*D22*$D$9*$G$13)+(D31*D22*$D$9))*(1+$B$13) -> 0 | E38: =((E32*E22*$D$9*$G$13)+(E31*E22*$D$9))*(1+$C$13) -> 0 | F38: =IF(H26=FALSE,0,(IF(SUM(B32:E32)=0,H27*G17*COUNTIF(B31:E31,">0"),IF(H32=TRUE,H27*G17,H27*G17*SUM(B32:E32))))) -> 0 | H38: Custo adm. | I38: Custo (Mão de obra) | J38: Custo (Demais) | K38: Total de custo | L38: Total de venda
A39: ENGENHEIRO SR. | B39: =(B32*B23*$E$9*$G$13)+(B31*B23*$E$9) -> 0 | C39: =((C32*C23*$E$9*$G$13)+(C31*C23*$E$9))*(1+$A$13) -> 0 | D39: =((D32*D23*$E$9*$G$13)+(D31*D23*$E$9))*(1+$B$13) -> 0 | E39: =((E32*E23*$E$9*$G$13)+(E31*E23*$E$9))*(1+$C$13) -> 0 | F39: Alugado | H39: =SUM(B36:L36)*F13 -> 0 | I39: =SUM(B36:E36) -> 0 | J39: =SUM(F36:L36)+H39 -> 0 | K39: =SUM(I39:J39) -> 0 | L39: =(I39*(1+E17))+(J36*(1+J32))+(K36*(1+K32))+(L31*(1+L32)) -> 0
A40: GERENTE PROJ. | B40: =(B32*B24*$F$9*$G$13)+(B31*B24*$F$9) -> 0 | C40: =((C32*C24*$F$9*$G$13)+(C31*C24*$F$9))*(1+$A$13) -> 0 | D40: =((D32*D24*$F$9*$G$13)+(D31*D24*$F$9))*(1+$B$13) -> 0 | E40: =((E32*E24*$F$9*$G$13)+(E31*E24*$F$9))*(1+$C$13) -> 0 | F40: =IF(I26=FALSE,0,((SUM(B32:E32)*H17)+(SUM(B32:E32)*I27*J17)))+IF(J26=FALSE,0,((SUM(B32:E32)*I17)+(SUM(B32:E32)*J27*J17))) -> 0
A41: SUPERVISOR | B41: =(B32*B25*$G$9*$G$13)+(B31*B25*$G$9) -> 0 | C41: =((C32*C25*$G$9*$G$13)+(C31*C25*$G$9))*(1+$A$13) -> 0 | D41: =((D32*D25*$G$9*$G$13)+(D31*D25*$G$9))*(1+$B$13) -> 0 | E41: =((E32*E25*$G$9*$G$13)+(E31*E25*$G$9))*(1+$C$13) -> 0 | F41: Estacionamento | H41: Imposto (R$) | I41: Lucro (R$) | J41: Imposto (%) | K41: Lucro / Custo (%) | L41: Lucro / Venda (%)
A42: DESENHISTA | B42: =(B32*B26*$H$9*$G$13)+(B31*B26*$H$9) -> 0 | C42: =((C32*C26*$H$9*$G$13)+(C31*C26*$H$9))*(1+$A$13) -> 0 | D42: =((D32*D26*$H$9*$G$13)+(D31*D26*$H$9))*(1+$B$13) -> 0 | E42: =((E32*E26*$H$9*$G$13)+(E31*E26*$H$9))*(1+$C$13) -> 0 | F42: =IF(K26=FALSE,0,K27*K17) -> 0 | H42: =L39*E13 -> 0 | I42: =L39-H42-K39 -> 0 | J42: =H42/L39 -> #DIV/0! | K42: =I42/K39 -> #DIV/0! | L42: =I42/L39 -> #DIV/0!
B43: =(B32*B27*$I$9*$G$13)+(B31*B27*$I$9) -> 0 | C43: =((C32*C27*$I$9*$G$13)+(C31*C27*$I$9))*(1+$A$13) -> 0 | D43: =((D32*D27*$I$9*$G$13)+(D31*D27*$I$9))*(1+$B$13) -> 0 | E43: =((E32*E27*$I$9*$G$13)+(E31*E27*$I$9))*(1+$C$13) -> 0 | F43: Aéreo
B44: =(B32*B28*$J$9*$G$13)+(B31*B28*$J$9) -> 0 | C44: =((C32*C28*$J$9*$G$13)+(C31*C28*$J$9))*(1+$A$13) -> 0 | D44: =((D32*D28*$J$9*$G$13)+(D31*D28*$J$9))*(1+$B$13) -> 0 | E44: =((E32*E28*$J$9*$G$13)+(E31*E28*$J$9))*(1+$C$13) -> 0 | F44: =IF(L26=FALSE,0,MAX(SUM(B21:B30),SUM(C21:C30),SUM(D21:D30),SUM(E21:E30))*(L27*2)*L17) -> 0 | H44: Observações
B45: =(B32*B29*$K$9*$G$13)+(B31*B29*$K$9) -> 0 | C45: =((C32*C29*$K$9*$G$13)+(C31*C29*$K$9))*(1+$A$13) -> 0 | D45: =((D32*D29*$K$9*$G$13)+(D31*D29*$K$9))*(1+$B$13) -> 0 | E45: =((E32*E29*$K$9*$G$13)+(E31*E29*$K$9))*(1+$C$13) -> 0 | F45: Tempo
B46: =(B32*B30*$L$9*$G$13)+(B31*B30*$L$9) -> 0 | C46: =((C32*C30*$L$9*$G$13)+(C31*C30*$L$9))*(1+$A$13) -> 0 | D46: =((D32*D30*$L$9*$G$13)+(D31*D30*$L$9))*(1+$B$13) -> 0 | E46: =((E32*E30*$L$9*$G$13)+(E31*E30*$L$9))*(1+$C$13) -> 0 | F46: =IF(H32=FALSE,(((B32*B21*$C$9)+(B32*B22*$D$9)+(B32*B23*$E$9)+(B32*B24*$F$9)+(B32*B25*$G$9)+(B32*B26*$H$9)+(B32*B27*$I$9)+(B32*B28*$J$9)+(B32*B29*$K$9)+(B32*B30*$L$9))*$H$28*(1+$A$13))+(((C32*C21*$C$9)+(C32*C22*$D$9)+(C32*C23*$E$9)+(C32*C24*$F$9)+(C32*C25*$G$9)+(C32*C26*$H$9)+(C32*C27*$I$9)+(C32*C28*$J$9)+(C32*C29*$K$9)+(C32*C30*$L$9))*$H$28*(1+$A$13))+(((D32*D21*$C$9)+(D32*D22*$D$9)+(D32*D23*$E$9)+(D32*D24*$F$9)+(D32*D25*$G$9)+(D32*D26*$H$9)+(D32*D27*$I$9)+(D32*D28*$J$9)+(D32*D29*$K$9)+(D32*D30*$L$9))*$H$28*(1+$B$13))+(((E32*E21*$C$9)+(E32*E22*$D$9)+(E32*E23*$E$9)+(E32*E24*$F$9)+(E32*E25*$G$9)+(E32*E26*$H$9)+(E32*E27*$I$9)+(E32*E28*$J$9)+(E32*E29*$K$9)+(E32*E30*$L$9))*$H$28*(1+$C$13)*(1+$A$13)),((((B32*B21*$C$9)+(B32*B22*$D$9)+(B32*B23*$E$9)+(B32*B24*$F$9)+(B32*B25*$G$9)+(B32*B26*$H$9)+(B32*B27*$I$9)+(B32*B28*$J$9)+(B32*B29*$K$9)+(B32*B30*$L$9))*$H$28*(1+$A$13))+(((C32*C21*$C$9)+(C32*C22*$D$9)+(C32*C23*$E$9)+(C32*C24*$F$9)+(C32*C25*$G$9)+(C32*C26*$H$9)+(C32*C27*$I$9)+(C32*C28*$J$9)+(C32*C29*$K$9)+(C32*C30*$L$9))*$H$28*(1+$A$13))+(((D32*D21*$C$9)+(D32*D22*$D$9)+(D32*D23*$E$9)+(D32*D24*$F$9)+(D32*D25*$G$9)+(D32*D26*$H$9)+(D32*D27*$I$9)+(D32*D28*$J$9)+(D32*D29*$K$9)+(D32*D30*$L$9))*$H$28*(1+$B$13))+(((E32*E21*$C$9)+(E32*E22*$D$9)+(E32*E23*$E$9)+(E32*E24*$F$9)+(E32*E25*$G$9)+(E32*E26*$H$9)+(E32*E27*$I$9)+(E32*E28*$J$9)+(E32*E29*$K$9)+(E32*E30*$L$9))*$H$28*(1+$C$13)*(1+$A$13)))/SUM(B32:E32)) -> 0

Sheet TOPOGRAFIA
C1: Planilha de formação de preço de venda de serviços
B5: Custo de mão de obra
B6: Descrição | C6: ENGENHEIRO JR. | D6: ENGENHEIRO PL. | E6: ENGENHEIRO SR. | F6: GERENTE PROJ. | G6: SUPERVISOR | H6: DESENHISTA | I6: TOPÓGRAFO | J6: AJUDANTE TOPOGRAFIA
A7: Resp.: Renan Ruiz | B7: Salário médio | C7: 9150 | D7: 12250 | E7: 15400 | F7: 6420 | G7: 6420 | H7: 5100 | I7: 3400 | J7: 2100
A8: Criação: Maio-2021 | B8: Custo CLT mensal | C8: =C7*1.86 -> 17019 | D8: =D7*1.86 -> 22785 | E8: =E7*1.86 -> 28644 | F8: =F7*1.86 -> 11941.2 | G8: =G7*1.86 -> 11941.2 | H8: =H7*1.86 -> 9486 | I8: =I7*1.86 -> 6324 | J8: =J7*1.86 -> 3906
A9: Última revisão: 26/05/2021 | B9: Custo CLT por hora | C9: =C8/220 -> 77.359091 | D9: =D8/220 -> 103.56818 | E9: =E8/220 -> 130.2 | F9: =F8/220 -> 54.278182 | G9: =G8/220 -> 54.278182 | H9: =H8/220 -> 43.118182 | I9: =I8/220 -> 28.745455 | J9: =J8/220 -> 17.754545
A11: Adicional de hora extra | E11: Impostos | F11: Custo administrativo | G11: Horas trabalhadas por dia | H11: Refeição
A12: Sábados | B12: Dom. e fer. | C12: Noturno
A13: 0.6 | B13: 1 | C13: 0.2 | E13: 0.129 | F13: 0.08 | G13: 8.75 | H13: 22
A15: ART | E15: Margem sobre HHT da Fundamentos | F15: Margem líquida global = 25% | G15: Deslocamento (Valores unitários)
A16: Até R$ 8.000,00 | B16: Até R$ 15.000,00 | C16: Acima de R$ 15.000,00 | G16: Próprio (por km) | H16: Diária (Básico) | I16: Diária (Completo) | J16: Extras (por Km) | K16: Park (Diária) | L16: Aéreo
A17: 88.78 | B17: 155.38 | C17: 233.94 | E17: 0.8 | F17: =L42 -> #DIV/0! | G17: 1.36 | H17: 125 | I17: 175 | J17: 1 | K17: 25 | L17: 500
A19: Mão de obra
A20: Descrição | B20: Normal | C20: Sáb. ou após 18h | D20: Dom. e Fer. | E20: Noturno
A21: ENGENHEIRO JR.
A22: ENGENHEIRO PL.
A23: ENGENHEIRO SR.
A24: GERENTE PROJ.
A25: SUPERVISOR | G25: Deslocamento (Proposta)
A26: DESENHISTA | G26: Tipo | H26: FALSE | I26: FALSE | J26: FALSE | K26: FALSE | L26: FALSE
A27: TOPÓGRAFO | G27: Km (ida e volta) | H27: 0 | I27: 0 | J27: 0 | K27: 0 | L27: 0
A28: AJUDANTE TOPOGRAFIA | G28: Tempo (ida e volta) | H28: =H27/70 -> 0
J29: Terceiros | K29: Outros | L29: Deslocamento / hospedagem e refeição
G30: Hospedagem (Valor unitário) | H30: Hospedagem (Proposta) | I30: Emitir ART
A31: Horas a trabalhar | J31: 0 | K31: 0 | L31: =SUM(F36:I36)+L36+H39 -> 0
A32: Dias à trabalhar | G32: 125 | H32: FALSE | I32: FALSE | J32: 0.3 | K32: 0.3 | L32: 0.3
A34: Cálculo do preço de venda - Custos
A35: Descrição | B35: Horas normais | C35: Horas extras - 60% | D35: Horas extras - 100% | E35: Horas noturnas | F35: Deslocamento | G35: Hospedagem | H35: Refeições | I35: Equipamentos | J35: Terceiros | K35: Outros | L35: ART
A36: Total | B36: =SUM(B37:B46) -> 0 | C36: =SUM(C37:C46) -> 0 | D36: =SUM(D37:D46) -> 0 | E36: =SUM(E37:E46) -> 0 | F36: =F38+F40+F42+F44+F46 -> 0 | G36: =IF(H32=FALSE,0,((B32*SUM(B21:B30))+(C32*SUM(C21:C30))+(D32*SUM(D21:D30))+(E32*SUM(E21:E30)))*G32) -> 0 | H36: =IF(H32=FALSE,(B32*SUM(B21:B30)*H13)+(C32*SUM(C21:C30)*H13)+(D32*SUM(D21:D30)*H13)+(E32*SUM(E21:E30)*H13),((B32*SUM(B21:B30)*H13)+(C32*SUM(C21:C30)*H13)+(D32*SUM(D21:D30)*H13)+(E32*SUM(E21:E30)*H13))*2) -> 0 | I36: =((L21*H21)+(L22*H22)+(L23*H23)) -> 0 | J36: =J31 -> 0 | K36: =K31 -> 0 | L36: =IF(I32=FALSE,0,C17) -> 0
A37: ENGENHEIRO JR. | B37: =(B32*B21*$C$9*$G$13)+(B31*B21*$C$9) -> 0 | C37: =((C32*C21*$C$9*$G$13)+(C31*C21*$C$9))*(1+$A$13) -> 0 | D37: =((D32*D21*$C$9*$G$13)+(D31*D21*$C$9))*(1+$B$13) -> 0 | E37: =((E32*E21*$C$9*$G$13)+(E31*E21*$C$9))*(1+$C$13) -> 0 | F37: Próprio
A38: ENGENHEIRO PL. | B38: =(B32*B22*$D$9*$G$13)+(B31*B22*$D$9) -> 0 | C38: =((C32*C22*$D$9*$G$13)+(C31*C22*$D$9))*(1+$A$13) -> 0 | D38: =((D32*D22*$D$9*$G$13)+(D31*D22*$D$9))*(1+$B$13) -> 0 | E38: =((E32*E22*$D$9*$G$13)+(E31*E22*$D$9))*(1+$C$13) -> 0 | F38: =IF(H26=FALSE,0,(IF(SUM(B32:E32)=0,H27*G17*COUNTIF(B31:E31,">0"),IF(H32=TRUE,H27*G17,H27*G17*SUM(B32:E32))))) -> 0 | H38: Custo adm. | I38: Custo (Mão de obra) | J38: Custo (Demais) | K38: Total de custo | L38: Total de venda
A39: ENGENHEIRO SR. | B39: =(B32*B23*$E$9*$G$13)+(B31*B23*$E$9) -> 0 | C39: =((C32*C23*$E$9*$G$13)+(C31*C23*$E$9))*(1+$A$13) -> 0 | D39: =((D32*D23*$E$9*$G$13)+(D31*D23*$E$9))*(1+$B$13) -> 0 | E39: =((E32*E23*$E$9*$G$13)+(E31*E23*$E$9))*(1+$C$13) -> 0 | F39: Alugado | H39: =SUM(B36:L36)*F13 -> 0 | I39: =SUM(B36:E36) -> 0 | J39: =SUM(F36:L36)+H39 -> 0 | K39: =SUM(I39:J39) -> 0 | L39: =(I39*(1+E17))+(J36*(1+J32))+(K36*(1+K32))+(L31*(1+L32)) -> 0
A40: GERENTE PROJ. | B40: =(B32*B24*$F$9*$G$13)+(B31*B24*$F$9) -> 0 | C40: =((C32*C24*$F$9*$G$13)+(C31*C24*$F$9))*(1+$A$13) -> 0 | D40: =((D32*D24*$F$9*$G$13)+(D31*D24*$F$9))*(1+$B$13) -> 0 | E40: =((E32*E24*$F$9*$G$13)+(E31*E24*$F$9))*(1+$C$13) -> 0 | F40: =IF(I26=FALSE,0,((SUM(B32:E32)*H17)+(SUM(B32:E32)*I27*J17)))+IF(J26=FALSE,0,((SUM(B32:E32)*I17)+(SUM(B32:E32)*J27*J17))) -> 0
A41: SUPERVISOR | B41: =(B32*B25*$G$9*$G$13)+(B31*B25*$G$9) -> 0 | C41: =((C32*C25*$G$9*$G$13)+(C31*C25*$G$9))*(1+$A$13) -> 0 | D41: =((D32*D25*$G$9*$G$13)+(D31*D25*$G$9))*(1+$B$13) -> 0 | E41: =((E32*E25*$G$9*$G$13)+(E31*E25*$G$9))*(1+$C$13) -> 0 | F41: Estacionamento | H41: Imposto (R$) | I41: Lucro (R$) | J41: Imposto (%) | K41: Lucro / Custo (%) | L41: Lucro / Venda (%)
A42: DESENHISTA | B42: =(B32*B26*$H$9*$G$13)+(B31*B26*$H$9) -> 0 | C42: =((C32*C26*$H$9*$G$13)+(C31*C26*$H$9))*(1+$A$13) -> 0 | D42: =((D32*D26*$H$9*$G$13)+(D31*D26*$H$9))*(1+$B$13) -> 0 | E42: =((E32*E26*$H$9*$G$13)+(E31*E26*$H$9))*(1+$C$13) -> 0 | F42: =IF(K26=FALSE,0,K27*K17) -> 0 | H42: =L39*E13 -> 0 | I42: =L39-H42-K39 -> 0 | J42: =H42/L39 -> #DIV/0! | K42: =I42/K39 -> #DIV/0! | L42: =I42/L39 -> #DIV/0!
A43: TOPÓGRAFO | B43: =(B32*B27*$I$9*$G$13)+(B31*B27*$I$9) -> 0 | C43: =((C32*C27*$I$9*$G$13)+(C31*C27*$I$9))*(1+$A$13) -> 0 | D43: =((D32*D27*$I$9*$G$13)+(D31*D27*$I$9))*(1+$B$13) -> 0 | E43: =((E32*E27*$I$9*$G$13)+(E31*E27*$I$9))*(1+$C$13) -> 0 | F43: Aéreo
A44: AJUDANTE TOPOGRAFIA | B44: =(B32*B28*$J$9*$G$13)+(B31*B28*$J$9) -> 0 | C44: =((C32*C28*$J$9*$G$13)+(C31*C28*$J$9))*(1+$A$13) -> 0 | D44: =((D32*D28*$J$9*$G$13)+(D31*D28*$J$9))*(1+$B$13) -> 0 | E44: =((E32*E28*$J$9*$G$13)+(E31*E28*$J$9))*(1+$C$13) -> 0 | F44: =IF(L26=FALSE,0,MAX(SUM(B21:B30),SUM(C21:C30),SUM(D21:D30),SUM(E21:E30))*(L27*2)*L17) -> 0 | H44: Observações
B45: =(B32*B29*$K$9*$G$13)+(B31*B29*$K$9) -> 0 | C45: =((C32*C29*$K$9*$G$13)+(C31*C29*$K$9))*(1+$A$13) -> 0 | D45: =((D32*D29*$K$9*$G$13)+(D31*D29*$K$9))*(1+$B$13) -> 0 | E45: =((E32*E29*$K$9*$G$13)+(E31*E29*$K$9))*(1+$C$13) -> 0 | F45: Tempo
B46: =(B32*B30*$L$9*$G$13)+(B31*B30*$L$9) -> 0 | C46: =((C32*C30*$L$9*$G$13)+(C31*C30*$L$9))*(1+$A$13) -> 0 | D46: =((D32*D30*$L$9*$G$13)+(D31*D30*$L$9))*(1+$B$13) -> 0 | E46: =((E32*E30*$L$9*$G$13)+(E31*E30*$L$9))*(1+$C$13) -> 0 | F46: =IF(H32=FALSE,(((B32*B21*$C$9)+(B32*B22*$D$9)+(B32*B23*$E$9)+(B32*B24*$F$9)+(B32*B25*$G$9)+(B32*B26*$H$9)+(B32*B27*$I$9)+(B32*B28*$J$9)+(B32*B29*$K$9)+(B32*B30*$L$9))*$H$28*(1+$A$13))+(((C32*C21*$C$9)+(C32*C22*$D$9)+(C32*C23*$E$9)+(C32*C24*$F$9)+(C32*C25*$G$9)+(C32*C26*$H$9)+(C32*C27*$I$9)+(C32*C28*$J$9)+(C32*C29*$K$9)+(C32*C30*$L$9))*$H$28*(1+$A$13))+(((D32*D21*$C$9)+(D32*D22*$D$9)+(D32*D23*$E$9)+(D32*D24*$F$9)+(D32*D25*$G$9)+(D32*D26*$H$9)+(D32*D27*$I$9)+(D32*D28*$J$9)+(D32*D29*$K$9)+(D32*D30*$L$9))*$H$28*(1+$B$13))+(((E32*E21*$C$9)+(E32*E22*$D$9)+(E32*E23*$E$9)+(E32*E24*$F$9)+(E32*E25*$G$9)+(E32*E26*$H$9)+(E32*E27*$I$9)+(E32*E28*$J$9)+(E32*E29*$K$9)+(E32*E30*$L$9))*$H$28*(1+$C$13)*(1+$A$13)),((((B32*B21*$C$9)+(B32*B22*$D$9)+(B32*B23*$E$9)+(B32*B24*$F$9)+(B32*B25*$G$9)+(B32*B26*$H$9)+(B32*B27*$I$9)+(B32*B28*$J$9)+(B32*B29*$K$9)+(B32*B30*$L$9))*$H$28*(1+$A$13))+(((C32*C21*$C$9)+(C32*C22*$D$9)+(C32*C23*$E$9)+(C32*C24*$F$9)+(C32*C25*$G$9)+(C32*C26*$H$9)+(C32*C27*$I$9)+(C32*C28*$J$9)+(C32*C29*$K$9)+(C32*C30*$L$9))*$H$28*(1+$A$13))+(((D32*D21*$C$9)+(D32*D22*$D$9)+(D32*D23*$E$9)+(D32*D24*$F$9)+(D32*D25*$G$9)+(D32*D26*$H$9)+(D32*D27*$I$9)+(D32*D28*$J$9)+(D32*D29*$K$9)+(D32*D30*$L$9))*$H$28*(1+$B$13))+(((E32*E21*$C$9)+(E32*E22*$D$9)+(E32*E23*$E$9)+(E32*E24*$F$9)+(E32*E25*$G$9)+(E32*E26*$H$9)+(E32*E27*$I$9)+(E32*E28*$J$9)+(E32*E29*$K$9)+(E32*E30*$L$9))*$H$28*(1+$C$13)*(1+$A$13)))/SUM(B32:E32)) -> 0
