Workbook

Sheet Gerenciamento Custo
B2: ITEM | C2: TIPO | D2: VALOR ORÇADO VENDA | F2: VALOR ORÇADO CUSTO | H2: VALOR PREVISTO | J2: VALOR REALIZADO | L2: VALOR A REALIZAR | N2: SALDO | P2: MARGEM Venda X Custo | Q2: MARGEM Custo X Realizado | R2: MARGEM Venda X Realizado | T2: TOTAL PAGO | U2: FAT DIRETO | V2: FALTA PAGAR
B3: Estrutura em Aço Galvanizado a frio (LSF) Z275 para área de cobertura e muretas. + Estrutura do telhado Incluso todos os insumos como fixações, parafusos, etc. | C3: Material | D3: =PROPOSTA!F3 -> 441794 | E3: =SUM(D3:D4) -> 701624.51 | F3: 416647.37 | G3: =SUM(F3:F4) -> 557172.37 | I3: =SUM(H3:H4) -> 0 | K3: =SUM(J3:J4) -> 0 | M3: =SUM(L3:L4) -> 0 | N3: =F3-(L3+H3) -> 416647.37 | P3: =D3-F3 -> 25146.63 | Q3: =F3-L3 -> 416647.37 | R3: =D3-L3 -> 441794 | T3: =Resumo!C6 -> 5132 | U3: =Resumo!C5 -> 1004567.7 | V3: =#REF!-U3-T3 -> #REF!
C4: Mão de obra | D4: =PROPOSTA!G3 -> 259830.51 | F4: 140525 | N4: =F4-(L4+J4) -> 140525 | P4: =D4-F4 -> 119305.51 | Q4: =F4-L4 -> 140525 | R4: =D4-L4 -> 259830.51
B5: Pintura do aço estrutural LSF do telhado. | C5: Material | D5: =PROPOSTA!F4 -> 0 | E5: =SUM(D5:D6) -> 69584.75 | F5: =PROPOSTA!B4 -> 0 | G5: =SUM(F5:F6) -> 37633.75 | I5: =SUM(H5:H6) -> 0 | K5: =SUM(J5:J6) -> 0 | M5: =SUM(L5:L6) -> 0 | N5: =F5-(L5+H5) -> 0 | P5: =D5-F5 -> 0 | Q5: =F5-L5 -> 0 | R5: =D5-L5 -> 0 | T5: =Resumo!C8 -> 9882 | U5: =Resumo!C7 -> 4750 | V5: =D38-U5-T5 -> -14632
C6: Mão de obra | D6: =PROPOSTA!G4 -> 69584.75 | F6: 37633.75 | N6: =F6-(L6+J6) -> 37633.75 | P6: =D6-F6 -> 31951 | Q6: =F6-L6 -> 37633.75 | R6: =D6-L6 -> 69584.75
B7: Pintura e fornecimento de material Stain em portão de Pinus fornecido pelo cliente. | C7: Material | D7: =PROPOSTA!F5 -> 161000 | E7: =SUM(D7:D8) -> 170550.85 | F7: 5116 | G7: =SUM(F7:F8) -> 10232 | I7: =SUM(H7:H8) -> 0 | K7: =SUM(J7:J8) -> 0 | M7: =SUM(L7:L8) -> 0 | N7: =F7-(L7+H7) -> 5116 | P7: =D7-F7 -> 155884 | Q7: =F7-L7 -> 5116 | R7: =D7-L7 -> 161000 | T7: =Resumo!C10 -> 0 | U7: =Resumo!C9 -> 994685.74 | V7: =D40-U7-T7 -> -994685.74
C8: Mão de obra | D8: =PROPOSTA!G5 -> 9550.85 | F8: 5116 | N8: =F8-(L8+J8) -> 5116 | P8: =D8-F8 -> 4434.85 | Q8: =F8-L8 -> 5116 | R8: =D8-L8 -> 9550.85
B9: Execução de Portão em Pinus - Sendo 2 por baia e fornecimento das madeiras pelo cliente.Trilho para portão, 1 por baia | C9: Material | D9: =PROPOSTA!F6 -> 7500 | E9: =SUM(D9:D10) -> 35974.58 | F9: =PROPOSTA!B6 -> 6000 | G9: =SUM(F9:F10) -> 22800 | I9: =SUM(H9:H10) -> 0 | K9: =SUM(J9:J10) -> 0 | M9: =SUM(L9:L10) -> 0 | N9: =F9-(L9+H9) -> 6000 | P9: =D9-F9 -> 1500 | Q9: =F9-L9 -> 6000 | R9: =D9-L9 -> 7500 | T9: =Resumo!#REF! -> #REF! | U9: =Resumo!#REF! -> #REF! | V9: =D16-U9-T9 -> #REF!
C10: Mão de obra | D10: =PROPOSTA!G6 -> 28474.58 | F10: =PROPOSTA!C6 -> 16800 | N10: =F10-(L10+J10) -> 16800 | P10: =D10-F10 -> 11674.58 | Q10: =F10-L10 -> 16800 | R10: =D10-L10 -> 28474.58
B11: Fechamento em placas cimenticias na parte interna das baias incluindo tratamento de superfície com basecoat. | C11: Material | D11: =PROPOSTA!F7 -> 0 | E11: =SUM(D11:D12) -> 68644.07 | F11: =PROPOSTA!B7 -> 0 | G11: =SUM(F11:F12) -> 40500 | I11: =SUM(H11:H12) -> 0 | K11: =SUM(J11:J12) -> 0 | M11: =SUM(L11:L12) -> 0 | N11: =F11-(L11+H11) -> 0 | P11: =D11-F11 -> 0 | Q11: =F11-L11 -> 0 | R11: =D11-L11 -> 0 | T11: =Resumo!#REF! -> #REF! | U11: =Resumo!#REF! -> #REF! | V11: =D18-U11-T11 -> #REF!
C12: Mão de obra | D12: =PROPOSTA!G7 -> 68644.07 | F12: =PROPOSTA!C7 -> 40500 | N12: =F12-(L12+J12) -> 40500 | P12: =D12-F12 -> 28144.07 | Q12: =F12-L12 -> 40500 | R12: =D12-L12 -> 68644.07
B13: Fechamento em reguas de pinus nas paredes externas das baias - Fornecimento da madeira pelo cliente. | C13: Material | D13: =PROPOSTA!F8 -> 0 | E13: =SUM(D13:D14) -> 50338.98 | F13: =PROPOSTA!B8 -> 0 | G13: =SUM(F13:F14) -> 29700 | I13: =SUM(H13:H14) -> 0 | K13: =SUM(J13:J14) -> 0 | M13: =SUM(L13:L14) -> 0 | N13: =F13-(L13+H13) -> 0 | P13: =D13-F13 -> 0 | Q13: =F13-L13 -> 0 | R13: =D13-L13 -> 0 | T13: =Resumo!#REF! -> #REF! | U13: =Resumo!#REF! -> #REF! | V13: =D20-U13-T13 -> #REF!
C14: Mão de obra | D14: =PROPOSTA!G8 -> 50338.98 | F14: =PROPOSTA!C8 -> 29700 | N14: =F14-(L14+J14) -> 29700 | P14: =D14-F14 -> 20638.98 | Q14: =F14-L14 -> 29700 | R14: =D14-L14 -> 50338.98
B15: Pintura dos fechamentos internos em placas cimentícias com acabamento em cimento queimado. | C15: Material | D15: =PROPOSTA!F9 -> 0 | E15: =SUM(D15:D16) -> 68644.07 | F15: =PROPOSTA!B9 -> 0 | G15: =SUM(F15:F16) -> 40500 | I15: =SUM(H15:H16) -> 0 | K15: =SUM(J15:J16) -> 0 | M15: =SUM(L15:L16) -> 0 | N15: =F15-(L15+H15) -> 0 | P15: =D15-F15 -> 0 | Q15: =F15-L15 -> 0 | R15: =D15-L15 -> 0 | T15: =Resumo!#REF! -> #REF! | U15: =Resumo!#REF! -> #REF! | V15: =D22-U15-T15 -> #REF!
C16: Mão de obra | D16: =PROPOSTA!G9 -> 68644.07 | F16: =PROPOSTA!C9 -> 40500 | N16: =F16-(L16+J16) -> 40500 | P16: =D16-F16 -> 28144.07 | Q16: =F16-L16 -> 40500 | R16: =D16-L16 -> 68644.07
B17: Pintura em Stain das paredes externas em reguas de pinus. | C17: Material | D17: =PROPOSTA!F10 -> 1000 | E17: =SUM(D17:D18) -> 34559.32 | F17: =PROPOSTA!B10 -> 800 | G17: =SUM(F17:F18) -> 20600 | I17: =SUM(H17:H18) -> 0 | K17: =SUM(J17:J18) -> 0 | M17: =SUM(L17:L18) -> 0 | N17: =F17-(L17+H17) -> 800 | P17: =D17-F17 -> 200 | Q17: =F17-L17 -> 800 | R17: =D17-L17 -> 1000 | T17: =Resumo!#REF! -> #REF! | U17: =Resumo!#REF! -> #REF! | V17: =D24-U17-T17 -> #REF!
C18: Mão de obra | D18: =PROPOSTA!G10 -> 33559.32 | F18: =PROPOSTA!C10 -> 19800 | N18: =F18-(L18+J18) -> 19800 | P18: =D18-F18 -> 13759.32 | Q18: =F18-L18 -> 19800 | R18: =D18-L18 -> 33559.32
B19: Estruturação e verticalização de Pilares roliços de tronco de eucalipto para apoio da estrutura LSF incluindo sapatas e concreto armado | C19: Material | D19: =PROPOSTA!F11 -> 0 | E19: =SUM(D19:D20) -> 30816.64 | F19: =PROPOSTA!B11 -> 0 | G19: =SUM(F19:F20) -> 18181.82 | I19: =SUM(H19:H20) -> 0 | K19: =SUM(J19:J20) -> 0 | M19: =SUM(L19:L20) -> 0 | N19: =F19-(L19+H19) -> 0 | P19: =D19-F19 -> 0 | Q19: =F19-L19 -> 0 | R19: =D19-L19 -> 0 | T19: =Resumo!#REF! -> #REF! | U19: =Resumo!#REF! -> #REF! | V19: =D26-U19-T19 -> #REF!
C20: Mão de obra | D20: =PROPOSTA!G11 -> 30816.64 | F20: =PROPOSTA!C11 -> 18181.82 | N20: =F20-(L20+J20) -> 18181.82 | P20: =D20-F20 -> 12634.82 | Q20: =F20-L20 -> 18181.82 | R20: =D20-L20 -> 30816.64
B21: Execução de 02 corredores de passagem com 2 metros de largura cada em concreto desempenado camurçado, incluso concreto, no perímetro das baias. | C21: Material | D21: =PROPOSTA!F12 -> 70680 | E21: =SUM(D21:D22) -> 96120.68 | F21: =PROPOSTA!B12 -> 56544 | G21: =SUM(F21:F22) -> 71554 | I21: =SUM(H21:H22) -> 0 | K21: =SUM(J21:J22) -> 0 | M21: =SUM(L21:L22) -> 0 | N21: =F21-(L21+H21) -> 56544 | P21: =D21-F21 -> 14136 | Q21: =F21-L21 -> 56544 | R21: =D21-L21 -> 70680 | T21: =Resumo!#REF! -> #REF! | U21: =Resumo!#REF! -> #REF! | V21: =D28-U21-T21 -> #REF!
C22: Mão de obra | D22: =PROPOSTA!G12 -> 25440.68 | F22: =PROPOSTA!C12 -> 15010 | N22: =F22-(L22+J22) -> 15010 | P22: =D22-F22 -> 10430.68 | Q22: =F22-L22 -> 15010 | R22: =D22-L22 -> 25440.68
B23: Revestimento em pedra moledo em pilares em até 1m de altura | C23: Material | D23: =PROPOSTA!F13 -> 0 | E23: =SUM(D23:D24) -> 15593.22 | F23: =PROPOSTA!B13 -> 0 | G23: =SUM(F23:F24) -> 9200 | I23: =SUM(H23:H24) -> 0 | K23: =SUM(J23:J24) -> 0 | M23: =SUM(L23:L24) -> 0 | N23: =F23-(L23+H23) -> 0 | P23: =D23-F23 -> 0 | Q23: =F23-L23 -> 0 | R23: =D23-L23 -> 0 | T23: =Resumo!#REF! -> #REF! | U23: =Resumo!#REF! -> #REF! | V23: =D30-U23-T23 -> #REF!
C24: Mão de obra | D24: =PROPOSTA!G13 -> 15593.22 | F24: =PROPOSTA!C13 -> 9200 | N24: =F24-(L24+J24) -> 9200 | P24: =D24-F24 -> 6393.22 | Q24: =F24-L24 -> 9200 | R24: =D24-L24 -> 15593.22
B25: Instalação de um ponto de luz em cada baia e um ponto de luz em cada pilar de eucalipto. (O fornecimento das luminárias pelo cliente) | C25: Material | D25: =PROPOSTA!F14 -> 8637.5 | E25: =SUM(D25:D26) -> 19654.45 | F25: =PROPOSTA!B14 -> 6910 | G25: =SUM(F25:F26) -> 13410 | I25: =SUM(H25:H26) -> 0 | K25: =SUM(J25:J26) -> 0 | M25: =SUM(L25:L26) -> 0 | N25: =F25-(L25+H25) -> 6910 | P25: =D25-F25 -> 1727.5 | Q25: =F25-L25 -> 6910 | R25: =D25-L25 -> 8637.5 | T25: =Resumo!#REF! -> #REF! | U25: =Resumo!#REF! -> #REF! | V25: =D32-U25-T25 -> #REF!
C26: Mão de obra | D26: =PROPOSTA!G14 -> 11016.95 | F26: =PROPOSTA!C14 -> 6500 | N26: =F26-(L26+J26) -> 6500 | P26: =D26-F26 -> 4516.95 | Q26: =F26-L26 -> 6500 | R26: =D26-L26 -> 11016.95
B27: Instalação de telha Shingle | C27: Material | D27: =PROPOSTA!F15 -> 0 | E27: =SUM(D27:D28) -> 168991.53 | F27: =PROPOSTA!B15 -> 0 | G27: =SUM(F27:F28) -> 99705 | I27: =SUM(H27:H28) -> 0 | K27: =SUM(J27:J28) -> 0 | M27: =SUM(L27:L28) -> 0 | N27: =F27-(L27+H27) -> 0 | P27: =D27-F27 -> 0 | Q27: =F27-L27 -> 0 | R27: =D27-L27 -> 0 | T27: =Resumo!#REF! -> #REF! | U27: =Resumo!#REF! -> #REF! | V27: =D34-U27-T27 -> #REF!
C28: Mão de obra | D28: =PROPOSTA!G15 -> 168991.53 | F28: =PROPOSTA!C15 -> 99705 | N28: =F28-(L28+J28) -> 99705 | P28: =D28-F28 -> 69286.53 | Q28: =F28-L28 -> 99705 | R28: =D28-L28 -> 168991.53
B29: Execução de cercado em todas a baias com 2 réguas de tábua e pilares de 12x12cm - fornecimento das réguas de tábua e pilares pelo cliente e fixadores pela VEKS Engenharia. | C29: Material | D29: =PROPOSTA!F16 -> 3000 | E29: =SUM(D29:D30) -> 21305.08 | F29: =PROPOSTA!B16 -> 2400 | G29: =SUM(F29:F30) -> 13200 | I29: =SUM(H29:H30) -> 0 | K29: =SUM(J29:J30) -> 0 | M29: =SUM(L29:L30) -> 0 | N29: =F29-(L29+H29) -> 2400 | P29: =D29-F29 -> 600 | Q29: =F29-L29 -> 2400 | R29: =D29-L29 -> 3000 | T29: =Resumo!#REF! -> #REF! | U29: =Resumo!#REF! -> #REF! | V29: =D36-U29-T29 -> #REF!
C30: Mão de obra | D30: =PROPOSTA!G16 -> 18305.08 | F30: =PROPOSTA!C16 -> 10800 | N30: =F30-(L30+J30) -> 10800 | P30: =D30-F30 -> 7505.08 | Q30: =F30-L30 -> 10800 | R30: =D30-L30 -> 18305.08
B31: Pintura em Stain do cercado das baias. | C31: Material | D31: =PROPOSTA!F17 -> 24000 | E31: =SUM(D31:D32) -> 40271.19 | F31: =PROPOSTA!B17 -> 800 | G31: =SUM(F31:F32) -> 10400 | I31: =SUM(H31:H32) -> 0 | K31: =SUM(J31:J32) -> 0 | M31: =SUM(L31:L32) -> 0 | N31: =F31-(L31+H31) -> 800 | P31: =D31-F31 -> 23200 | Q31: =F31-L31 -> 800 | R31: =D31-L31 -> 24000 | T31: =Resumo!#REF! -> #REF! | U31: =Resumo!#REF! -> #REF! | V31: =#REF!-U31-T31 -> #REF!
C32: Mão de obra | D32: =PROPOSTA!G17 -> 16271.19 | F32: =PROPOSTA!C17 -> 9600 | N32: =F32-(L32+J32) -> 9600 | P32: =D32-F32 -> 6671.19 | Q32: =F32-L32 -> 9600 | R32: =D32-L32 -> 16271.19
B33: Execução de um ponto hidraulico por baia para bebedouro | C33: Material | D33: =PROPOSTA!F18 -> 1083.88 | E33: =SUM(D33:D34) -> 5151.68 | F33: =PROPOSTA!B18 -> 867.1 | G33: =SUM(F33:F34) -> 3267.1 | I33: =SUM(H33:H34) -> 0 | K33: =SUM(J33:J34) -> 0 | M33: =SUM(L33:L34) -> 0 | N33: =F33-(L33+H33) -> 867.1 | P33: =D33-F33 -> 216.78 | Q33: =F33-L33 -> 867.1 | R33: =D33-L33 -> 1083.88 | T33: =Resumo!#REF! -> #REF! | U33: =Resumo!#REF! -> #REF! | V33: =#REF!-U33-T33 -> #REF!
C34: Mão de obra | D34: =PROPOSTA!G18 -> 4067.8 | F34: =PROPOSTA!C18 -> 2400 | N34: =F34-(L34+J34) -> 2400 | P34: =D34-F34 -> 1667.8 | Q34: =F34-L34 -> 2400 | R34: =D34-L34 -> 4067.8
B35: Execução de casa de gourmet apoio -Projeto de Fundação e Projeto LSF -Fundação -Aço engenheirado -Fechamento interno e externo -Forro -Elétrica -Hidraulico -Pintura de madeira em Stain | C35: Material | D35: =PROPOSTA!F19 -> 67079.49 | E35: =SUM(D35:D36) -> 122971.16 | F35: =PROPOSTA!B19 -> 52322 | G35: =SUM(F35:F36) -> 92564 | I35: =SUM(H35:H36) -> 0 | K35: =SUM(J35:J36) -> 0 | M35: =SUM(L35:L36) -> 0 | N35: =F35-(L35+H35) -> 52322 | P35: =D35-F35 -> 14757.49 | Q35: =F35-L35 -> 52322 | R35: =D35-L35 -> 67079.49 | T35: =Resumo!#REF! -> #REF! | U35: =Resumo!#REF! -> #REF! | V35: =#REF!-U35-T35 -> #REF!
C36: Mão de obra | D36: =PROPOSTA!G19 -> 55891.67 | F36: =PROPOSTA!C19 -> 40242 | N36: =F36-(L36+J36) -> 40242 | P36: =D36-F36 -> 15649.67 | Q36: =F36-L36 -> 40242 | R36: =D36-L36 -> 55891.67
B37: Projetos de Fundação, LSF e Metalica pesada | D37: 0 | E37: 0 | F37: 0 | G37: =SUM(F37) -> 0 | I37: =SUM(H37) -> 0 | J37: =GETPIVOTDATA("Valor",'Locação + Frete'!$G$2,"Tipo","Projetos (Realizado)") -> 4750 | K37: =SUM(J37) -> 4750 | L37: =GETPIVOTDATA("Valor",'Locação + Frete'!$G$2,"Tipo","Projetos (A realizar)") -> 4750 | M37: =SUM(L37) -> 4750 | N37: =F37-(L37+J37) -> -9500 | P37: =D37-F37 -> 0 | Q37: =F37-L37 -> -4750 | R37: =D37-L37 -> -4750
B38: Custo de equipe de gerenciamento em campo (Logistica) | J38: =GETPIVOTDATA("Valor",'Refeição + Transporte'!$G$2,"Tipo","Visita em obra") -> 382 | K38: =SUM(J38) -> 382 | L38: 0 | M38: =SUM(L38) -> 0 | N38: =F38-(L38+J38) -> -382 | P38: =D38-F38 -> 0 | Q38: =F38-L38 -> 0 | R38: =D38-L38 -> 0
B39: Custos equipe (alimentação + transporte + outros) | K39: =SUM(J39) -> 0 | M39: =SUM(L39) -> 0 | N39: =F39-(L39+J39) -> 0 | P39: =D39-F39 -> 0 | Q39: =F39-L39 -> 0 | R39: =D39-L39 -> 0
K40: =SUM(J40) -> 0 | M40: =SUM(L40) -> 0 | N40: =F40-(L40+J40) -> 0 | P40: =D40-F40 -> 0 | Q40: =F40-L40 -> 0 | R40: =D40-L40 -> 0
K41: =SUM(J41) -> 0 | M41: =SUM(L41) -> 0 | N41: =F41-(L41+J41) -> 0 | P41: =D41-F41 -> 0 | Q41: =F41-L41 -> 0 | R41: =D41-L41 -> 0
...

Sheet PROPOSTA
B1: CUSTO | F1: VENDA
B2: MATERIAL | C2: MÃO DE OBRA | D2: TOTAL | F2: MATERIAL | G2: MÃO DE OBRA | H2: TOTAL
B3: 331345.5 | C3: 153300 | D3: =B3+C3 -> 484645.5 | F3: 441794 | G3: 259830.51 | H3: =F3+G3 -> 701624.51
B4: 0 | C4: 41055 | D4: =B4+C4 -> 41055 | F4: 0 | G4: 69584.75 | H4: =F4+G4 -> 69584.75
B5: 128800 | C5: 5635 | D5: =B5+C5 -> 134435 | F5: 161000 | G5: 9550.85 | H5: =F5+G5 -> 170550.85
B6: 6000 | C6: 16800 | D6: =B6+C6 -> 22800 | F6: 7500 | G6: 28474.58 | H6: =F6+G6 -> 35974.58
B7: 0 | C7: 40500 | D7: =B7+C7 -> 40500 | F7: 0 | G7: 68644.07 | H7: =F7+G7 -> 68644.07
B8: 0 | C8: 29700 | D8: =B8+C8 -> 29700 | F8: 0 | G8: 50338.98 | H8: =F8+G8 -> 50338.98
B9: 0 | C9: 40500 | D9: =B9+C9 -> 40500 | F9: 0 | G9: 68644.07 | H9: =F9+G9 -> 68644.07
B10: 800 | C10: 19800 | D10: =B10+C10 -> 20600 | F10: 1000 | G10: 33559.32 | H10: =F10+G10 -> 34559.32
B11: 0 | C11: 18181.82 | D11: =B11+C11 -> 18181.82 | F11: 0 | G11: 30816.64 | H11: =F11+G11 -> 30816.64
B12: 56544 | C12: 15010 | D12: =B12+C12 -> 71554 | F12: 70680 | G12: 25440.68 | H12: =F12+G12 -> 96120.68
B13: 0 | C13: 9200 | D13: =B13+C13 -> 9200 | F13: 0 | G13: 15593.22 | H13: =F13+G13 -> 15593.22
B14: 6910 | C14: 6500 | D14: =B14+C14 -> 13410 | F14: 8637.5 | G14: 11016.95 | H14: =F14+G14 -> 19654.45
... B19: 52322 | C19: 40242 | D19: =B19+C19 -> 92564 | F19: 67079.49 | G19: 55891.67 | H19: =F19+G19 -> 122971.16

Sheet Resumo
B2: RESUMO CUSTOS
B3: TIPO | C3: VALOR
B4: TOTAL PROPOSTA ORÇ. | C4: {='Gerenciamento Custo'!D42:E42} -> 1505613.8 | D4: 0 | H4: Entrada 12/06 | I4: 0.05 | J4: =I4*$C$4 -> 75280.688 | L4: =SUM(J4:J6)-12000 -> 665526.19
B5: VALOR CUSTO ORÇ. | C5: {='Gerenciamento Custo'!F42:G42} -> 1004567.7 | D5: 0 | H5: Entrada 16/06 | I5: 0.15 | J5: =I5*$C$4 -> 225842.06
B6: TOTAL REALIZADO | C6: {='Gerenciamento Custo'!J42:K42} -> 5132 | D6: 0 | H6: Medição 1 - 10/07 | I6: 0.25 | J6: =I6*$C$4 -> 376403.44
B7: TOTAL A REALIZAR | C7: {='Gerenciamento Custo'!L42:M42} -> 4750 | D7: 0 | H7: Medição 2 - 10/08 | I7: 0.2 | J7: =I7*$C$4 -> 301122.75
B8: CUSTO REAL DA OBRA | C8: =C6+C7 -> 9882 | H8: Medição 3 - 10/09 | I8: 0.2 | J8: =I8*$C$4 -> 301122.75
B9: VERBA DISPONIVEL | C9: =C5-C8 -> 994685.74 | H9: Medição 4 - 05/10 | I9: 0.1 | J9: =I9*$C$4 -> 150561.38
H10: Medição 5 - 20/11 | I10: 0.05 | J10: =I10*$C$4 -> 75280.688
B11: FATURAMENTO DIRETO | C11: 0 | I11: =SUM(I4:I10) -> 1 | J11: =SUM(J4:J10) -> 1505613.8
B12: VALOR RECEBIDO | C12: =J4+J5 -> 301122.75
B13: VALOR A RECEBER | C13: =C4-C12 -> 1204491
B15: MARGEM PREVISTA
B16: MARGEM LIQUIDA | C16: =C4-C5-C17-C18-C24 -> 253967.8 | E16: =C16/C4 -> 0.16868058 | F16: =C16/3.5 -> 72562.229
B17: ADMINISTRAÇÃO | C17: =C4*0.103 -> 155078.22 | E17: =C17/C4 -> 0.103 | F17: =C17/3.5 -> 44308.062
B18: EMPRESTIMO | C18: =16000*3.5 -> 56000 | E18: =C18/C4 -> 0.037194134 | F18: =C18/3.5 -> 16000
B20: MARGEM REAL
B21: LUCRO LIQUIDO | C21: =C4-C8-C22 -> 1340653.5 | E21: =C21/C4 -> 0.89043656 | F21: =C21/3 -> 446884.51
B22: ADMINISTRAÇÃO | C22: =C17 -> 155078.22 | E22: =C22/C4 -> 0.103 | F22: =C22/3 -> 51692.739
B23: IMPOSTOS
B24: TOTAL PROJETADO | C24: 36000
B25: Mês 06 | C25: 12000
B26: Mês 07
B27: Mês 08
B28: Mês 09

Sheet Planilha1
A1: CRONOGRAMA FÍSICO-FINANCEIRO — POR ETAPA (reorganizado da aba Previsao)
A2: Mesmos custos da Previsao, ordenados por sequência de obra (EAP) em vez de por mês. Veks = desembolso Veks · Fat = faturamento direto.
A3: Etapa / Item | B3: Veks (R$) | C3: Fat Direto (R$) | D3: Total (R$) | E3: % | F3: jun | H3: jul | J3: ago | L3: set | N3: out | Q3: Resumo mês
F4: Veks | G4: Fat Direto | H4: Veks | I4: Fat Direto | J4: Veks | K4: Fat Direto | L4: Veks | M4: Fat Direto | N4: Veks | O4: Fat Direto | P4: 1505613.8 | Q4: Item | R4: jun | S4: jul | T4: ago | U4: set | V4: out | W4: Nov | X4: Total
A5: Preliminares e projetos | B5: =SUM(B6:B10) -> 51159.69 | C5: =SUM(C6:C10) -> 0 | D5: =SUM(D6:D10) -> 51159.69 | E5: =SUM(E6:E10) -> 0.033979292 | F5: =SUM(F6:F10) -> 46409.69 | G5: =SUM(G6:G10) -> 0 | H5: =SUM(H6:H10) -> 4750 | I5: =SUM(I6:I10) -> 0 | ... O5: =SUM(O6:O10) -> 0 | Q5: % | R5: 0.2 | S5: 0.3 | T5: 0.2 | U5: 0.2 | V5: 0.05 | W5: 0.05 | X5: =SUM(R5:W5) -> 1
A6: CUSTOS EXTERNOS | B6: 34219.69 | D6: =B6+C6 -> 34219.69 | E6: =D6/$X$6 -> 0.022728067 | F6: =D6 -> 34219.69 | Q6: MEDIÇÕES | R6: =R5*$P$4 -> 301122.75 | S6: =S5*$P$4 -> 451684.13 | T6: =T5*$P$4 -> 301122.75 | U6: =U5*$P$4 -> 301122.75 | V6: =V5*$P$4 -> 75280.688 | W6: =W5*$P$4 -> 75280.688 | X6: =SUM(R6:W6) -> 1505613.8
A7: PROJETOS | B7: 9500 | D7: =B7+C7 -> 9500 | E7: =D7/$X$6 -> 0.0063097192 | F7: =D7/2 -> 4750 | H7: =D7/2 -> 4750 | Q7: ENTRADA | R7: =R6 -> 301122.75 | S7: =S6-S14-S15 -> 181221.09 | T7: =T6-T14-T15 -> 127003.99 | U7: =U6-U14-U15 -> 127003.99 | V7: =V6-V14-V15 -> 65117.795 | W7: =W6-W14-W15 -> 65117.795
A8: TOPOGRAFO | B8: 3000 | D8: =B8+C8 -> 3000 | E8: =D8/$X$6 -> 0.0019925429 | F8: =D8 -> 3000
A9: ASO FUNC. | B9: 3000 | D9: =B9+C9 -> 3000 | E9: =D9/$X$6 -> 0.0019925429 | F9: =D9 -> 3000
A10: PGR | PCMSO | B10: 1440 | D10: =B10+C10 -> 1440 | E10: =D10/$X$6 -> 0.00095642059 | F10: =D10 -> 1440 | Q10: CAIXA INICIAL | R10: =R6 -> 301122.75 | S10: =S7+R11 -> 341994.16 | T10: =T7+S11 -> 267658.14 | U10: =U7+T11 -> 213802.13 | V10: =V7+U11 -> 115379.93 | W10: =W7+V11 -> 65627.72
A11: Fundação | B11: =SUM(B12:B17) -> 68100 | C11: =SUM(C12:C17) -> 87882.64 | D11: =SUM(D12:D17) -> 155982.64 | E11: =D11/$X$6 -> 0.1036007 | F11: =SUM(F12:F17) -> 26940 | G11: =SUM(G12:G17) -> 0 | H11: =SUM(H12:H17) -> 35280 | I11: =SUM(I12:I17) -> 87882.64 | J11: =SUM(J12:J17) -> 5880 | K11: =SUM(K12:K17) -> 0 | L11: =SUM(L12:L17) -> 0 | M11: =SUM(M12:M17) -> 0 | ... O11: =SUM(O12:O17) -> 0 | Q11: CAIXA FINAL | R11: =R10-R13 -> 160773.06 | S11: =S10-S13 -> 140654.16 | T11: =T10-T13 -> 86798.143 | U11: =U10-U13 -> 50262.13 | V11: =V10-V13 -> 509.9252 | W11: =W10-W13 -> 65627.72
A12: M.O FUNDAÇÃO | B12: =49000+9800 -> 58800 | D12: =B12+C12 -> 58800 | E12: =D12/$X$6 -> 0.039053841 | F12: =D12*0.3 -> 17640 | H12: =D12*0.6 -> 35280 | J12: =D12*0.1 -> 5880
A13: MATERIAL FUNDAÇÃO - FERRAGEM | B13: 0 | C13: 47882.64 | D13: =B13+C13 -> 47882.64 | E13: =D13/$X$6 -> 0.031802738 | I13: =C13 -> 47882.64 | Q13: GASTO VEKS | R13: =F55 -> 140349.69 | S13: =H55 -> 201340 | T13: =J55 -> 180860 | U13: =L55 -> 163540 | V13: =N55 -> 114870 | W13: 0 | X13: =SUM(R13:W14) -> 1351734.3
A14: MATERIAL FUNDAÇÃO | C14: 40000 | D14: =B14+C14 -> 40000 | E14: =D14/$X$6 -> 0.026567239 | I14: =D14 -> 40000 | Q14: FAT DIRETO | R14: =G55 -> 0 | S14: =I55 -> 242179.97 | T14: =K55 -> 154297.33 | U14: =M55 -> 154297.33 | V14: =O55 -> 0
A15: RETROESCAVADEIRA | B15: 3800 | D15: =B15+C15 -> 3800 | E15: =D15/$X$6 -> 0.0025238877 | F15: =D15 -> 3800 | R15: 0 | S15: =(S6-S14)*$R$21 -> 28283.061 | T15: =(T6-T14)*$R$21 -> 19821.432 | U15: =(U6-U14)*$R$21 -> 19821.432 | V15: =(V6-V14)*$R$21 -> 10162.893 | W15: =(W6-W14)*$R$21 -> 10162.893
A16: MUNCK | B16: 3000 | D16: =B16+C16 -> 3000 | E16: =D16/$X$6 -> 0.0019925429 | F16: =D16 -> 3000 | Q16: IMPOSTO
A17: PERFURATRIZ | B17: 2500 | D17: =B17+C17 -> 2500 | E17: =D17/$X$6 -> 0.0016604524 | F17: =D17 -> 2500
A18: Estrutura metálica (cobertura) | B18: =SUM(B20:B20) -> 0 | C18: =SUM(C19:C20) -> 332892 | D18: =SUM(D19:D20) -> 332892 | E18: =D18/$X$6 -> 0.22110053 | F18: =SUM(F20:F20) -> 0 | G18: =SUM(G20:G20) -> 0 | H18: =SUM(H19:H20) -> 0 | I18: =SUM(I19:I20) -> 110964 | J18: =SUM(J19:J20) -> 0 | K18: =SUM(K19:K20) -> 110964 | L18: =SUM(L19:L20) -> 0 | M18: =SUM(M19:M20) -> 110964 | N18: =SUM(N20:N20) -> 0 | O18: =SUM(O20:O20) -> 0 | Q18: % IMPOSTOS
A19: M.O ESTRUTURA METALICA COB. | C19: 172320 | D19: =B19+C19 -> 172320 | E19: =D19/$X$6 -> 0.11445166 | I19: =$D$19/3 -> 57440 | K19: =$D$19/3 -> 57440 | M19: =$D$19/3 -> 57440 | Q19: ISS | R19: 0.04
A20: MATERIAL ESTRUTURA METALICA COB. | C20: 160572 | D20: =B20+C20 -> 160572 | E20: =D20/$X$6 -> 0.10664887 | I20: =$D$20/3 -> 53524 | K20: =$D$20/3 -> 53524 | M20: =$D$20/3 -> 53524 | Q20: DAS | R20: =13.5%-4% -> 0.095
A21: Estrutura LSF (baias) | B21: =SUM(B22:B23) -> 15000 | C21: =SUM(C22:C23) -> 55000 | D21: =SUM(D22:D23) -> 70000 | E21: =D21/$X$6 -> 0.046492668 | F21: =SUM(F22:F23) -> 0 | G21: =SUM(G22:G23) -> 0 | H21: =SUM(H22:H23) -> 15000 | I21: =SUM(I22:I23) -> 18333.333 | J21: =SUM(J22:J23) -> 0 | K21: =SUM(K22:K23) -> 18333.333 | L21: =SUM(L22:L23) -> 0 | M21: =SUM(M22:M23) -> 18333.333 | ... O21: =SUM(O22:O23) -> 0 | Q21: TOTAL | R21: =R20+R19 -> 0.135
A22: AÇO LSF | C22: 55000 | D22: =B22+C22 -> 55000 | E22: =D22/$X$6 -> 0.036529953 | I22: =$D$22/3 -> 18333.333 | K22: =$D$22/3 -> 18333.333 | M22: =$D$22/3 -> 18333.333
A23: M.O AÇO LSF | B23: 15000 | D23: =B23+C23 -> 15000 | E23: =D23/$X$6 -> 0.0099627145 | H23: =D23 -> 15000
A24: Cobertura (Shingle) | B24: =SUM(B25) -> 75400 | C24: =SUM(C25) -> 0 | D24: =SUM(D25) -> 75400 | E24: =D24/$X$6 -> 0.050079245 | F24: =SUM(F25) -> 0 | G24: =SUM(G25) -> 0 | H24: =SUM(H25) -> 11310 | I24: =SUM(I25) -> 0 | J24: =SUM(J25) -> 15080 | K24: =SUM(K25) -> 0 | L24: =SUM(L25) -> 45240 | M24: =SUM(M25) -> 0 | ... O24: =SUM(O25) -> 0
A25: M.O SHINGLE | B25: =65*1160 -> 75400 | D25: =B25+C25 -> 75400 | E25: =D25/$X$6 -> 0.050079245 | H25: =$D$25*0.15 -> 11310 | J25: =$D$25*0.2 -> 15080 | L25: =$D$25*0.6 -> 45240 | N25: =$D$25*0.05 -> 3770
A26: Fechamentos | B26: =SUM(B27:B29) -> 51000 | C26: =SUM(C27:C29) -> 75000 | D26: =SUM(D27:D29) -> 126000 | E26: =D26/$X$6 -> 0.083686802 | F26: =SUM(F27:F29) -> 0 | G26: =SUM(G27:G29) -> 0 | H26: =SUM(H27:H29) -> 25500 | I26: =SUM(I27:I29) -> 25000 | J26: =SUM(J27:J29) -> 25500 | K26: =SUM(K27:K29) -> 25000 | L26: =SUM(L27:L29) -> 0 | M26: =SUM(M27:M29) -> 25000 | ... O26: =SUM(O27:O29) -> 0
A27: MATERIAIS DE PLACA CIMENTICIA | C27: 75000 | D27: =B27+C27 -> 75000 | E27: =D27/$X$6 -> 0.049813572 | I27: =D27/3 -> 25000 | K27: =D27/3 -> 25000 | M27: =D27/3 -> 25000
A28: M.O PLAQUEAMENTO | B28: 30000 | D28: =B28+C28 -> 30000 | E28: =D28/$X$6 -> 0.019925429 | H28: =D28/2 -> 15000 | J28: =D28/2 -> 15000
A29: BASECOAT | B29: 21000 | D29: =B29+C29 -> 21000 | E29: =D29/$X$6 -> 0.0139478 | H29: =D29/2 -> 10500 | J29: =D29/2 -> 10500
A30: Pintura / Stain | B30: =SUM(B31:B33) -> 51700 | C30: =SUM(C31:C33) -> 0 | D30: =SUM(D31:D33) -> 51700 | E30: =D30/$X$6 -> 0.034338156 | F30: =SUM(F31:F33) -> 0 | G30: =SUM(G31:G33) -> 0 | H30: =SUM(H31:H33) -> 0 | I30: =SUM(I31:I33) -> 0 | J30: =SUM(J31:J33) -> 16500 | K30: =SUM(K31:K33) -> 0 | L30: =SUM(L31:L33) -> 17600 | M30: =SUM(M31:M33) -> 0 | ... O30: =SUM(O31:O33) -> 0
A31: PINTURA Estrutura | B31: 35200 | D31: =B31+C31 -> 35200 | E31: =D31/$X$6 -> 0.02337917 | L31: =B31/2 -> 17600 | N31: =B31/2 -> 17600
A32: M.O APLICAÇÃO DE STAIN | B32: 15500 | D32: =B32+C32 -> 15500 | E32: =D32/$X$6 -> 0.010294805 | J32: 15500
A33: MATERIAL STAIN | B33: 1000 | D33: =B33+C33 -> 1000 | E33: =D33/$X$6 -> 0.00066418096 | J33: 1000
A34: Portões | B34: =SUM(B35) -> 10000 | C34: =SUM(C35) -> 0 | D34: =SUM(D35) -> 10000 | E34: =D34/$X$6 -> 0.0066418096 | F34: =SUM(F35) -> 0 | G34: =SUM(G35) -> 0 | H34: =SUM(H35) -> 0 | I34: =SUM(I35) -> 0 | J34: =SUM(J35) -> 10000 | K34: =SUM(K35) -> 0 | L34: =SUM(L35) -> 0 | M34: =SUM(M35) -> 0 | ... O34: =SUM(O35) -> 0
A35: CARPINTARIA | B35: 10000 | D35: =B35+C35 -> 10000 | E35: =D35/$X$6 -> 0.0066418096 | J35: 10000
A36: Pedra moledo | B36: =SUM(B37) -> 10000 | C36: =SUM(C37) -> 0 | D36: =SUM(D37) -> 10000 | E36: =D36/$X$6 -> 0.0066418096 | F36: =SUM(F37) -> 0 | G36: =SUM(G37) -> 0 | H36: =SUM(H37) -> 0 | I36: =SUM(I37) -> 0 | J36: =SUM(J37) -> 10000 | K36: =SUM(K37) -> 0 | L36: =SUM(L37) -> 0 | M36: =SUM(M37) -> 0 | ... O36: =SUM(O37) -> 0
A37: ESTRUTURA NA TORA PARA PEDRA MOLEDO | B37: 10000 | D37: =B37+C37 -> 10000 | E37: =D37/$X$6 -> 0.0066418096 | J37: 10000
A38: Hidráulica | B38: =SUM(B39:B40) -> 4400 | C38: =SUM(C39:C40) -> 0 | D38: =SUM(D39:D40) -> 4400 | E38: =D38/$X$6 -> 0.0029223962 | F38: =SUM(F39:F40) -> 0 | G38: =SUM(G39:G40) -> 0 | H38: =SUM(H39:H40) -> 0 | I38: =SUM(I39:I40) -> 0 | J38: =SUM(J39:J40) -> 4400 | K38: =SUM(K39:K40) -> 0 | L38: =SUM(L39:L40) -> 0 | M38: =SUM(M39:M40) -> 0 | ... O38: =SUM(O39:O40) -> 0
A39: M.O HIDRAULICA | B39: 2400 | D39: =B39+C39 -> 2400 | E39: =D39/$X$6 -> 0.0015940343 | J39: 2400
A40: MATERIAL HIDRAULICO | B40: 2000 | D40: =B40+C40 -> 2000 | E40: =D40/$X$6 -> 0.0013283619 | J40: 2000
...

Sheet Mão de Obra
B2: Tipo | C2: Descrição | D2: Mês | E2: Valor | G2: Rótulos de Linha | H2: Soma de Valor
G3: (vazio)
G4: Total Geral

Sheet Materiais
B2: Tipo | C2: Descrição | D2: Mês | E2: Valor | G2: Rótulos de Linha | H2: Soma de Valor
G3: (vazio)
G4: Total Geral

Sheet Refeição + Transporte
B2: Tipo | C2: Descrição | D2: Mês | E2: Valor | G2: Rótulos de Linha | H2: Soma de Valor
B3: Visita em obra | C3: Alan e Paulo (Carro da empresa) | D3: 46184 | E3: =66+66+250 -> 382 | G3: (vazio)
G4: Visita em obra | H4: 382
G5: Total Geral | H5: 382

Sheet Locação + Frete
B2: Tipo | C2: Descrição | D2: Mês | E2: Valor | G2: Rótulos de Linha | H2: Soma de Valor
B3: Projetos (Realizado) | C3: Projeto para metalica de cobertura | D3: 46188 | E3: =4000/2 -> 2000 | G3: (vazio)
B4: Projetos (Realizado) | C4: Projeto fundação | D4: 46188 | E4: =2500/2 -> 1250 | G4: Projetos (Realizado) | H4: 4750
B5: Projetos (Realizado) | C5: Projeto de LSF | D5: 46188 | E5: =3000/2 -> 1500 | G5: Projetos (A realizar) | H5: 4750
B6: Projetos (A realizar) | C6: Projeto para metalica de cobertura | D6: 46188 | E6: =4000/2 -> 2000 | G6: Total Geral | H6: 9500
B7: Projetos (A realizar) | C7: Projeto fundação | D7: 46188 | E7: =2500/2 -> 1250
B8: Projetos (A realizar) | C8: Projeto de LSF | D8: 46188 | E8: =3000/2 -> 1500

Sheet Fat Direto
B2: Tipo | C2: Descrição | D2: Mês | E2: Valor | G2: Rótulos de Linha | H2: Soma de Valor
G3: (vazio)
G4: Total Geral
L7: NF
L8: 357
