Workbook

Sheet Gerenciamento Custo
B2: ITEM | C2: TIPO | D2: VALOR ORÇADO VENDA | F2: VALOR ORÇADO CUSTO | H2: VALOR PREVISTO | J2: VALOR REALIZADO | L2: VALOR A REALIZAR | N2: SALDO | P2: MARGEM Venda X Custo | Q2: MARGEM Custo X Realizado | R2: MARGEM Venda X Realizado | T2: TOTAL PAGO | U2: FAT DIRETO | V2: FALTA PAGAR
B3: Execução completa de mão de obra especializada em sistema Light Steel Frame, incluindo a emissão de ART e marcação da obra conforme projeto executivo, montagem e fixação dos painéis estruturais, instalação de guias e montantes, aplicação de mantas de vedação, impermeabilização e isolamento, chumbamento e verticalização dos painéis, execução de estruturas de laje e cobertura, instalação de telhas, além dos sistemas de fechamento externo com placa cimentícia, aplicação de tela e basecoat nas fachadas, fechamento interno com chapas OSB, ST e RU, instalação de isolamentos termoacústicos e execução de forros, garantindo o desempenho estrutural, térmico e acústico da edificação. | C3: Material | E3: =SUM(D3:D4) -> 137000 | G3: =SUM(F3:F4) -> 106065.4 | I3: =SUM(H3:H4) -> 0 | K3: =SUM(J3:J4) -> 42278.75 | M3: =SUM(L3:L4) -> 6581.25 | N3: =F3-(L3+H3) -> 0 | P3: =D3-F3 -> 0 | Q3: =F3-L3 -> 0 | R3: =D3-L3 -> 0 | T3: =Resumo!C12 -> 97042.5 | U3: =Resumo!C11 -> 0 | V3: =D10-U3-T3 -> 39957.5
C4: Mão de obra | D4: 137000 | F4: 106065.4 | J4: =GETPIVOTDATA("Valor",'Mão de Obra'!$G$2) -> 42278.75 | L4: ='A Realizar'!C14 -> 6581.25 | N4: =F4-(L4+J4) -> 57205.4 | P4: =D4-F4 -> 30934.6 | Q4: =F4-L4 -> 99484.15 | R4: =D4-L4 -> 130418.75
B5: A REALIZAR PARA INTERNO | G5: =SUM(F5) -> 0 | I5: =SUM(H5) -> 0 | K5: =SUM(J5) -> 0 | L5: ='A Realizar'!I21 -> 20000 | M5: =SUM(L5) -> 20000 | N5: =F5-(L5+J5) -> -20000 | P5: =D5-F5 -> 0 | Q5: =F5-L5 -> -20000 | R5: =D5-L5 -> -20000
K6: =SUM(J6) -> 0 | M6: =SUM(L6) -> 0 | N6: =F6-(L6+J6) -> 0 | P6: =D6-F6 -> 0 | Q6: =F6-L6 -> 0 | R6: =D6-L6 -> 0
B7: Custos equipe (alimentação + transporte + outros) | J7: =GETPIVOTDATA("Valor",'Refeição + Transporte'!$G$2) -> 32629.93 | K7: =SUM(J7) -> 32629.93 | M7: =SUM(L7) -> 0 | N7: =F7-(L7+J7) -> -32629.93 | P7: =D7-F7 -> 0 | Q7: =F7-L7 -> 0 | R7: =D7-L7 -> 0
K8: =SUM(J8) -> 0 | M8: =SUM(L8) -> 0 | N8: =F8-(L8+J8) -> 0 | P8: =D8-F8 -> 0 | Q8: =F8-L8 -> 0 | R8: =D8-L8 -> 0
B9: Locação + fretes + ourtros | J9: =GETPIVOTDATA("Valor",'Locação + Frete'!$G$2) -> 17710.3 | K9: =SUM(J9) -> 17710.3 | M9: =SUM(L9) -> 0 | N9: =F9-(L9+J9) -> -17710.3 | P9: =D9-F9 -> 0 | Q9: =F9-L9 -> 0 | R9: =D9-L9 -> 0
B10: TOTAL | D10: =SUM(E3:E9) -> 137000 | F10: =SUM(G3:G9) -> 106065.4 | H10: =SUM(I3:I9) -> 0 | J10: =SUM(K3:K9) -> 92618.98 | L10: =SUM(M3:M9) -> 26581.25 | N10: =SUM(N3:N9) -> -13134.83 | P10: =SUM(P3:P9) -> 30934.6 | Q10: =SUM(Q3:Q9) -> 79484.15 | R10: =SUM(R3:R9) -> 110418.75

Sheet A Realizar
B3: INTERNO
B4: CUSTO EQUIPE | C4: EQUIPE | D4: DIARIA | E4: JANTA E CAFÉ | F4: ALMOÇO | G4: SUBTOTAL | H4: TOTAL EQUIPE | I4: DIAS | J4: TOTAL ITEM
C5: Matheus | D5: 250 | E5: =340/7 -> 48.571429 | F5: 30 | G5: =SUM(D5:F5) -> 328.57143 | H5: =SUM(G5:G9) -> 1064.2857 | I5: 0 | J5: =H5*I5 -> 0
C6: Roger | D6: 200 | E6: =340/7 -> 48.571429 | F6: 30 | G6: =SUM(D6:F6) -> 278.57143
C7: Josué | D7: 150 | E7: =340/7 -> 48.571429 | F7: 30 | G7: =SUM(D7:F7) -> 228.57143
C8: Leonardo | D8: 150 | E8: =340/7 -> 48.571429 | F8: 30 | G8: =SUM(D8:F8) -> 228.57143
G9: =SUM(D9:F9) -> 0
B12: BASECOAT | C12: 260 | D12: 45 | E12: =(D12*C12)-5118.75 -> 6581.25
F13: Interno parede | G13: =180*0.6 -> 108 | H13: 35 | I13: =H13*G13 -> 3780
B14: CUSTO TOTAL A REALIZAR | C14: =J5+E12 -> 6581.25 | F14: Forro interno | G14: 273.1 | H14: 40 | I14: =H14*G14 -> 10924
I15: =I13+I14 -> 14704
F17: TELHADO | G17: 230 | H17: 35 | I17: 3500
I19: =I15+I17 -> 18204
I21: 20000

Sheet Resumo
B2: RESUMO CUSTOS | K2: Dia 29/05
B3: TIPO | C3: VALOR | G3: Recebido | H3: Gasto | I3: Diferença | K3: Medição | L3: Gasto previsto
B4: TOTAL PROPOSTA ORÇ. | C4: {='Gerenciamento Custo'!D10:E10} -> 137000 | D4: 0 | G4: =C12 -> 97042.5 | H4: =C6 -> 92618.98 | I4: =G4-H4 -> 4423.52 | K4: 37050
B5: VALOR CUSTO ORÇ. | C5: {='Gerenciamento Custo'!F10:G10} -> 106065.4 | D5: 0
B6: TOTAL REALIZADO | C6: {='Gerenciamento Custo'!J10:K10} -> 92618.98 | D6: 0
B7: TOTAL A REALIZAR | C7: {='Gerenciamento Custo'!L10:M10} -> 26581.25 | D7: 0
B8: CUSTO REAL DA OBRA | C8: =C6+C7 -> 119200.23
B9: VERBA DISPONIVEL | C9: =C5-C8 -> -13134.83
B11: FATURAMENTO DIRETO | C11: 0
B12: VALOR RECEBIDO | C12: =3000+8000+23000+33750+9200+20092.5 -> 97042.5
B13: VALOR A RECEBER | C13: =C4-C12 -> 39957.5
B15: MARGEM PREVISTA
B16: LUCRO LIQUIDO | C16: =C4-C5-C17 -> 30934.6 | E16: =C16/C4 -> 0.2258 | F16: =C16/3 -> 10311.533
B17: ADMINISTRAÇÃO | E17: =C17/C4 -> 0 | F17: =C17/3 -> 0
B19: MARGEM REAL
B20: LUCRO LIQUIDO | C20: =C4-C8-C21 -> 17799.77 | E20: =C20/C8 -> 0.14932664 | F20: =C20/3 -> 5933.2567
B21: ADMINISTRAÇÃO | E21: =C21/C8 -> 0 | F21: =C21/3 -> 0

Sheet Mão de Obra
B2: Tipo | C2: Descrição | D2: Mês | E2: Valor | G2: Rótulos de Linha | H2: Soma de Valor
B3: Aço LSF | C3: Matheus (lider) | D3: 46118 | E3: 1250 | G3: (vazio)
B4: Aço LSF | C4: Roger (montador) | D4: 46118 | E4: 1000 | G4: OUTROS | H4: 18738.75
B5: Aço LSF | C5: Vinicius (Ajudante) | D5: 46118 | E5: 750 | G5: Aço LSF | H5: 23540
B6: Aço LSF | C6: Leonardo (Ajudante) | D6: 46118 | E6: 750 | G6: Total Geral | H6: 42278.75
B7: Aço LSF | C7: Matheus (lider) | D7: 46119 | E7: 250
B8: Aço LSF | C8: Roger (montador) | D8: 46119 | E8: 200
B9: Aço LSF | C9: Vinicius (Ajudante) | D9: 46119 | E9: 150
B10: Aço LSF | C10: Leonardo (Ajudante) | D10: 46119 | E10: 150
B11: Aço LSF | C11: Matheus (lider) | D11: 46120 | E11: 250
B12: Aço LSF | C12: Roger (montador) | D12: 46120 | E12: 200
B13: Aço LSF | C13: Vinicius (Ajudante) | D13: 46120 | E13: 150
B14: Aço LSF | C14: Leonardo (Ajudante) | D14: 46120 | E14: 150
B15: Aço LSF | C15: Matheus (lider) | D15: 46121 | E15: 250
B16: Aço LSF | C16: Roger (montador) | D16: 46121 | E16: 200
B17: Aço LSF | C17: Vinicius (Ajudante) | D17: 46121 | E17: 150
B18: Aço LSF | C18: Leonardo (Ajudante) | D18: 46121 | E18: 150
B19: Aço LSF | C19: Vinicius (Ajudante) 10/04 - 30/04 | D19: - | E19: 2250
B20: Aço LSF | C20: Roger (montador) 10/04 - 15/05 | D20: - | E20: 4200
B21: Aço LSF | C21: Matheus (lider) 10/04 - 15/05 | D21: - | E21: 5250
B22: Aço LSF | C22: Leonardo (Ajudante) 10/04 - 15/05 | D22: - | E22: 3150
B23: Aço LSF | C23: Marcos (ajudanta) 10/04 - 30/04 | D23: - | E23: 1940
B24: Aço LSF | C24: Josué (ajudante) 11/05 - 15/05 | D24: - | E24: 750
B25: OUTROS | C25: Eduardo - Basecoat | D25: 46171 | E25: 6348.75
B26: OUTROS | C26: Gustavo - Ajudante Vila Velha | D26: 46162 | E26: 780
B27: OUTROS | C27: Davi - Ajudante Vila Velha | D27: 46162 | E27: 260
B28: OUTROS | C28: Roger (montador) 15.05 a 05.06 | D28: 46178 | E28: 3400
B29: OUTROS | C29: Leonardo (Ajudante) 15.05 a 30.05 | D29: 46178 | E29: 1650
B30: OUTROS | C30: Matheus (lider) 15.05 a 05.06 | D30: 46178 | E30: 4500
B31: OUTROS | C31: Josué (ajudante) 15.05 a 30.05 | D31: 46178 | E31: 1800

Sheet Materiais
B2: Tipo | C2: Descrição | D2: Mês | E2: Valor | G2: Rótulos de Linha | H2: Soma de Valor
G3: (vazio)
G4: Total Geral

Sheet Refeição + Transporte
B2: Tipo | C2: Descrição | D2: Mês | E2: Valor | G2: Rótulos de Linha | H2: Soma de Valor
B3: Viagem ida | C3: Geral | D3: 46108 | E3: 2046.4 | G3: (vazio) | H3: 410
B4: Viagem ida | C4: Despesas da viagem para Roger | D4: 46110 | E4: 400 | G4: Refeição | H4: 4736
B5: Viagem ida | C5: Despesas da viagem para Abel | D5: 46110 | E5: 800 | G5: Viagem ida | H5: 7459.29
B6: Viagem ida | C6: Abel organização casa | D6: 46113 | E6: 1000 | G6: Café e Janta | H6: 12510
B7: Refeição | C7: Restaurante Vila velha - Equipe geral | D7: 46118 | E7: 524 | G7: Bonus 01 | H7: 4400
B8: Café e Janta | C8: Matheus (lider) | D8: 46118 | E8: 640 | G8: Combustivel | H8: 1582.08
B9: Café e Janta | C9: Roger (montador) | D9: 46118 | E9: 640 | G9: Uber | H9: 55.67
B10: Café e Janta | C10: Vinicius (Ajudante) | D10: 46118 | E10: 640 | G10: Bonus 02
B11: Café e Janta | C11: Leonardo (Ajudante) | D11: 46118 | E11: 640 | G11: Ferramentas | H11: 614
B12: Café e Janta | C12: Matheus (lider) | D12: 46125 | E12: 340 | G12: Viagem Volta | H12: 862.89
B13: Café e Janta | C13: Roger (montador) | D13: 46125 | E13: 340 | G13: Total Geral | H13: 32629.93
B14: Café e Janta | C14: Vinicius (Ajudante) | D14: 46125 | E14: 340
B15: Café e Janta | C15: Leonardo (Ajudante) | D15: 46125 | E15: 340
B16: Café e Janta | C16: Equipe | D16: 46132 | E16: 1700
B17: Refeição | C17: Restaurante Vila velha - Equipe geral | D17: 46135 | E17: 1501
B18: Café e Janta | C18: Equipe | D18: 46139 | E18: 1700
B19: Refeição | C19: Restaurante Vila velha - Equipe geral | D19: 46147 | E19: 773
B20: Combustivel | D20: 46147 | E20: 542.08
B21: Viagem ida | C21: Abel | D21: 46152 | E21: 1200
B22: Viagem ida | C22: Matheus (lider) | D22: 46152 | E22: 400
B23: Café e Janta | C23: Equipe | D23: 46153 | E23: 1360
B24: Café e Janta | C24: Josue | D24: 46153 | E24: 340
B25: Combustivel | D25: 46155 | E25: 840
B26: Ferramentas | C26: Abel - Reembolso Ferramentas | D26: 46155 | E26: 255
B27: Viagem Volta | C27: Abel - Passagem | D27: 46155 | E27: 412.89
B28: Viagem ida | C28: Viagem volta Abel | D28: 46156 | E28: 412.89
B29: Café e Janta | C29: Josue Dias de Andrade | D29: 46167 | E29: 340
B30: Café e Janta | C30: Leonardo Oliveira Santos | D30: 46167 | E30: 340
B31: Café e Janta | C31: Matheus Antonio Barbosa dos Santos | D31: 46167 | E31: 340
B32: Café e Janta | C32: Roger Rivas | D32: 46167 | E32: 340
B33: Ferramentas | C33: Matheus - Reembolso Ferramentas | D33: 46168 | E33: 112
B34: Combustivel | C34: Matheus | D34: 46168 | E34: 200
B35: Ferramentas | C35: Matheus - Reembolso Ferramentas | D35: 46171 | E35: 247
B36: Refeição | C36: Restaurante Vila velha - Equipe geral | D36: 46171 | E36: 1938
B37: Café e Janta | C37: Matheus e Roger | D37: 46175 | E37: 370
B38: Viagem volta | C38: Mateus - Custos Viagem | D38: 46176 | E38: 450
B39: Uber | D39: - | E39: 55.67
B40: Café e Janta | C40: Alimentação equipe | D40: 46153 | E40: 1760
B41: Viagem ida | C41: Abel - Despesas Viagem | D41: 46153 | E41: 1200
...

Sheet Locação + Frete
B2: Tipo | C2: Descrição | D2: Mês | E2: Valor | G2: Rótulos de Linha | H2: Soma de Valor
B3: Frete | C3: Caminhão Muck (descarregamento) | D3: 46113 | E3: 1000 | G3: (vazio)
B4: Locação | C4: Mestre da obra | D4: 46113 | E4: 410 | G4: Locação | H4: 6467
B5: Frete | C5: Mudança de material do terreno | D5: 46120 | E5: 750 | G5: Frete | H5: 1750
B6: Alojamento | C6: Aluguel da casa (Calção - Será estornado ao final do contrato) | D6: 46115 | E6: 3000 | G6: Alojamento | H6: 9000
B7: Alojamento | C7: Aluguel da casa (1/2) | D7: 46119 | E7: 3000 | G7: Estadia Abel | H7: 493.3
B8: Alojamento | C8: Aluguel da casa (2/2) | D8: 46147 | E8: 3000 | G8: Total Geral | H8: 17710.3
B9: Estadia Abel | C9: Hotel | D9: 46125 | E9: 493.3
B10: Locação | C10: Mestre da obra | D10: 46127 | E10: 864
B11: Locação | C11: Mestre da obra | D11: 46135 | E11: 345
B12: Locação | C12: Mestre da obra | D12: 46141 | E12: 240
B13: Locação | C13: Mestre da obra | D13: 46149 | E13: 410
B14: Locação | C14: Mestre da obra | D14: 46162 | E14: 642
B15: Locação | C15: Movimentação de material kevily | D15: 46149 | E15: 900
B16: Locação | C16: Descarga de mateial Jadisson | D16: 46146 | E16: 800
B17: Locação | C17: Mestre da obra | D17: 46171 | E17: 804
B18: Locação | C18: Mestre da obra | D18: 46164 | E18: 642
B19: Locação | C19: Mestre da obra | D19: 46149 | E19: 410

Sheet Fat Direto
B2: Tipo | C2: Descrição | D2: Mês | E2: Valor | G2: Rótulos de Linha | H2: Soma de Valor
G3: (vazio)
G4: Total Geral
L7: NF
L8: 357
