Workbook

Sheet 00_LEIA-ME
B1: Orçamento Baia REV10 — base de custo TÉCNICA (formato do app)
B3: COMO USAR: preencha as células AMARELO-FORTE de PRODUTIVIDADE em 03_SERVICOS (coluna F).
B4: Enquanto vazias, o coeficiente e o custo da M.O. ficam em branco. Ao digitar, tudo recalcula.
B5: Ajuste também os R$/h em 02_PRECOS e a equipe (linhas) em 04_COMPOSICAO conforme a realidade.
B7: TRANSFORMAÇÃO: coef M.O. (h/un, por pessoa) = Horas/dia ÷ Produtividade (un/dia).
B8: custo/un = coef × preço · custo serviço = soma insumos · total = custo/un × qtd · obra = soma.
B10: PREMISSA: Proposta Comercial = camada do cliente (inflada). Custo real = abas técnicas auditadas.
B11: 3 itens já transformados (1.1, 1.5, 1.6) como exemplo; os demais aguardam sua produtividade.
B13: QUANTIDADES: coluna E da Proposta. Em 1.1/1.10/1.12 a qtd física está dentro da fórmula de custo.
B15: BDI: material vende por custo/(1-lucro); M.O. por custo/(1-imposto-lucro). % por item (col. K-AE).
B17: LEGENDA: [transformado]=ok · [preencher prod.]=falta produtividade · [verba]/[pendente] · [erro planilha]=ver 07.

Sheet 01_INSUMOS
A1: id | B1: Nome do insumo | C1: Tipo | D1: Un. | E1: Observação
A2: I01 | B2: Aço LSF galvanizado Z275 | C2: Material | D2: kg
A3: I02 | B3: Fixadores/parafusos LSF | C3: Material | D3: vb
A4: I03 | B4: Encarregado | C4: Mão de Obra | D4: h | E4: mão de obra por hora
A5: I04 | B5: Montador líder | C5: Mão de Obra | D5: h | E5: mão de obra por hora
A6: I05 | B6: Montador | C6: Mão de Obra | D6: h | E6: mão de obra por hora
A7: I06 | B7: Ajudante | C7: Mão de Obra | D7: h | E7: mão de obra por hora
A8: I07 | B8: Pintor | C8: Mão de Obra | D8: h | E8: mão de obra por hora
A9: I08 | B9: Stain (verba global) | C9: Material | D9: vb
A10: I09 | B10: Ferragens/trilho portão | C10: Material | D10: un
A11: I10 | B11: Pedreiro | C11: Mão de Obra | D11: h | E11: mão de obra por hora
A12: I11 | B12: Concreto usinado | C12: Material | D12: m³
A13: I12 | B13: Extra/ferramenta concreto | C13: Material | D13: vb
A14: I13 | B14: Taxa fixa concretagem | C14: Mão de Obra | D14: vb
A15: I14 | B15: Ponto de luz (material) | C15: Material | D15: un
A16: I15 | B16: Adicional elétrico | C16: Material | D16: vb
A17: I16 | B17: Quadro/diversos | C17: Material | D17: vb
A18: I17 | B18: M.O. instalação elétrica | C18: Mão de Obra | D18: vb
A19: I18 | B19: Fixadores cercado | C19: Material | D19: un
A20: I19 | B20: Material ponto hidráulico | C20: Material | D20: un
A21: I20 | B21: Encanador | C21: Mão de Obra | D21: h | E21: mão de obra por hora
A22: I21 | B22: Material pacote complementar | C22: Material | D22: vb
A23: I22 | B23: M.O. pacote complementar | C23: Mão de Obra | D23: vb

Sheet 02_PRECOS_INSUMOS
A1: Insumo (M.O.) | B1: R$/h | C1: Un. | D1: Base / observação (editar)
A2: Encarregado | B2: 36.36 | C2: h | D2: ≈6.400/mês÷176h [validar]
A3: Montador líder | B3: 31.82 | C3: h | D3: diária 250÷8h [validar]
A4: Montador | B4: 26.14 | C4: h | D4: diária ~209÷8h [validar]
A5: Ajudante | B5: 20.46 | C5: h | D5: diária ~164÷8h [validar]
A6: Pedreiro | B6: 25 | C6: h | D6: diária 200÷8h [validar]
A7: Meio oficial | B7: 18.75 | C7: h | D7: diária 150÷8h [validar]
A8: Pintor | B8: 20.46 | C8: h | D8: [validar]
A9: Instalador | B9: 20.46 | C9: h | D9: [validar]
A10: Eletricista | B10: 25 | C10: h | D10: [validar]
A11: Encanador | B11: 25 | C11: h | D11: [validar]

Sheet 03_SERVICOS
A1: Cód. | B1: Serviço | C1: Un. | D1: Quantidade | E1: Horas/dia | F1: PRODUTIV. (un/dia) | G1: Origem da quantidade | H1: Lucro mat | I1: Imp MO | J1: Lucro MO
A2: 1.1 | B2: Estrutura em Aço LSF Z275 | C2: kg | D2: 21900 | E2: 8 | F2: 363.6 | G2: dentro de F10 =((21900×13,5)×1,07)+15000; E10=1 vb | H2: 0.25 | I2: 0.13 | J2: 0.28
A3: 1.2 | B3: Pintura do aço estrutural | C3: m² | D3: 1173 | E3: 8 | G3: E11 (digitado) | H3: 0.2 | I3: 0.13 | J3: 0.28
A4: 1.3 | B4: Pintura/Stain portão Pinus | C4: m² | D4: 161 | E4: 8 | G4: E12 (digitado) | H4: 0.2 | I4: 0.13 | J4: 0.28
A5: 1.4 | B5: Portão em Pinus | C5: un | D5: 48 | E5: 8 | G5: E13 =24×2 | H5: 0.2 | I5: 0.13 | J5: 0.28
A6: 1.5 | B6: Fechamento interno placa cimentícia | C6: m² | D6: 900 | E6: 8 | F6: 30 | G6: E14 (digitado) | H6: 0.2 | I6: 0.13 | J6: 0.28
A7: 1.6 | B7: Fechamento externo régua pinus | C7: m² | D7: 660 | E7: 8 | F7: 15 | G7: E15 (digitado) | H7: 0.2 | I7: 0.13 | J7: 0.28
A8: 1.7 | B8: Pintura fechamentos internos | C8: m² | D8: 900 | E8: 8 | G8: E16 =E14 (un. corrigida vb→m²) | H8: 0.2 | I8: 0.13 | J8: 0.28
A9: 1.8 | B9: Pintura Stain paredes externas | C9: m² | D9: 660 | E9: 8 | G9: E17 (digitado) | H9: 0.2 | I9: 0.13 | J9: 0.28
A10: 1.9 | B10: Verticalização pilares roliços | C10: un | D10: 32 | E10: 8 | G10: E18 =44-12 | H10: 0.2 | I10: 0.13 | J10: 0.28
A11: 1.10 | B11: Corredores em concreto | C11: m² | D11: 500.4 | E11: 8 | G11: dentro de F19/G19 (500,4); E19=1 vb | H11: 0.2 | I11: 0.13 | J11: 0.28
A12: 1.11 | B12: Revestimento pedra moledo | C12: m² | D12: 40 | E12: 8 | G12: E20 =80/2 | H12: 0.2 | I12: 0.13 | J12: 0.28
A13: 1.12 | B13: Instalação pontos de luz | C13: vb | D13: 1 | E13: 8 | F13: n/a (verba) | G13: E21=1; 12 pontos em F21 | H13: 0.2 | I13: 0.13 | J13: 0.28
A14: 1.13 | B14: Instalação telha shingle | C14: m² | D14: 1173 | E14: 8 | G14: E22 (digitado) | H14: 0.2 | I14: 0.13 | J14: 0.28
A15: 1.14 | B15: Cercado das baias | C15: un | D15: 24 | E15: 8 | G15: E23 (digitado) | H15: 0.2 | I15: 0.13 | J15: 0.28
A16: 1.15 | B16: Pintura Stain do cercado | C16: un | D16: 24 | E16: 8 | G16: E24 (digitado) | H16: 0.2 | I16: 0.13 | J16: 0.28
A17: 1.16 | B17: Ponto hidráulico por baia | C17: un | D17: 24 | E17: 8 | G17: E25 (digitado) | H17: 0.2 | I17: 0.13 | J17: 0.28
A18: 1.17 | B18: Pacote complementar REV10 | C18: vb | D18: 1 | E18: 8 | F18: n/a (verba) | G18: E26 (digitado) | H18: 0.22 | I18: 0.13 | J18: 0.15

Sheet 04_COMPOSICAO_SERVICOS
A1: Cód. | B1: Insumo | C1: Tipo | D1: Un. | E1: Coeficiente | F1: Preço unit. | G1: Custo/un serviço | H1: Como transformei / origem
A2: 1.1 | B2: Aço LSF galvanizado Z275 | C2: Material | D2: kg | E2: 1.07 | F2: 13.5 | G2: =IF(E2="","",E2*F2) | H2: coef 1,07 = 1kg + 7% perda (F10)
A3: 1.1 | B3: Fixadores/parafusos LSF | C3: Material | D3: vb | E3: 1 | F3: =15000/'03_SERVICOS'!D2 | G3: =IF(E3="","",E3*F3) | H3: verba R$15.000 (F10) rateada
A4: 1.1 | B4: Encarregado | C4: Mão de Obra | D4: h | E4: =IF(OR('03_SERVICOS'!F2="",'03_SERVICOS'!F2=0),"",'03_SERVICOS'!E2/'03_SERVICOS'!F2) | F4: 36.36 | G4: =IF(E4="","",E4*F4) | H4: [transformado] 8h ÷ produtividade
A5: 1.1 | B5: Montador líder | C5: Mão de Obra | D5: h | E5: =IF(OR('03_SERVICOS'!F2="",'03_SERVICOS'!F2=0),"",'03_SERVICOS'!E2/'03_SERVICOS'!F2) | F5: 31.82 | G5: =IF(E5="","",E5*F5) | H5: [transformado] 8h ÷ produtividade
A6: 1.1 | B6: Montador | C6: Mão de Obra | D6: h | E6: =IF(OR('03_SERVICOS'!F2="",'03_SERVICOS'!F2=0),"",'03_SERVICOS'!E2/'03_SERVICOS'!F2) | F6: 26.14 | G6: =IF(E6="","",E6*F6) | H6: [transformado] 8h ÷ produtividade
A7: 1.1 | B7: Montador | C7: Mão de Obra | D7: h | E7: =IF(OR('03_SERVICOS'!F2="",'03_SERVICOS'!F2=0),"",'03_SERVICOS'!E2/'03_SERVICOS'!F2) | F7: 26.14 | G7: =IF(E7="","",E7*F7) | H7: [transformado] 8h ÷ produtividade
A8: 1.1 | B8: Ajudante | C8: Mão de Obra | D8: h | E8: =IF(OR('03_SERVICOS'!F2="",'03_SERVICOS'!F2=0),"",'03_SERVICOS'!E2/'03_SERVICOS'!F2) | F8: 20.46 | G8: =IF(E8="","",E8*F8) | H8: [transformado] 8h ÷ produtividade
A9: 1.1 | B9: Ajudante | C9: Mão de Obra | D9: h | E9: =IF(OR('03_SERVICOS'!F2="",'03_SERVICOS'!F2=0),"",'03_SERVICOS'!E2/'03_SERVICOS'!F2) | F9: 20.46 | G9: =IF(E9="","",E9*F9) | H9: [transformado] 8h ÷ produtividade
A10: 1.2 | B10: Pintor | C10: Mão de Obra | D10: h | E10: =IF(OR('03_SERVICOS'!F3="",'03_SERVICOS'!F3=0),"",'03_SERVICOS'!E3/'03_SERVICOS'!F3) | F10: 20.46 | G10: =IF(E10="","",E10*F10) | H10: [preencher prod.] equipe pintura — aba sugere taxa proposta 35/m²
A11: 1.2 | B11: Ajudante | C11: Mão de Obra | D11: h | E11: =IF(OR('03_SERVICOS'!F3="",'03_SERVICOS'!F3=0),"",'03_SERVICOS'!E3/'03_SERVICOS'!F3) | F11: 20.46 | G11: =IF(E11="","",E11*F11) | H11: [preencher prod.] equipe pintura — aba sugere taxa proposta 35/m²
A12: 1.3 | B12: Stain (verba global) | C12: Material | D12: vb | E12: 1 | F12: =800/'03_SERVICOS'!D4 | G12: =IF(E12="","",E12*F12) | H12: [erro planilha] H12=800 global (venda ×161)
A13: 1.3 | B13: Pintor | C13: Mão de Obra | D13: h | E13: =IF(OR('03_SERVICOS'!F4="",'03_SERVICOS'!F4=0),"",'03_SERVICOS'!E4/'03_SERVICOS'!F4) | F13: 20.46 | G13: =IF(E13="","",E13*F13) | H13: [preencher prod.] pintura/stain portão (proposta 35/m²)
A14: 1.4 | B14: Ferragens/trilho portão | C14: Material | D14: un | E14: 1 | F14: 125 | G14: =IF(E14="","",E14*F14) | H14: F13 por unidade
A15: 1.4 | B15: Montador | C15: Mão de Obra | D15: h | E15: =IF(OR('03_SERVICOS'!F5="",'03_SERVICOS'!F5=0),"",'03_SERVICOS'!E5/'03_SERVICOS'!F5) | F15: 26.14 | G15: =IF(E15="","",E15*F15) | H15: [preencher prod.] un/dia (aba Portas ~ R$116,78/un; proposta 350/un)
A16: 1.4 | B16: Ajudante | C16: Mão de Obra | D16: h | E16: =IF(OR('03_SERVICOS'!F5="",'03_SERVICOS'!F5=0),"",'03_SERVICOS'!E5/'03_SERVICOS'!F5) | F16: 20.46 | G16: =IF(E16="","",E16*F16) | H16: [preencher prod.] un/dia (aba Portas ~ R$116,78/un; proposta 350/un)
A17: 1.5 | B17: Montador líder | C17: Mão de Obra | D17: h | E17: =IF(OR('03_SERVICOS'!F6="",'03_SERVICOS'!F6=0),"",'03_SERVICOS'!E6/'03_SERVICOS'!F6) | F17: 31.82 | G17: =IF(E17="","",E17*F17) | H17: [transformado] 8h÷30 m²/dia
A18: 1.5 | B18: Montador | C18: Mão de Obra | D18: h | E18: =IF(OR('03_SERVICOS'!F6="",'03_SERVICOS'!F6=0),"",'03_SERVICOS'!E6/'03_SERVICOS'!F6) | F18: 26.14 | G18: =IF(E18="","",E18*F18) | H18: [transformado] 8h÷30 m²/dia
A19: 1.5 | B19: Ajudante | C19: Mão de Obra | D19: h | E19: =IF(OR('03_SERVICOS'!F6="",'03_SERVICOS'!F6=0),"",'03_SERVICOS'!E6/'03_SERVICOS'!F6) | F19: 20.46 | G19: =IF(E19="","",E19*F19) | H19: [transformado] 8h÷30 m²/dia
A20: 1.6 | B20: Montador líder | C20: Mão de Obra | D20: h | E20: =IF(OR('03_SERVICOS'!F7="",'03_SERVICOS'!F7=0),"",'03_SERVICOS'!E7/'03_SERVICOS'!F7) | F20: 31.82 | G20: =IF(E20="","",E20*F20) | H20: [transformado] 8h÷15 m²/dia
A21: 1.6 | B21: Montador | C21: Mão de Obra | D21: h | E21: =IF(OR('03_SERVICOS'!F7="",'03_SERVICOS'!F7=0),"",'03_SERVICOS'!E7/'03_SERVICOS'!F7) | F21: 26.14 | G21: =IF(E21="","",E21*F21) | H21: [transformado] 8h÷15 m²/dia
A22: 1.6 | B22: Ajudante | C22: Mão de Obra | D22: h | E22: =IF(OR('03_SERVICOS'!F7="",'03_SERVICOS'!F7=0),"",'03_SERVICOS'!E7/'03_SERVICOS'!F7) | F22: 20.46 | G22: =IF(E22="","",E22*F22) | H22: [transformado] 8h÷15 m²/dia
A23: 1.7 | B23: Pintor | C23: Mão de Obra | D23: h | E23: =IF(OR('03_SERVICOS'!F8="",'03_SERVICOS'!F8=0),"",'03_SERVICOS'!E8/'03_SERVICOS'!F8) | F23: 20.46 | G23: =IF(E23="","",E23*F23) | H23: [preencher prod.] pintura interna (proposta 45/m²)
A24: 1.8 | B24: Stain (verba global) | C24: Material | D24: vb | E24: 1 | F24: =800/'03_SERVICOS'!D9 | G24: =IF(E24="","",E24*F24) | H24: H17=800 global (consistente)
A25: 1.8 | B25: Pintor | C25: Mão de Obra | D25: h | E25: =IF(OR('03_SERVICOS'!F9="",'03_SERVICOS'!F9=0),"",'03_SERVICOS'!E9/'03_SERVICOS'!F9) | F25: 20.46 | G25: =IF(E25="","",E25*F25) | H25: [preencher prod.] stain externa (proposta 30/m²)
A26: 1.9 | B26: Pedreiro | C26: Mão de Obra | D26: h | E26: =IF(OR('03_SERVICOS'!F10="",'03_SERVICOS'!F10=0),"",'03_SERVICOS'!E10/'03_SERVICOS'!F10) | F26: 25 | G26: =IF(E26="","",E26*F26) | H26: [preencher prod.] pilares/dia (proposta 568,18/un; base 44 vs qtd 32)
A27: 1.9 | B27: Ajudante | C27: Mão de Obra | D27: h | E27: =IF(OR('03_SERVICOS'!F10="",'03_SERVICOS'!F10=0),"",'03_SERVICOS'!E10/'03_SERVICOS'!F10) | F27: 20.46 | G27: =IF(E27="","",E27*F27) | H27: [preencher prod.] pilares/dia (proposta 568,18/un; base 44 vs qtd 32)
A28: 1.10 | B28: Concreto usinado | C28: Material | D28: m³ | E28: 0.2 | F28: 550 | G28: =IF(E28="","",E28*F28) | H28: 100,08 m³ ÷ 500,4 = 0,20 m³/m²
A29: 1.10 | B29: Extra/ferramenta concreto | C29: Material | D29: vb | E29: 1 | F29: =1500/'03_SERVICOS'!D11 | G29: =IF(E29="","",E29*F29) | H29: verba R$1.500 rateada
A30: 1.10 | B30: Taxa fixa concretagem | C30: Mão de Obra | D30: vb | E30: 1 | F30: =2500/'03_SERVICOS'!D11 | G30: =IF(E30="","",E30*F30) | H30: verba R$2.500 rateada
A31: 1.10 | B31: Pedreiro | C31: Mão de Obra | D31: h | E31: =IF(OR('03_SERVICOS'!F11="",'03_SERVICOS'!F11=0),"",'03_SERVICOS'!E11/'03_SERVICOS'!F11) | F31: 25 | G31: =IF(E31="","",E31*F31) | H31: [preencher prod.] concretagem m²/dia (proposta 25/m²)
A32: 1.10 | B32: Ajudante | C32: Mão de Obra | D32: h | E32: =IF(OR('03_SERVICOS'!F11="",'03_SERVICOS'!F11=0),"",'03_SERVICOS'!E11/'03_SERVICOS'!F11) | F32: 20.46 | G32: =IF(E32="","",E32*F32) | H32: [preencher prod.] concretagem m²/dia (proposta 25/m²)
A33: 1.11 | B33: Pedreiro | C33: Mão de Obra | D33: h | E33: =IF(OR('03_SERVICOS'!F12="",'03_SERVICOS'!F12=0),"",'03_SERVICOS'!E12/'03_SERVICOS'!F12) | F33: 25 | G33: =IF(E33="","",E33*F33) | H33: [preencher prod.] revestimento m²/dia (proposta 230/m²; aba 62,98)
A34: 1.11 | B34: Ajudante | C34: Mão de Obra | D34: h | E34: =IF(OR('03_SERVICOS'!F12="",'03_SERVICOS'!F12=0),"",'03_SERVICOS'!E12/'03_SERVICOS'!F12) | F34: 20.46 | G34: =IF(E34="","",E34*F34) | H34: [preencher prod.] revestimento m²/dia (proposta 230/m²; aba 62,98)
A35: 1.12 | B35: Ponto de luz (material) | C35: Material | D35: un | E35: 12 | F35: 400 | G35: =IF(E35="","",E35*F35) | H35: 12×400 (F21)
A36: 1.12 | B36: Adicional elétrico | C36: Material | D36: vb | E36: 1 | F36: 1500 | G36: =IF(E36="","",E36*F36) | H36: +1500
A37: 1.12 | B37: Quadro/diversos | C37: Material | D37: vb | E37: 1 | F37: 610 | G37: =IF(E37="","",E37*F37) | H37: +610
A38: 1.12 | B38: M.O. instalação elétrica | C38: Mão de Obra | D38: vb | E38: 1 | F38: 6500 | G38: =IF(E38="","",E38*F38) | H38: [verba] G21=6500 global (vb — sem produtividade)
A39: 1.13 | B39: Montador líder | C39: Mão de Obra | D39: h | E39: =IF(OR('03_SERVICOS'!F14="",'03_SERVICOS'!F14=0),"",'03_SERVICOS'!E14/'03_SERVICOS'!F14) | F39: 31.82 | G39: =IF(E39="","",E39*F39) | H39: [preencher prod.] shingle m²/dia (proposta 85/m²)
A40: 1.13 | B40: Montador | C40: Mão de Obra | D40: h | E40: =IF(OR('03_SERVICOS'!F14="",'03_SERVICOS'!F14=0),"",'03_SERVICOS'!E14/'03_SERVICOS'!F14) | F40: 26.14 | G40: =IF(E40="","",E40*F40) | H40: [preencher prod.] shingle m²/dia (proposta 85/m²)
...

Sheet 05_ORCAMENTO_PROPOSTA
A1: Cód. | B1: Serviço | C1: Un. | D1: Qtd | E1: Custo/un Mat | F1: Custo/un MO | G1: Custo/un Tot | H1: Total Mat | I1: Total MO | J1: Custo Total | K1: Lucro mat | L1: Imp MO | M1: Lucro MO | N1: Venda Mat | O1: Venda MO | P1: Total Venda
A2: 1.1 | B2: ='03_SERVICOS'!B2 | C2: ='03_SERVICOS'!C2 | D2: ='03_SERVICOS'!D2 | E2: =SUMIFS('04_COMPOSICAO_SERVICOS'!$G$2:$G$51,'04_COMPOSICAO_SERVICOS'!$A$2:$A$51,A2,'04_COMPOSICAO_SERVICOS'!$C$2:$C$51,"Material") | F2: =SUMIFS('04_COMPOSICAO_SERVICOS'!$G$2:$G$51,'04_COMPOSICAO_SERVICOS'!$A$2:$A$51,A2,'04_COMPOSICAO_SERVICOS'!$C$2:$C$51,"Mão de Obra") | G2: =E2+F2 | H2: =E2*D2 | I2: =F2*D2 | J2: =H2+I2 | K2: ='03_SERVICOS'!H2 | L2: ='03_SERVICOS'!I2 | M2: ='03_SERVICOS'!J2 | N2: =IF(H2=0,0,H2/(1-K2)) | O2: =IF(I2=0,0,I2/(1-L2-M2)) | P2: =N2+O2
A3: 1.2 | B3: ='03_SERVICOS'!B3 | C3: ='03_SERVICOS'!C3 | D3: ='03_SERVICOS'!D3 | E3: =SUMIFS('04_COMPOSICAO_SERVICOS'!$G$2:$G$51,'04_COMPOSICAO_SERVICOS'!$A$2:$A$51,A3,'04_COMPOSICAO_SERVICOS'!$C$2:$C$51,"Material") | F3: =SUMIFS('04_COMPOSICAO_SERVICOS'!$G$2:$G$51,'04_COMPOSICAO_SERVICOS'!$A$2:$A$51,A3,'04_COMPOSICAO_SERVICOS'!$C$2:$C$51,"Mão de Obra") | G3: =E3+F3 | H3: =E3*D3 | I3: =F3*D3 | J3: =H3+I3 | K3: ='03_SERVICOS'!H3 | L3: ='03_SERVICOS'!I3 | M3: ='03_SERVICOS'!J3 | N3: =IF(H3=0,0,H3/(1-K3)) | O3: =IF(I3=0,0,I3/(1-L3-M3)) | P3: =N3+O3
A4: 1.3 | B4: ='03_SERVICOS'!B4 | C4: ='03_SERVICOS'!C4 | D4: ='03_SERVICOS'!D4 | E4: =SUMIFS('04_COMPOSICAO_SERVICOS'!$G$2:$G$51,'04_COMPOSICAO_SERVICOS'!$A$2:$A$51,A4,'04_COMPOSICAO_SERVICOS'!$C$2:$C$51,"Material") | F4: =SUMIFS('04_COMPOSICAO_SERVICOS'!$G$2:$G$51,'04_COMPOSICAO_SERVICOS'!$A$2:$A$51,A4,'04_COMPOSICAO_SERVICOS'!$C$2:$C$51,"Mão de Obra") | G4: =E4+F4 | H4: =E4*D4 | I4: =F4*D4 | J4: =H4+I4 | K4: ='03_SERVICOS'!H4 | L4: ='03_SERVICOS'!I4 | M4: ='03_SERVICOS'!J4 | N4: =IF(H4=0,0,H4/(1-K4)) | O4: =IF(I4=0,0,I4/(1-L4-M4)) | P4: =N4+O4
A5: 1.4 | B5: ='03_SERVICOS'!B5 | C5: ='03_SERVICOS'!C5 | D5: ='03_SERVICOS'!D5 | E5: =SUMIFS('04_COMPOSICAO_SERVICOS'!$G$2:$G$51,'04_COMPOSICAO_SERVICOS'!$A$2:$A$51,A5,'04_COMPOSICAO_SERVICOS'!$C$2:$C$51,"Material") | F5: =SUMIFS('04_COMPOSICAO_SERVICOS'!$G$2:$G$51,'04_COMPOSICAO_SERVICOS'!$A$2:$A$51,A5,'04_COMPOSICAO_SERVICOS'!$C$2:$C$51,"Mão de Obra") | G5: =E5+F5 | H5: =E5*D5 | I5: =F5*D5 | J5: =H5+I5 | K5: ='03_SERVICOS'!H5 | L5: ='03_SERVICOS'!I5 | M5: ='03_SERVICOS'!J5 | N5: =IF(H5=0,0,H5/(1-K5)) | O5: =IF(I5=0,0,I5/(1-L5-M5)) | P5: =N5+O5
A6: 1.5 | B6: ='03_SERVICOS'!B6 | C6: ='03_SERVICOS'!C6 | D6: ='03_SERVICOS'!D6 | E6: =SUMIFS('04_COMPOSICAO_SERVICOS'!$G$2:$G$51,'04_COMPOSICAO_SERVICOS'!$A$2:$A$51,A6,'04_COMPOSICAO_SERVICOS'!$C$2:$C$51,"Material") | F6: =SUMIFS('04_COMPOSICAO_SERVICOS'!$G$2:$G$51,'04_COMPOSICAO_SERVICOS'!$A$2:$A$51,A6,'04_COMPOSICAO_SERVICOS'!$C$2:$C$51,"Mão de Obra") | G6: =E6+F6 | H6: =E6*D6 | I6: =F6*D6 | J6: =H6+I6 | K6: ='03_SERVICOS'!H6 | L6: ='03_SERVICOS'!I6 | M6: ='03_SERVICOS'!J6 | N6: =IF(H6=0,0,H6/(1-K6)) | O6: =IF(I6=0,0,I6/(1-L6-M6)) | P6: =N6+O6
A7: 1.6 | B7: ='03_SERVICOS'!B7 | C7: ='03_SERVICOS'!C7 | D7: ='03_SERVICOS'!D7 | E7: =SUMIFS('04_COMPOSICAO_SERVICOS'!$G$2:$G$51,'04_COMPOSICAO_SERVICOS'!$A$2:$A$51,A7,'04_COMPOSICAO_SERVICOS'!$C$2:$C$51,"Material") | F7: =SUMIFS('04_COMPOSICAO_SERVICOS'!$G$2:$G$51,'04_COMPOSICAO_SERVICOS'!$A$2:$A$51,A7,'04_COMPOSICAO_SERVICOS'!$C$2:$C$51,"Mão de Obra") | G7: =E7+F7 | H7: =E7*D7 | I7: =F7*D7 | J7: =H7+I7 | K7: ='03_SERVICOS'!H7 | L7: ='03_SERVICOS'!I7 | M7: ='03_SERVICOS'!J7 | N7: =IF(H7=0,0,H7/(1-K7)) | O7: =IF(I7=0,0,I7/(1-L7-M7)) | P7: =N7+O7
A8: 1.7 | B8: ='03_SERVICOS'!B8 | C8: ='03_SERVICOS'!C8 | D8: ='03_SERVICOS'!D8 | E8: =SUMIFS('04_COMPOSICAO_SERVICOS'!$G$2:$G$51,'04_COMPOSICAO_SERVICOS'!$A$2:$A$51,A8,'04_COMPOSICAO_SERVICOS'!$C$2:$C$51,"Material") | F8: =SUMIFS('04_COMPOSICAO_SERVICOS'!$G$2:$G$51,'04_COMPOSICAO_SERVICOS'!$A$2:$A$51,A8,'04_COMPOSICAO_SERVICOS'!$C$2:$C$51,"Mão de Obra") | G8: =E8+F8 | H8: =E8*D8 | I8: =F8*D8 | J8: =H8+I8 | K8: ='03_SERVICOS'!H8 | L8: ='03_SERVICOS'!I8 | M8: ='03_SERVICOS'!J8 | N8: =IF(H8=0,0,H8/(1-K8)) | O8: =IF(I8=0,0,I8/(1-L8-M8)) | P8: =N8+O8
A9: 1.8 | B9: ='03_SERVICOS'!B9 | C9: ='03_SERVICOS'!C9 | D9: ='03_SERVICOS'!D9 | E9: =SUMIFS('04_COMPOSICAO_SERVICOS'!$G$2:$G$51,'04_COMPOSICAO_SERVICOS'!$A$2:$A$51,A9,'04_COMPOSICAO_SERVICOS'!$C$2:$C$51,"Material") | F9: =SUMIFS('04_COMPOSICAO_SERVICOS'!$G$2:$G$51,'04_COMPOSICAO_SERVICOS'!$A$2:$A$51,A9,'04_COMPOSICAO_SERVICOS'!$C$2:$C$51,"Mão de Obra") | G9: =E9+F9 | H9: =E9*D9 | I9: =F9*D9 | J9: =H9+I9 | K9: ='03_SERVICOS'!H9 | L9: ='03_SERVICOS'!I9 | M9: ='03_SERVICOS'!J9 | N9: =IF(H9=0,0,H9/(1-K9)) | O9: =IF(I9=0,0,I9/(1-L9-M9)) | P9: =N9+O9
A10: 1.9 | B10: ='03_SERVICOS'!B10 | C10: ='03_SERVICOS'!C10 | D10: ='03_SERVICOS'!D10 | E10: =SUMIFS('04_COMPOSICAO_SERVICOS'!$G$2:$G$51,'04_COMPOSICAO_SERVICOS'!$A$2:$A$51,A10,'04_COMPOSICAO_SERVICOS'!$C$2:$C$51,"Material") | F10: =SUMIFS('04_COMPOSICAO_SERVICOS'!$G$2:$G$51,'04_COMPOSICAO_SERVICOS'!$A$2:$A$51,A10,'04_COMPOSICAO_SERVICOS'!$C$2:$C$51,"Mão de Obra") | G10: =E10+F10 | H10: =E10*D10 | I10: =F10*D10 | J10: =H10+I10 | K10: ='03_SERVICOS'!H10 | L10: ='03_SERVICOS'!I10 | M10: ='03_SERVICOS'!J10 | N10: =IF(H10=0,0,H10/(1-K10)) | O10: =IF(I10=0,0,I10/(1-L10-M10)) | P10: =N10+O10
A11: 1.10 | B11: ='03_SERVICOS'!B11 | C11: ='03_SERVICOS'!C11 | D11: ='03_SERVICOS'!D11 | E11: =SUMIFS('04_COMPOSICAO_SERVICOS'!$G$2:$G$51,'04_COMPOSICAO_SERVICOS'!$A$2:$A$51,A11,'04_COMPOSICAO_SERVICOS'!$C$2:$C$51,"Material") | F11: =SUMIFS('04_COMPOSICAO_SERVICOS'!$G$2:$G$51,'04_COMPOSICAO_SERVICOS'!$A$2:$A$51,A11,'04_COMPOSICAO_SERVICOS'!$C$2:$C$51,"Mão de Obra") | G11: =E11+F11 | H11: =E11*D11 | I11: =F11*D11 | J11: =H11+I11 | K11: ='03_SERVICOS'!H11 | L11: ='03_SERVICOS'!I11 | M11: ='03_SERVICOS'!J11 | N11: =IF(H11=0,0,H11/(1-K11)) | O11: =IF(I11=0,0,I11/(1-L11-M11)) | P11: =N11+O11
A12: 1.11 | B12: ='03_SERVICOS'!B12 | C12: ='03_SERVICOS'!C12 | D12: ='03_SERVICOS'!D12 | E12: =SUMIFS('04_COMPOSICAO_SERVICOS'!$G$2:$G$51,'04_COMPOSICAO_SERVICOS'!$A$2:$A$51,A12,'04_COMPOSICAO_SERVICOS'!$C$2:$C$51,"Material") | F12: =SUMIFS('04_COMPOSICAO_SERVICOS'!$G$2:$G$51,'04_COMPOSICAO_SERVICOS'!$A$2:$A$51,A12,'04_COMPOSICAO_SERVICOS'!$C$2:$C$51,"Mão de Obra") | G12: =E12+F12 | H12: =E12*D12 | I12: =F12*D12 | J12: =H12+I12 | K12: ='03_SERVICOS'!H12 | L12: ='03_SERVICOS'!I12 | M12: ='03_SERVICOS'!J12 | N12: =IF(H12=0,0,H12/(1-K12)) | O12: =IF(I12=0,0,I12/(1-L12-M12)) | P12: =N12+O12
A13: 1.12 | B13: ='03_SERVICOS'!B13 | C13: ='03_SERVICOS'!C13 | D13: ='03_SERVICOS'!D13 | E13: =SUMIFS('04_COMPOSICAO_SERVICOS'!$G$2:$G$51,'04_COMPOSICAO_SERVICOS'!$A$2:$A$51,A13,'04_COMPOSICAO_SERVICOS'!$C$2:$C$51,"Material") | F13: =SUMIFS('04_COMPOSICAO_SERVICOS'!$G$2:$G$51,'04_COMPOSICAO_SERVICOS'!$A$2:$A$51,A13,'04_COMPOSICAO_SERVICOS'!$C$2:$C$51,"Mão de Obra") | G13: =E13+F13 | H13: =E13*D13 | I13: =F13*D13 | J13: =H13+I13 | K13: ='03_SERVICOS'!H13 | L13: ='03_SERVICOS'!I13 | M13: ='03_SERVICOS'!J13 | N13: =IF(H13=0,0,H13/(1-K13)) | O13: =IF(I13=0,0,I13/(1-L13-M13)) | P13: =N13+O13
... A18: 1.17 | B18: ='03_SERVICOS'!B18 | C18: ='03_SERVICOS'!C18 | D18: ='03_SERVICOS'!D18 | E18: =SUMIFS('04_COMPOSICAO_SERVICOS'!$G$2:$G$51,'04_COMPOSICAO_SERVICOS'!$A$2:$A$51,A18,'04_COMPOSICAO_SERVICOS'!$C$2:$C$51,"Material") | F18: =SUMIFS('04_COMPOSICAO_SERVICOS'!$G$2:$G$51,'04_COMPOSICAO_SERVICOS'!$A$2:$A$51,A18,'04_COMPOSICAO_SERVICOS'!$C$2:$C$51,"Mão de Obra") | G18: =E18+F18 | H18: =E18*D18 | I18: =F18*D18 | J18: =H18+I18 | K18: ='03_SERVICOS'!H18 | L18: ='03_SERVICOS'!I18 | M18: ='03_SERVICOS'!J18 | N18: =IF(H18=0,0,H18/(1-K18)) | O18: =IF(I18=0,0,I18/(1-L18-M18)) | P18: =N18+O18
B19: TOTAL DA OBRA | H19: =SUM(H2:H18) | I19: =SUM(I2:I18) | J19: =SUM(J2:J18) | N19: =SUM(N2:N18) | O19: =SUM(O2:O18) | P19: =SUM(P2:P18)

Sheet 06_VALIDACAO
A1: Cód. | B1: Mat técnico | C1: Mat proposta | D1: Dif mat | E1: MO técnica | F1: MO proposta | G1: Dif MO | H1: Status
A2: 1.1 | B2: ='05_ORCAMENTO_PROPOSTA'!H2 | C2: 331345.5 | D2: =B2-C2 | E2: ='05_ORCAMENTO_PROPOSTA'!I2 | F2: 153300 | G2: =E2-F2 | H2: =IF(E2=0,"M.O. a preencher",IF(AND(ABS(D2)<1,ABS(G2)<1),"OK","Divergente (ver 07)"))
A3: 1.2 | B3: ='05_ORCAMENTO_PROPOSTA'!H3 | C3: 0 | D3: =B3-C3 | E3: ='05_ORCAMENTO_PROPOSTA'!I3 | F3: 41055 | G3: =E3-F3 | H3: =IF(E3=0,"M.O. a preencher",IF(AND(ABS(D3)<1,ABS(G3)<1),"OK","Divergente (ver 07)"))
A4: 1.3 | B4: ='05_ORCAMENTO_PROPOSTA'!H4 | C4: 800 | D4: =B4-C4 | E4: ='05_ORCAMENTO_PROPOSTA'!I4 | F4: 5635 | G4: =E4-F4 | H4: =IF(E4=0,"M.O. a preencher",IF(AND(ABS(D4)<1,ABS(G4)<1),"OK","Divergente (ver 07)"))
A5: 1.4 | B5: ='05_ORCAMENTO_PROPOSTA'!H5 | C5: 6000 | D5: =B5-C5 | E5: ='05_ORCAMENTO_PROPOSTA'!I5 | F5: 16800 | G5: =E5-F5 | H5: =IF(E5=0,"M.O. a preencher",IF(AND(ABS(D5)<1,ABS(G5)<1),"OK","Divergente (ver 07)"))
A6: 1.5 | B6: ='05_ORCAMENTO_PROPOSTA'!H6 | C6: 0 | D6: =B6-C6 | E6: ='05_ORCAMENTO_PROPOSTA'!I6 | F6: 40500 | G6: =E6-F6 | H6: =IF(E6=0,"M.O. a preencher",IF(AND(ABS(D6)<1,ABS(G6)<1),"OK","Divergente (ver 07)"))
A7: 1.6 | B7: ='05_ORCAMENTO_PROPOSTA'!H7 | C7: 0 | D7: =B7-C7 | E7: ='05_ORCAMENTO_PROPOSTA'!I7 | F7: 29700 | G7: =E7-F7 | H7: =IF(E7=0,"M.O. a preencher",IF(AND(ABS(D7)<1,ABS(G7)<1),"OK","Divergente (ver 07)"))
A8: 1.7 | B8: ='05_ORCAMENTO_PROPOSTA'!H8 | C8: 0 | D8: =B8-C8 | E8: ='05_ORCAMENTO_PROPOSTA'!I8 | F8: 40500 | G8: =E8-F8 | H8: =IF(E8=0,"M.O. a preencher",IF(AND(ABS(D8)<1,ABS(G8)<1),"OK","Divergente (ver 07)"))
A9: 1.8 | B9: ='05_ORCAMENTO_PROPOSTA'!H9 | C9: 800 | D9: =B9-C9 | E9: ='05_ORCAMENTO_PROPOSTA'!I9 | F9: 19800 | G9: =E9-F9 | H9: =IF(E9=0,"M.O. a preencher",IF(AND(ABS(D9)<1,ABS(G9)<1),"OK","Divergente (ver 07)"))
A10: 1.9 | B10: ='05_ORCAMENTO_PROPOSTA'!H10 | C10: 0 | D10: =B10-C10 | E10: ='05_ORCAMENTO_PROPOSTA'!I10 | F10: 18181.82 | G10: =E10-F10 | H10: =IF(E10=0,"M.O. a preencher",IF(AND(ABS(D10)<1,ABS(G10)<1),"OK","Divergente (ver 07)"))
A11: 1.10 | B11: ='05_ORCAMENTO_PROPOSTA'!H11 | C11: 56544 | D11: =B11-C11 | E11: ='05_ORCAMENTO_PROPOSTA'!I11 | F11: 15010 | G11: =E11-F11 | H11: =IF(E11=0,"M.O. a preencher",IF(AND(ABS(D11)<1,ABS(G11)<1),"OK","Divergente (ver 07)"))
A12: 1.11 | B12: ='05_ORCAMENTO_PROPOSTA'!H12 | C12: 0 | D12: =B12-C12 | E12: ='05_ORCAMENTO_PROPOSTA'!I12 | F12: 9200 | G12: =E12-F12 | H12: =IF(E12=0,"M.O. a preencher",IF(AND(ABS(D12)<1,ABS(G12)<1),"OK","Divergente (ver 07)"))
A13: 1.12 | B13: ='05_ORCAMENTO_PROPOSTA'!H13 | C13: 6910 | D13: =B13-C13 | E13: ='05_ORCAMENTO_PROPOSTA'!I13 | F13: 6500 | G13: =E13-F13 | H13: =IF(E13=0,"M.O. a preencher",IF(AND(ABS(D13)<1,ABS(G13)<1),"OK","Divergente (ver 07)"))
... A18: 1.17 | B18: ='05_ORCAMENTO_PROPOSTA'!H18 | C18: 52322 | D18: =B18-C18 | E18: ='05_ORCAMENTO_PROPOSTA'!I18 | F18: 40242 | G18: =E18-F18 | H18: =IF(E18=0,"M.O. a preencher",IF(AND(ABS(D18)<1,ABS(G18)<1),"OK","Divergente (ver 07)"))

Sheet 07_DE_PARA_ORIGINAL
A1: Cód. | B1: Cél Qtd | C1: Cél Mat | D1: Cél MO | E1: Fórmula original | F1: Decisão / observação
A2: 1.1 | B2: E10 | C2: F10 | D2: G10 | E2: =((21900×13,5)×1,07)+15000 | =7×21900 | F2: M.O. transformada p/ h (~R$3,55/kg vs R$7/kg = margem→BDI)
A3: 1.3 | B3: E12 | C3: F12 | D3: G12 | E3: H12=ROUND(F12,2)=800 | F3: Stain global no custo, venda ×161 — inconsistência; modelado global
A4: 1.7 | B4: =E14 | C4: F16 | D4: G16 | E4: D='vb', E=900 | F4: Unidade corrigida vb→m²
A5: 1.9 | B5: =44-12 | C5: F18 | D5: G18 | E5: =(50000/2)/44 | F5: Custo base 44 pilares, qtd 32 — validar
A6: 1.10 | B6: E19 | C6: F19 | D6: G19 | E6: =(500,4×0,2)×550+1500 | =(500,4×25)+2500 | F6: Serviço em m² (500,4); E=1 vb
A7: 1.12 | B7: E21 | C7: F21 | D7: G21 | E7: =(12×400)+1500+610 | F7: 12 pontos vs descrição (1/baia+1/pilar≈68) — validar
A8: 1.15 | B8: E24 | C8: F24 | D8: G24 | E8: H24=ROUND(F24,2)=800 | F8: Stain global, venda ×24 — modelado global
A9: 1.16 | B9: E25 | C9: F25 | D9: G25 | E9: H25=ROUND(F25,2)=867,10 | F9: Material 1× na planilha; modelado ×24. Dif +R$19.943
A10: 1.17 | B10: E26 | C10: F26 | D10: G26 | E10: =49322+3000 | =37742+2500 | F10: Pacote — decompor (Fundação/Instalações; Instalações zerada)
