Workbook

Sheet DIÁRIAS
A1: COLABORADOR | C1: CRISTIANO MATIAS DA SILVA | H1: COLABORADOR | J1: EDNILSON BERNARDO DA SILVA | O1: COLABORADOR | Q1: JOSE CARLOS MONTELES CARVALHO | V1: COLABORADOR | X1: LUCAS HENRIQUE ALBERNAZ | AC1: COLABORADOR | AE1: ROGER ARMANDO SEQUERA RIVAS | AJ1: COLABORADOR | AL1: VITOR HUGO BRAGA | AQ1: COLABORADOR | AS1: DAVI FERREIRA DA SILVA | AX1: COLABORADOR | AZ1: VINICIUS OLIVEIRA COSTA ROMANO | BE1: COLABORADOR | BG1: ABEL BARGE | BL1: COLABORADOR | BN1: PEDRO EDNEI BATISTA PEREIRA | BS1: COLABORADOR | BU1: MAICON WILLIAN | BZ1: COLABORADOR | CB1: FABRICIO FERREIRA DA SILVA | CG1: COLABORADOR | CI1: MURILO CAIQUE DE LIMA CECIM | CN1: COLABORADOR | CP1: PAULO CESAR BITENCOURT DE SOUSA | CS1: 180 | CU1: COLABORADOR | CW1: LEONARDO OLIVEIRA SANTOS | DB1: COLABORADOR | DD1: MATHEUS ANTONIO BARBOSA DOS SANTOS | DI1: COLABORADOR | DK1: RENAN ANDLER ARAÚJO SIMEÃO | DP1: COLABORADOR | DR1: MARCOS VINICIUS BARBOSA CARDOSO | DW1: COLABORADOR | DY1: JOSUÉ DIAS DE ANDRADE
A3: DATA | B3: DIA DA SEMANA | C3: CENTRO DE CUSTO | D3: $ DIÁRIA | E3: $ VT | F3: $ VA | H3: DATA | I3: DIA DA SEMANA | J3: CENTRO DE CUSTO | K3: $ DIÁRIA | L3: $ VT | M3: $ VA | O3: DATA | P3: DIA DA SEMANA | Q3: CENTRO DE CUSTO | R3: $ DIÁRIA | S3: $ VT | T3: $ VA | V3: DATA | W3: DIA DA SEMANA | X3: CENTRO DE CUSTO | Y3: $ DIÁRIA | Z3: $ VT | AA3: $ VA | AC3: DATA | AD3: DIA DA SEMANA | AE3: CENTRO DE CUSTO | AF3: $ DIÁRIA | AG3: $ VT | AH3: $ VA | AJ3: DATA | AK3: DIA DA SEMANA | AL3: CENTRO DE CUSTO | AM3: $ DIÁRIA | AN3: $ VT | AO3: $ VA | AQ3: DATA | AR3: DIA DA SEMANA | AS3: CENTRO DE CUSTO | AT3: $ DIÁRIA | AU3: $ VT | AV3: $ VA | AX3: DATA | AY3: DIA DA SEMANA | AZ3: CENTRO DE CUSTO | BA3: $ DIÁRIA | BB3: $ VT | BC3: $ VA | BE3: DATA | BF3: DIA DA SEMANA | BG3: CENTRO DE CUSTO | BH3: $ DIÁRIA | BI3: $ VT | BJ3: $ VA | BL3: DATA | BM3: DIA DA SEMANA | BN3: CENTRO DE CUSTO | BO3: $ DIÁRIA | BP3: $ VT | BQ3: $ VA | BS3: DATA | BT3: DIA DA SEMANA | BU3: CENTRO DE CUSTO | BV3: $ DIÁRIA | BW3: $ VT | BX3: $ VA | BZ3: DATA | CA3: DIA DA SEMANA | CB3: CENTRO DE CUSTO | CC3: $ DIÁRIA | CD3: $ VT | CE3: $ VA | CG3: DATA | CH3: DIA DA SEMANA | CI3: CENTRO DE CUSTO | CJ3: $ DIÁRIA | CK3: $ VT | CL3: $ VA | CN3: DATA | CO3: DIA DA SEMANA | CP3: CENTRO DE CUSTO | CQ3: $ DIÁRIA | CR3: $ VT | CS3: $ VA | CU3: DATA | CV3: DIA DA SEMANA | CW3: CENTRO DE CUSTO | CX3: $ DIÁRIA | CY3: $ VT | CZ3: $ VA | DB3: DATA | DC3: DIA DA SEMANA | DD3: CENTRO DE CUSTO | DE3: $ DIÁRIA | DF3: $ VT | DG3: $ VA | DI3: DATA | DJ3: DIA DA SEMANA | DK3: CENTRO DE CUSTO | DL3: $ DIÁRIA | DM3: $ VT | DN3: $ VA | DP3: DATA | DQ3: DIA DA SEMANA | DR3: CENTRO DE CUSTO | DS3: $ DIÁRIA | DT3: $ VT | DU3: $ VA | DW3: DATA | DX3: DIA DA SEMANA | DY3: CENTRO DE CUSTO | DZ3: $ DIÁRIA | EA3: $ VT | EB3: $ VA
A4: 46023 | B4: QUINTA-FEIRA | C4: FERIADO | H4: 46023 | I4: QUINTA-FEIRA | J4: FERIADO | O4: 46023 | P4: QUINTA-FEIRA | Q4: FERIADO | V4: 46023 | W4: QUINTA-FEIRA | X4: FERIADO | AC4: 46023 | AD4: QUINTA-FEIRA | AE4: FERIADO | AJ4: 46023 | AK4: QUINTA-FEIRA | AL4: FERIADO | AQ4: 46023 | AR4: QUINTA-FEIRA | AS4: FERIADO | AX4: 46023 | AY4: QUINTA-FEIRA | AZ4: FERIADO | BE4: 46023 | BF4: QUINTA-FEIRA | BG4: FERIADO | BL4: 46023 | BM4: QUINTA-FEIRA | BN4: FERIADO | BS4: 46023 | BT4: QUINTA-FEIRA | BU4: FERIADO | BZ4: 46023 | CA4: QUINTA-FEIRA | CG4: 46023 | CH4: QUINTA-FEIRA | CN4: 46023 | CO4: QUINTA-FEIRA | CU4: 46023 | CV4: QUINTA-FEIRA | DB4: 46023 | DC4: QUINTA-FEIRA | DI4: 46023 | DJ4: QUINTA-FEIRA | DP4: 46023 | DQ4: QUINTA-FEIRA | DW4: 46023 | DX4: QUINTA-FEIRA
A5: 46024 | B5: SEXTA-FEIRA | C5: GESPI - REFEITORIO | D5: 180 | E5: 15 | F5: 19 | H5: 46024 | I5: SEXTA-FEIRA | J5: GESPI - REFEITORIO | K5: 250 | L5: 20.5 | M5: 0 | O5: 46024 | P5: SEXTA-FEIRA | Q5: DESCANSO | V5: 46024 | W5: SEXTA-FEIRA | X5: DESCANSO | AC5: 46024 | AD5: SEXTA-FEIRA | AE5: DESCANSO | AJ5: 46024 | AK5: SEXTA-FEIRA | AL5: DESCANSO | AQ5: 46024 | AR5: SEXTA-FEIRA | AS5: GESPI - REFEITORIO | AT5: 100 | AU5: 12 | AV5: 0 | AX5: 46024 | AY5: SEXTA-FEIRA | AZ5: DESCANSO | BE5: 46024 | BF5: SEXTA-FEIRA | BL5: 46024 | BM5: SEXTA-FEIRA | BN5: GESPI - REFEITORIO | BO5: 100 | BP5: 12 | BQ5: 0 | BS5: 46024 | BT5: SEXTA-FEIRA | BU5: GESPI - REFEITORIO | BV5: 100 | BW5: 12 | BX5: 0 | BZ5: 46024 | CA5: SEXTA-FEIRA | CG5: 46024 | CH5: SEXTA-FEIRA | CN5: 46024 | CO5: SEXTA-FEIRA | CU5: 46024 | CV5: SEXTA-FEIRA | DB5: 46024 | DC5: SEXTA-FEIRA | DI5: 46024 | DJ5: SEXTA-FEIRA | DP5: 46024 | DQ5: SEXTA-FEIRA | DW5: 46024 | DX5: SEXTA-FEIRA
A6: 46025 | B6: SÁBADO | C6: GESPI - REFEITORIO | D6: 180 | E6: 15 | F6: 19 | H6: 46025 | I6: SÁBADO | J6: GESPI - REFEITORIO | K6: 250 | L6: 20.5 | M6: 0 | O6: 46025 | P6: SÁBADO | V6: 46025 | W6: SÁBADO | AC6: 46025 | AD6: SÁBADO | AJ6: 46025 | AK6: SÁBADO | AQ6: 46025 | AR6: SÁBADO | AX6: 46025 | AY6: SÁBADO | BE6: 46025 | BF6: SÁBADO | BL6: 46025 | BM6: SÁBADO | BN6: GESPI - REFEITORIO | BO6: 100 | BP6: 12 | BQ6: 0 | BS6: 46025 | BT6: SÁBADO | BZ6: 46025 | CA6: SÁBADO | CG6: 46025 | CH6: SÁBADO | CN6: 46025 | CO6: SÁBADO | CU6: 46025 | CV6: SÁBADO | DB6: 46025 | DC6: SÁBADO | DI6: 46025 | DJ6: SÁBADO | DP6: 46025 | DQ6: SÁBADO | DW6: 46025 | DX6: SÁBADO
A7: 46026 | B7: DOMINGO | H7: 46026 | I7: DOMINGO | O7: 46026 | P7: DOMINGO | V7: 46026 | W7: DOMINGO | AC7: 46026 | AD7: DOMINGO | AJ7: 46026 | AK7: DOMINGO | AQ7: 46026 | AR7: DOMINGO | AX7: 46026 | AY7: DOMINGO | BE7: 46026 | BF7: DOMINGO | BL7: 46026 | BM7: DOMINGO | BS7: 46026 | BT7: DOMINGO | BZ7: 46026 | CA7: DOMINGO | CG7: 46026 | CH7: DOMINGO | CN7: 46026 | CO7: DOMINGO | CU7: 46026 | CV7: DOMINGO | DB7: 46026 | DC7: DOMINGO | DI7: 46026 | DJ7: DOMINGO | DP7: 46026 | DQ7: DOMINGO | DW7: 46026 | DX7: DOMINGO
A8: 46027 | B8: SEGUNDA-FEIRA | C8: GESPI - REFEITORIO | D8: 180 | E8: 15 | F8: 19 | H8: 46027 | I8: SEGUNDA-FEIRA | J8: GESPI - REFEITORIO | K8: 250 | L8: 20.5 | M8: 0 | O8: 46027 | P8: SEGUNDA-FEIRA | Q8: FALTOU | V8: 46027 | W8: SEGUNDA-FEIRA | X8: GATTAI - ROBSON | Y8: 120 | Z8: 0 | AA8: 0 | AC8: 46027 | AD8: SEGUNDA-FEIRA | AE8: GATTAI - ROBSON | AF8: 180 | AG8: 0 | AH8: 0 | AJ8: 46027 | AK8: SEGUNDA-FEIRA | AL8: GATTAI - ROBSON | AM8: 250 | AN8: 0 | AO8: 0 | AQ8: 46027 | AR8: SEGUNDA-FEIRA | AS8: GESPI - REFEITORIO | AT8: 100 | AU8: 12 | AV8: 0 | AX8: 46027 | AY8: SEGUNDA-FEIRA | AZ8: GATTAI - ROBSON | BA8: 120 | BB8: 0 | BC8: 0 | BE8: 46027 | BF8: SEGUNDA-FEIRA | BG8: DESCANSO | BL8: 46027 | BM8: SEGUNDA-FEIRA | BN8: GESPI - REFEITORIO | BO8: 100 | BP8: 12 | BQ8: 0 | BS8: 46027 | BT8: SEGUNDA-FEIRA | BU8: GESPI - REFEITORIO | BV8: 100 | BW8: 12 | BX8: 0 | BZ8: 46027 | CA8: SEGUNDA-FEIRA | CG8: 46027 | CH8: SEGUNDA-FEIRA | CN8: 46027 | CO8: SEGUNDA-FEIRA | CU8: 46027 | CV8: SEGUNDA-FEIRA | DB8: 46027 | DC8: SEGUNDA-FEIRA | DI8: 46027 | DJ8: SEGUNDA-FEIRA | DP8: 46027 | DQ8: SEGUNDA-FEIRA | DW8: 46027 | DX8: SEGUNDA-FEIRA
A9: 46028 | B9: TERÇA-FEIRA | C9: GESPI - REFEITORIO | D9: 180 | E9: 15 | F9: 19 | H9: 46028 | I9: TERÇA-FEIRA | J9: GESPI - REFEITORIO | K9: 250 | L9: 20.5 | M9: 0 | O9: 46028 | P9: TERÇA-FEIRA | V9: 46028 | W9: TERÇA-FEIRA | X9: GATTAI - ROBSON | Y9: 120 | Z9: 0 | AA9: 0 | AC9: 46028 | AD9: TERÇA-FEIRA | AE9: GATTAI - ROBSON | AF9: 180 | AG9: 0 | AH9: 0 | AJ9: 46028 | AK9: TERÇA-FEIRA | AL9: GATTAI - ROBSON | AM9: 250 | AN9: 0 | AO9: 0 | AQ9: 46028 | AR9: TERÇA-FEIRA | AS9: GESPI - REFEITORIO | AT9: 100 | AU9: 12 | AV9: 0 | AX9: 46028 | AY9: TERÇA-FEIRA | AZ9: GATTAI - ROBSON | BA9: 120 | BB9: 0 | BC9: 0 | BE9: 46028 | BF9: TERÇA-FEIRA | BG9: DESCANSO | BL9: 46028 | BM9: TERÇA-FEIRA | BN9: GESPI - REFEITORIO | BO9: 100 | BP9: 12 | BQ9: 0 | BS9: 46028 | BT9: TERÇA-FEIRA | BU9: FALTOU | BZ9: 46028 | CA9: TERÇA-FEIRA | CG9: 46028 | CH9: TERÇA-FEIRA | CN9: 46028 | CO9: TERÇA-FEIRA | CU9: 46028 | CV9: TERÇA-FEIRA | DB9: 46028 | DC9: TERÇA-FEIRA | DI9: 46028 | DJ9: TERÇA-FEIRA | DP9: 46028 | DQ9: TERÇA-FEIRA | DW9: 46028 | DX9: TERÇA-FEIRA
A10: 46029 | B10: QUARTA-FEIRA | C10: GESPI - REFEITORIO | D10: 180 | E10: 15 | F10: 19 | H10: 46029 | I10: QUARTA-FEIRA | J10: GESPI - REFEITORIO | K10: 250 | L10: 20.5 | M10: 0 | O10: 46029 | P10: QUARTA-FEIRA | V10: 46029 | W10: QUARTA-FEIRA | X10: GATTAI - ROBSON | Y10: 120 | Z10: 0 | AA10: 0 | AC10: 46029 | AD10: QUARTA-FEIRA | AE10: GATTAI - ROBSON | AF10: 180 | AG10: 0 | AH10: 0 | AJ10: 46029 | AK10: QUARTA-FEIRA | AL10: GATTAI - ROBSON | AM10: 250 | AN10: 0 | AO10: 0 | AQ10: 46029 | AR10: QUARTA-FEIRA | AS10: GESPI - REFEITORIO | AT10: 100 | AU10: 12 | AV10: 0 | AX10: 46029 | AY10: QUARTA-FEIRA | AZ10: GATTAI - ROBSON | BA10: 120 | BB10: 0 | BC10: 0 | BE10: 46029 | BF10: QUARTA-FEIRA | BG10: DESCANSO | BL10: 46029 | BM10: QUARTA-FEIRA | BN10: GESPI - REFEITORIO | BO10: 100 | BP10: 12 | BQ10: 0 | BS10: 46029 | BT10: QUARTA-FEIRA | BU10: FALTOU | BZ10: 46029 | CA10: QUARTA-FEIRA | CG10: 46029 | CH10: QUARTA-FEIRA | CN10: 46029 | CO10: QUARTA-FEIRA | CU10: 46029 | CV10: QUARTA-FEIRA | DB10: 46029 | DC10: QUARTA-FEIRA | DI10: 46029 | DJ10: QUARTA-FEIRA | DP10: 46029 | DQ10: QUARTA-FEIRA | DW10: 46029 | DX10: QUARTA-FEIRA
A11: 46030 | B11: QUINTA-FEIRA | C11: DONA GILDA | D11: 180 | E11: 15 | F11: 19 | H11: 46030 | I11: QUINTA-FEIRA | J11: GESPI - SALA DE CONTROLE | K11: 250 | L11: 20.5 | M11: 0 | O11: 46030 | P11: QUINTA-FEIRA | V11: 46030 | W11: QUINTA-FEIRA | X11: GATTAI - ROBSON | Y11: 120 | Z11: 0 | AA11: 0 | AC11: 46030 | AD11: QUINTA-FEIRA | AE11: GATTAI - ROBSON | AF11: 180 | AG11: 0 | AH11: 0 | AJ11: 46030 | AK11: QUINTA-FEIRA | AL11: GATTAI - ROBSON | AM11: 250 | AN11: 0 | AO11: 0 | AQ11: 46030 | AR11: QUINTA-FEIRA | AS11: GESPI - SALA DE CONTROLE | AT11: 100 | AU11: 12 | AV11: 0 | AX11: 46030 | AY11: QUINTA-FEIRA | AZ11: GATTAI - ROBSON | BA11: 120 | BB11: 0 | BC11: 0 | BE11: 46030 | BF11: QUINTA-FEIRA | BG11: DESCANSO | BL11: 46030 | BM11: QUINTA-FEIRA | BN11: DONA GILDA | BO11: 100 | BP11: 12 | BQ11: 0 | BS11: 46030 | BT11: QUINTA-FEIRA | BU11: FALTOU | BZ11: 46030 | CA11: QUINTA-FEIRA | CG11: 46030 | CH11: QUINTA-FEIRA | CN11: 46030 | CO11: QUINTA-FEIRA | CU11: 46030 | CV11: QUINTA-FEIRA | DB11: 46030 | DC11: QUINTA-FEIRA | DI11: 46030 | DJ11: QUINTA-FEIRA | DP11: 46030 | DQ11: QUINTA-FEIRA | DW11: 46030 | DX11: QUINTA-FEIRA
A12: 46031 | B12: SEXTA-FEIRA | C12: GESPI - SALA DE CONTROLE | D12: 180 | E12: 15 | F12: 19 | H12: 46031 | I12: SEXTA-FEIRA | J12: ANGELA CID | K12: 250 | L12: 20.5 | M12: 0 | O12: 46031 | P12: SEXTA-FEIRA | V12: 46031 | W12: SEXTA-FEIRA | X12: GATTAI - ROBSON | Y12: 120 | Z12: 0 | AA12: 0 | AC12: 46031 | AD12: SEXTA-FEIRA | AE12: GATTAI - ROBSON | AF12: 180 | AG12: 0 | AH12: 0 | AJ12: 46031 | AK12: SEXTA-FEIRA | AL12: GATTAI - ROBSON | AM12: 250 | AN12: 0 | AO12: 0 | AQ12: 46031 | AR12: SEXTA-FEIRA | AS12: ANGELA CID | AT12: 100 | AU12: 12 | AV12: 0 | AX12: 46031 | AY12: SEXTA-FEIRA | AZ12: GATTAI - ROBSON | BA12: 120 | BB12: 0 | BC12: 0 | BE12: 46031 | BF12: SEXTA-FEIRA | BG12: DESCANSO | BL12: 46031 | BM12: SEXTA-FEIRA | BN12: GESPI - SALA DE CONTROLE | BO12: 100 | BP12: 12 | BQ12: 0 | BS12: 46031 | BT12: SEXTA-FEIRA | BU12: FALTOU | BZ12: 46031 | CA12: SEXTA-FEIRA | CG12: 46031 | CH12: SEXTA-FEIRA | CN12: 46031 | CO12: SEXTA-FEIRA | CU12: 46031 | CV12: SEXTA-FEIRA | DB12: 46031 | DC12: SEXTA-FEIRA | DI12: 46031 | DJ12: SEXTA-FEIRA | DP12: 46031 | DQ12: SEXTA-FEIRA | DW12: 46031 | DX12: SEXTA-FEIRA
A13: 46032 | B13: SÁBADO | H13: 46032 | I13: SÁBADO | O13: 46032 | P13: SÁBADO | V13: 46032 | W13: SÁBADO | AC13: 46032 | AD13: SÁBADO | AJ13: 46032 | AK13: SÁBADO | AQ13: 46032 | AR13: SÁBADO | AX13: 46032 | AY13: SÁBADO | BE13: 46032 | BF13: SÁBADO | BL13: 46032 | BM13: SÁBADO | BS13: 46032 | BT13: SÁBADO | BZ13: 46032 | CA13: SÁBADO | CG13: 46032 | CH13: SÁBADO | CN13: 46032 | CO13: SÁBADO | CU13: 46032 | CV13: SÁBADO | DB13: 46032 | DC13: SÁBADO | DI13: 46032 | DJ13: SÁBADO | DP13: 46032 | DQ13: SÁBADO | DW13: 46032 | DX13: SÁBADO
A14: 46033 | B14: DOMINGO | H14: 46033 | I14: DOMINGO | O14: 46033 | P14: DOMINGO | V14: 46033 | W14: DOMINGO | AC14: 46033 | AD14: DOMINGO | AJ14: 46033 | AK14: DOMINGO | AQ14: 46033 | AR14: DOMINGO | AX14: 46033 | AY14: DOMINGO | BE14: 46033 | BF14: DOMINGO | BL14: 46033 | BM14: DOMINGO | BS14: 46033 | BT14: DOMINGO | BZ14: 46033 | CA14: DOMINGO | CG14: 46033 | CH14: DOMINGO | CN14: 46033 | CO14: DOMINGO | CU14: 46033 | CV14: DOMINGO | DB14: 46033 | DC14: DOMINGO | DI14: 46033 | DJ14: DOMINGO | DP14: 46033 | DQ14: DOMINGO | DW14: 46033 | DX14: DOMINGO
A15: 46034 | B15: SEGUNDA-FEIRA | C15: FALTOU | H15: 46034 | I15: SEGUNDA-FEIRA | J15: GESPI - SALA DE CONTROLE | K15: 250 | L15: 20.5 | M15: 0 | O15: 46034 | P15: SEGUNDA-FEIRA | V15: 46034 | W15: SEGUNDA-FEIRA | X15: GESPI - SALA DE CONTROLE | Y15: 100 | Z15: 12.6 | AA15: 0 | AC15: 46034 | AD15: SEGUNDA-FEIRA | AE15: GESPI - SALA DE CONTROLE | AF15: 160 | AG15: 12 | AH15: 0 | AJ15: 46034 | AK15: SEGUNDA-FEIRA | AL15: GESPI - SALA DE CONTROLE | AM15: 250 | AN15: 12 | AO15: 0 | AQ15: 46034 | AR15: SEGUNDA-FEIRA | AS15: FALTOU | AX15: 46034 | AY15: SEGUNDA-FEIRA | AZ15: GESPI - SALA DE CONTROLE | BA15: 100 | BB15: 0 | BC15: 0 | BE15: 46034 | BF15: SEGUNDA-FEIRA | BL15: 46034 | BM15: SEGUNDA-FEIRA | BN15: GESPI - REFEITORIO | BO15: 100 | BP15: 12 | BQ15: 0 | BS15: 46034 | BT15: SEGUNDA-FEIRA | BU15: FALTOU | BZ15: 46034 | CA15: SEGUNDA-FEIRA | CG15: 46034 | CH15: SEGUNDA-FEIRA | CN15: 46034 | CO15: SEGUNDA-FEIRA | CU15: 46034 | CV15: SEGUNDA-FEIRA | DB15: 46034 | DC15: SEGUNDA-FEIRA | DI15: 46034 | DJ15: SEGUNDA-FEIRA | DP15: 46034 | DQ15: SEGUNDA-FEIRA | DW15: 46034 | DX15: SEGUNDA-FEIRA
A16: 46035 | B16: TERÇA-FEIRA | C16: GESPI - REFEITORIO | D16: 180 | E16: 15 | F16: 19 | H16: 46035 | I16: TERÇA-FEIRA | J16: GESPI - REFEITORIO | K16: 250 | L16: 20.5 | M16: 0 | O16: 46035 | P16: TERÇA-FEIRA | V16: 46035 | W16: TERÇA-FEIRA | X16: GESPI - REFEITORIO | Y16: 100 | Z16: 12.6 | AA16: 0 | AC16: 46035 | AD16: TERÇA-FEIRA | AE16: GESPI - REFEITORIO | AF16: 160 | AG16: 12 | AH16: 0 | AJ16: 46035 | AK16: TERÇA-FEIRA | AL16: DESCANSO | AM16: 250 | AQ16: 46035 | AR16: TERÇA-FEIRA | AS16: GESPI - REFEITORIO | AT16: 100 | AU16: 12 | AV16: 0 | AX16: 46035 | AY16: TERÇA-FEIRA | AZ16: GESPI - REFEITORIO | BA16: 100 | BB16: 0 | BC16: 0 | BE16: 46035 | BF16: TERÇA-FEIRA | BL16: 46035 | BM16: TERÇA-FEIRA | BN16: DESCANSO | BS16: 46035 | BT16: TERÇA-FEIRA | BZ16: 46035 | CA16: TERÇA-FEIRA | CG16: 46035 | CH16: TERÇA-FEIRA | CN16: 46035 | CO16: TERÇA-FEIRA | CU16: 46035 | CV16: TERÇA-FEIRA | DB16: 46035 | DC16: TERÇA-FEIRA | DI16: 46035 | DJ16: TERÇA-FEIRA | DP16: 46035 | DQ16: TERÇA-FEIRA | DW16: 46035 | DX16: TERÇA-FEIRA
A17: 46036 | B17: QUARTA-FEIRA | C17: GESPI - REFEITORIO | D17: 180 | E17: 15 | F17: 19 | H17: 46036 | I17: QUARTA-FEIRA | J17: GESPI - REFEITORIO | K17: 250 | L17: 20.5 | M17: 0 | O17: 46036 | P17: QUARTA-FEIRA | V17: 46036 | W17: QUARTA-FEIRA | X17: ANGELA CID | Y17: 100 | Z17: 12.6 | AA17: 0 | AC17: 46036 | AD17: QUARTA-FEIRA | AE17: GESPI - REFEITORIO | AF17: 160 | AG17: 12 | AH17: 0 | AJ17: 46036 | AK17: QUARTA-FEIRA | AL17: ANGELA CID | AM17: 250 | AN17: 12 | AO17: 0 | AQ17: 46036 | AR17: QUARTA-FEIRA | AS17: GESPI - REFEITORIO | AT17: 100 | AU17: 12 | AV17: 0 | AX17: 46036 | AY17: QUARTA-FEIRA | AZ17: ANGELA CID | BA17: 100 | BB17: 6 | BC17: 0 | BE17: 46036 | BF17: QUARTA-FEIRA | BG17: ANGELA CID | BL17: 46036 | BM17: QUARTA-FEIRA | BN17: GESPI - REFEITORIO | BO17: 100 | BP17: 12 | BQ17: 0 | BS17: 46036 | BT17: QUARTA-FEIRA | BZ17: 46036 | CA17: QUARTA-FEIRA | CB17: ANGELA CID | CC17: 100 | CD17: 12 | CE17: 0 | CG17: 46036 | CH17: QUARTA-FEIRA | CN17: 46036 | CO17: QUARTA-FEIRA | CU17: 46036 | CV17: QUARTA-FEIRA | DB17: 46036 | DC17: QUARTA-FEIRA | DI17: 46036 | DJ17: QUARTA-FEIRA | DP17: 46036 | DQ17: QUARTA-FEIRA | DW17: 46036 | DX17: QUARTA-FEIRA
A18: 46037 | B18: QUINTA-FEIRA | C18: GESPI - REFEITORIO | D18: 180 | E18: 15 | F18: 19 | H18: 46037 | I18: QUINTA-FEIRA | J18: LARISSA BERLATO | K18: 250 | L18: 20.5 | M18: 0 | O18: 46037 | P18: QUINTA-FEIRA | V18: 46037 | W18: QUINTA-FEIRA | X18: ANGELA CID | Y18: 100 | Z18: 12.6 | AA18: 0 | AC18: 46037 | AD18: QUINTA-FEIRA | AE18: GESPI - REFEITORIO | AF18: 160 | AG18: 12 | AH18: 0 | AJ18: 46037 | AK18: QUINTA-FEIRA | AL18: ANGELA CID | AM18: 250 | AN18: 12 | AO18: 0 | AQ18: 46037 | AR18: QUINTA-FEIRA | AS18: LARISSA BERLATO | AT18: 100 | AU18: 12 | AV18: 0 | AX18: 46037 | AY18: QUINTA-FEIRA | AZ18: ANGELA CID | BA18: 100 | BB18: 12 | BC18: 0 | BE18: 46037 | BF18: QUINTA-FEIRA | BG18: ANGELA CID | BL18: 46037 | BM18: QUINTA-FEIRA | BN18: GESPI - REFEITORIO | BO18: 100 | BP18: 12 | BQ18: 0 | BS18: 46037 | BT18: QUINTA-FEIRA | BZ18: 46037 | CA18: QUINTA-FEIRA | CB18: ANGELA CID | CC18: 100 | CD18: 12 | CE18: 0 | CG18: 46037 | CH18: QUINTA-FEIRA | CN18: 46037 | CO18: QUINTA-FEIRA | CU18: 46037 | CV18: QUINTA-FEIRA | DB18: 46037 | DC18: QUINTA-FEIRA | DI18: 46037 | DJ18: QUINTA-FEIRA | DP18: 46037 | DQ18: QUINTA-FEIRA | DW18: 46037 | DX18: QUINTA-FEIRA
A19: 46038 | B19: SEXTA-FEIRA | C19: GESPI - REFEITORIO | D19: 180 | E19: 15 | F19: 19 | H19: 46038 | I19: SEXTA-FEIRA | J19: LARISSA BERLATO | K19: 250 | L19: 20.5 | M19: 0 | O19: 46038 | P19: SEXTA-FEIRA | V19: 46038 | W19: SEXTA-FEIRA | X19: ANGELA CID | Y19: 100 | Z19: 12.6 | AA19: 0 | AC19: 46038 | AD19: SEXTA-FEIRA | AE19: GESPI - REFEITORIO | AF19: 160 | AG19: 12 | AH19: 0 | AJ19: 46038 | AK19: SEXTA-FEIRA | AL19: ANGELA CID | AM19: 250 | AN19: 12 | AO19: 0 | AQ19: 46038 | AR19: SEXTA-FEIRA | AS19: LARISSA BERLATO | AT19: 100 | AU19: 12 | AV19: 0 | AX19: 46038 | AY19: SEXTA-FEIRA | AZ19: ANGELA CID | BA19: 100 | BB19: 12 | BC19: 0 | BE19: 46038 | BF19: SEXTA-FEIRA | BL19: 46038 | BM19: SEXTA-FEIRA | BN19: GESPI - REFEITORIO | BO19: 100 | BP19: 12 | BQ19: 0 | BS19: 46038 | BT19: SEXTA-FEIRA | BZ19: 46038 | CA19: SEXTA-FEIRA | CB19: ANGELA CID | CC19: 100 | CD19: 12 | CE19: 0 | CG19: 46038 | CH19: SEXTA-FEIRA | CN19: 46038 | CO19: SEXTA-FEIRA | CU19: 46038 | CV19: SEXTA-FEIRA | DB19: 46038 | DC19: SEXTA-FEIRA | DI19: 46038 | DJ19: SEXTA-FEIRA | DP19: 46038 | DQ19: SEXTA-FEIRA | DW19: 46038 | DX19: SEXTA-FEIRA
A20: 46039 | B20: SÁBADO | H20: 46039 | I20: SÁBADO | O20: 46039 | P20: SÁBADO | V20: 46039 | W20: SÁBADO | AC20: 46039 | AD20: SÁBADO | AJ20: 46039 | AK20: SÁBADO | AQ20: 46039 | AR20: SÁBADO | AX20: 46039 | AY20: SÁBADO | BE20: 46039 | BF20: SÁBADO | BL20: 46039 | BM20: SÁBADO | BS20: 46039 | BT20: SÁBADO | BZ20: 46039 | CA20: SÁBADO | CG20: 46039 | CH20: SÁBADO | CN20: 46039 | CO20: SÁBADO | CU20: 46039 | CV20: SÁBADO | DB20: 46039 | DC20: SÁBADO | DI20: 46039 | DJ20: SÁBADO | DP20: 46039 | DQ20: SÁBADO | DW20: 46039 | DX20: SÁBADO
A21: 46040 | B21: DOMINGO | H21: 46040 | I21: DOMINGO | O21: 46040 | P21: DOMINGO | V21: 46040 | W21: DOMINGO | AC21: 46040 | AD21: DOMINGO | AJ21: 46040 | AK21: DOMINGO | AQ21: 46040 | AR21: DOMINGO | AX21: 46040 | AY21: DOMINGO | BE21: 46040 | BF21: DOMINGO | BL21: 46040 | BM21: DOMINGO | BS21: 46040 | BT21: DOMINGO | BZ21: 46040 | CA21: DOMINGO | CG21: 46040 | CH21: DOMINGO | CN21: 46040 | CO21: DOMINGO | CU21: 46040 | CV21: DOMINGO | DB21: 46040 | DC21: DOMINGO | DI21: 46040 | DJ21: DOMINGO | DP21: 46040 | DQ21: DOMINGO | DW21: 46040 | DX21: DOMINGO
A22: 46041 | B22: SEGUNDA-FEIRA | C22: GESPI - REFEITORIO | D22: 180 | E22: 15 | F22: 19 | H22: 46041 | I22: SEGUNDA-FEIRA | J22: GESPI - REFEITORIO | K22: 250 | L22: 20.5 | M22: 0 | O22: 46041 | P22: SEGUNDA-FEIRA | V22: 46041 | W22: SEGUNDA-FEIRA | X22: ANGELA CID | Y22: 100 | Z22: 12.6 | AA22: 0 | AC22: 46041 | AD22: SEGUNDA-FEIRA | AE22: GESPI - REFEITORIO | AF22: 160 | AG22: 12 | AH22: 0 | AJ22: 46041 | AK22: SEGUNDA-FEIRA | AL22: ANGELA CID | AM22: 250 | AN22: 12 | AO22: 0 | AQ22: 46041 | AR22: SEGUNDA-FEIRA | AS22: GESPI - REFEITORIO | AT22: 100 | AU22: 12 | AV22: 0 | AX22: 46041 | AY22: SEGUNDA-FEIRA | AZ22: ANGELA CID | BA22: 100 | BB22: 12 | BC22: 0 | BE22: 46041 | BF22: SEGUNDA-FEIRA | BL22: 46041 | BM22: SEGUNDA-FEIRA | BN22: GESPI - REFEITORIO | BO22: 100 | BP22: 12 | BQ22: 0 | BS22: 46041 | BT22: SEGUNDA-FEIRA | BZ22: 46041 | CA22: SEGUNDA-FEIRA | CB22: ANGELA CID | CC22: 100 | CD22: 12 | CE22: 0 | CG22: 46041 | CH22: SEGUNDA-FEIRA | CI22: GESPI - REFEITORIO | CJ22: 100 | CK22: 12 | CL22: 0 | CN22: 46041 | CO22: SEGUNDA-FEIRA | CU22: 46041 | CV22: SEGUNDA-FEIRA | DB22: 46041 | DC22: SEGUNDA-FEIRA | DI22: 46041 | DJ22: SEGUNDA-FEIRA | DP22: 46041 | DQ22: SEGUNDA-FEIRA | DW22: 46041 | DX22: SEGUNDA-FEIRA
A23: 46042 | B23: TERÇA-FEIRA | C23: GESPI - REFEITORIO | D23: 180 | E23: 15 | F23: 19 | H23: 46042 | I23: TERÇA-FEIRA | J23: GESPI - REFEITORIO | K23: 250 | L23: 20.5 | M23: 0 | O23: 46042 | P23: TERÇA-FEIRA | V23: 46042 | W23: TERÇA-FEIRA | X23: ANGELA CID | Y23: 100 | Z23: 12.6 | AA23: 0 | AC23: 46042 | AD23: TERÇA-FEIRA | AE23: GESPI - REFEITORIO | AF23: 160 | AG23: 12 | AH23: 0 | AJ23: 46042 | AK23: TERÇA-FEIRA | AL23: ANGELA CID | AM23: 250 | AN23: 12 | AO23: 0 | AQ23: 46042 | AR23: TERÇA-FEIRA | AS23: GESPI - REFEITORIO | AT23: 100 | AU23: 12 | AV23: 0 | AX23: 46042 | AY23: TERÇA-FEIRA | AZ23: ANGELA CID | BA23: 100 | BB23: 12 | BC23: 0 | BE23: 46042 | BF23: TERÇA-FEIRA | BL23: 46042 | BM23: TERÇA-FEIRA | BN23: GESPI - REFEITORIO | BO23: 100 | BP23: 12 | BQ23: 0 | BS23: 46042 | BT23: TERÇA-FEIRA | BZ23: 46042 | CA23: TERÇA-FEIRA | CB23: ANGELA CID | CC23: 100 | CD23: 12 | CE23: 0 | CG23: 46042 | CH23: TERÇA-FEIRA | CI23: GESPI - REFEITORIO | CJ23: 100 | CK23: 12 | CL23: 0 | CN23: 46042 | CO23: TERÇA-FEIRA | CU23: 46042 | CV23: TERÇA-FEIRA | DB23: 46042 | DC23: TERÇA-FEIRA | DI23: 46042 | DJ23: TERÇA-FEIRA | DP23: 46042 | DQ23: TERÇA-FEIRA | DW23: 46042 | DX23: TERÇA-FEIRA
A24: 46043 | B24: QUARTA-FEIRA | C24: GESPI - REFEITORIO | D24: 180 | E24: 15 | F24: 19 | H24: 46043 | I24: QUARTA-FEIRA | J24: GESPI - REFEITORIO | K24: 250 | L24: 20.5 | M24: 0 | O24: 46043 | P24: QUARTA-FEIRA | V24: 46043 | W24: QUARTA-FEIRA | X24: CLÍNICA DGM | Y24: 100 | Z24: 12.6 | AA24: 0 | AC24: 46043 | AD24: QUARTA-FEIRA | AE24: GESPI - REFEITORIO | AF24: 160 | AG24: 12 | AH24: 0 | AJ24: 46043 | AK24: QUARTA-FEIRA | AL24: CLÍNICA DGM | AM24: 250 | AN24: 12 | AO24: 0 | AQ24: 46043 | AR24: QUARTA-FEIRA | AS24: GESPI - REFEITORIO | AT24: 100 | AU24: 12 | AV24: 0 | AX24: 46043 | AY24: QUARTA-FEIRA | AZ24: CLÍNICA DGM | BA24: 100 | BB24: 12 | BC24: 0 | BE24: 46043 | BF24: QUARTA-FEIRA | BL24: 46043 | BM24: QUARTA-FEIRA | BN24: GESPI - REFEITORIO | BO24: 100 | BP24: 12 | BQ24: 0 | BS24: 46043 | BT24: QUARTA-FEIRA | BZ24: 46043 | CA24: QUARTA-FEIRA | CB24: FALTOU | CC24: 0 | CD24: 0 | CG24: 46043 | CH24: QUARTA-FEIRA | CI24: GESPI - REFEITORIO | CJ24: 100 | CK24: 12 | CL24: 0 | CN24: 46043 | CO24: QUARTA-FEIRA | CU24: 46043 | CV24: QUARTA-FEIRA | DB24: 46043 | DC24: QUARTA-FEIRA | DI24: 46043 | DJ24: QUARTA-FEIRA | DP24: 46043 | DQ24: QUARTA-FEIRA | DW24: 46043 | DX24: QUARTA-FEIRA
A25: 46044 | B25: QUINTA-FEIRA | C25: GESPI - REFEITORIO | D25: 180 | E25: 15 | F25: 19 | H25: 46044 | I25: QUINTA-FEIRA | J25: GESPI - REFEITORIO | K25: 250 | L25: 20.5 | M25: 0 | O25: 46044 | P25: QUINTA-FEIRA | V25: 46044 | W25: QUINTA-FEIRA | X25: CLÍNICA DGM | Y25: 100 | Z25: 12.6 | AA25: 0 | AC25: 46044 | AD25: QUINTA-FEIRA | AE25: GESPI - REFEITORIO | AF25: 160 | AG25: 12 | AH25: 0 | AJ25: 46044 | AK25: QUINTA-FEIRA | AL25: CLÍNICA DGM | AM25: 250 | AN25: 12 | AO25: 0 | AQ25: 46044 | AR25: QUINTA-FEIRA | AS25: GESPI - REFEITORIO | AT25: 100 | AU25: 12 | AV25: 0 | AX25: 46044 | AY25: QUINTA-FEIRA | AZ25: CLÍNICA DGM | BA25: 100 | BB25: 12 | BC25: 0 | BE25: 46044 | BF25: QUINTA-FEIRA | BL25: 46044 | BM25: QUINTA-FEIRA | BN25: GESPI - REFEITORIO | BO25: 100 | BP25: 12 | BQ25: 0 | BS25: 46044 | BT25: QUINTA-FEIRA | BZ25: 46044 | CA25: QUINTA-FEIRA | CB25: CLÍNICA DGM | CC25: 100 | CD25: 12 | CG25: 46044 | CH25: QUINTA-FEIRA | CI25: GESPI - REFEITORIO | CJ25: 100 | CK25: 12 | CL25: 0 | CN25: 46044 | CO25: QUINTA-FEIRA | CU25: 46044 | CV25: QUINTA-FEIRA | DB25: 46044 | DC25: QUINTA-FEIRA | DI25: 46044 | DJ25: QUINTA-FEIRA | DP25: 46044 | DQ25: QUINTA-FEIRA | DW25: 46044 | DX25: QUINTA-FEIRA
A26: 46045 | B26: SEXTA-FEIRA | C26: GESPI - REFEITORIO | D26: 180 | E26: 15 | F26: 19 | H26: 46045 | I26: SEXTA-FEIRA | J26: GESPI - REFEITORIO | K26: 250 | L26: 20.5 | M26: 0 | O26: 46045 | P26: SEXTA-FEIRA | V26: 46045 | W26: SEXTA-FEIRA | X26: CLÍNICA DGM | Y26: 100 | Z26: 12.6 | AA26: 0 | AC26: 46045 | AD26: SEXTA-FEIRA | AE26: GESPI - REFEITORIO | AF26: 160 | AG26: 12 | AH26: 0 | AJ26: 46045 | AK26: SEXTA-FEIRA | AL26: CLÍNICA DGM | AM26: 250 | AN26: 12 | AO26: 0 | AQ26: 46045 | AR26: SEXTA-FEIRA | AS26: GESPI - REFEITORIO | AT26: 100 | AU26: 12 | AV26: 0 | AX26: 46045 | AY26: SEXTA-FEIRA | AZ26: CLÍNICA DGM | BA26: 100 | BB26: 12 | BC26: 0 | BE26: 46045 | BF26: SEXTA-FEIRA | BL26: 46045 | BM26: SEXTA-FEIRA | BN26: GESPI - REFEITORIO | BO26: 100 | BP26: 12 | BQ26: 0 | BS26: 46045 | BT26: SEXTA-FEIRA | BZ26: 46045 | CA26: SEXTA-FEIRA | CB26: CLÍNICA DGM | CC26: 100 | CD26: 12 | CG26: 46045 | CH26: SEXTA-FEIRA | CI26: GESPI - REFEITORIO | CJ26: 100 | CK26: 12 | CL26: 0 | CN26: 46045 | CO26: SEXTA-FEIRA | CU26: 46045 | CV26: SEXTA-FEIRA | DB26: 46045 | DC26: SEXTA-FEIRA | DI26: 46045 | DJ26: SEXTA-FEIRA | DP26: 46045 | DQ26: SEXTA-FEIRA | DW26: 46045 | DX26: SEXTA-FEIRA
A27: 46046 | B27: SÁBADO | H27: 46046 | I27: SÁBADO | O27: 46046 | P27: SÁBADO | V27: 46046 | W27: SÁBADO | AC27: 46046 | AD27: SÁBADO | AJ27: 46046 | AK27: SÁBADO | AQ27: 46046 | AR27: SÁBADO | AX27: 46046 | AY27: SÁBADO | BE27: 46046 | BF27: SÁBADO | BL27: 46046 | BM27: SÁBADO | BS27: 46046 | BT27: SÁBADO | BZ27: 46046 | CA27: SÁBADO | CG27: 46046 | CH27: SÁBADO | CN27: 46046 | CO27: SÁBADO | CU27: 46046 | CV27: SÁBADO | DB27: 46046 | DC27: SÁBADO | DI27: 46046 | DJ27: SÁBADO | DP27: 46046 | DQ27: SÁBADO | DW27: 46046 | DX27: SÁBADO
A28: 46047 | B28: DOMINGO | H28: 46047 | I28: DOMINGO | O28: 46047 | P28: DOMINGO | V28: 46047 | W28: DOMINGO | AC28: 46047 | AD28: DOMINGO | AJ28: 46047 | AK28: DOMINGO | AQ28: 46047 | AR28: DOMINGO | AX28: 46047 | AY28: DOMINGO | BE28: 46047 | BF28: DOMINGO | BL28: 46047 | BM28: DOMINGO | BS28: 46047 | BT28: DOMINGO | BZ28: 46047 | CA28: DOMINGO | CG28: 46047 | CH28: DOMINGO | CN28: 46047 | CO28: DOMINGO | CU28: 46047 | CV28: DOMINGO | DB28: 46047 | DC28: DOMINGO | DI28: 46047 | DJ28: DOMINGO | DP28: 46047 | DQ28: DOMINGO | DW28: 46047 | DX28: DOMINGO
A29: 46048 | B29: SEGUNDA-FEIRA | C29: GESPI - REFEITORIO | D29: 180 | E29: 15 | F29: 19 | H29: 46048 | I29: SEGUNDA-FEIRA | J29: GESPI - REFEITORIO | K29: 250 | L29: 20.5 | M29: 0 | O29: 46048 | P29: SEGUNDA-FEIRA | V29: 46048 | W29: SEGUNDA-FEIRA | X29: CLÍNICA DGM | Y29: 100 | Z29: 12.6 | AA29: 0 | AC29: 46048 | AD29: SEGUNDA-FEIRA | AE29: GESPI - REFEITORIO | AF29: 160 | AG29: 12 | AH29: 0 | AJ29: 46048 | AK29: SEGUNDA-FEIRA | AL29: CLÍNICA DGM | AM29: 250 | AN29: 12 | AO29: 0 | AQ29: 46048 | AR29: SEGUNDA-FEIRA | AS29: FALTOU | AX29: 46048 | AY29: SEGUNDA-FEIRA | AZ29: FALTOU | BE29: 46048 | BF29: SEGUNDA-FEIRA | BG29: CLÍNICA DGM | BL29: 46048 | BM29: SEGUNDA-FEIRA | BN29: FALTOU | BS29: 46048 | BT29: SEGUNDA-FEIRA | BZ29: 46048 | CA29: SEGUNDA-FEIRA | CB29: CLÍNICA DGM | CC29: 100 | CD29: 12 | CG29: 46048 | CH29: SEGUNDA-FEIRA | CI29: GESPI - REFEITORIO | CJ29: 100 | CK29: 12 | CL29: 0 | CN29: 46048 | CO29: SEGUNDA-FEIRA | CU29: 46048 | CV29: SEGUNDA-FEIRA | DB29: 46048 | DC29: SEGUNDA-FEIRA | DI29: 46048 | DJ29: SEGUNDA-FEIRA | DP29: 46048 | DQ29: SEGUNDA-FEIRA | DW29: 46048 | DX29: SEGUNDA-FEIRA
A30: 46049 | B30: TERÇA-FEIRA | C30: GESPI - REFEITORIO | D30: 180 | E30: 15 | F30: 19 | H30: 46049 | I30: TERÇA-FEIRA | J30: GESPI - REFEITORIO | K30: 250 | L30: 20.5 | M30: 0 | O30: 46049 | P30: TERÇA-FEIRA | V30: 46049 | W30: TERÇA-FEIRA | X30: ANGELA CID | Y30: 100 | Z30: 12.6 | AA30: 0 | AC30: 46049 | AD30: TERÇA-FEIRA | AE30: GESPI - REFEITORIO | AF30: 160 | AG30: 12 | AH30: 0 | AJ30: 46049 | AK30: TERÇA-FEIRA | AL30: ANGELA CID | AM30: 250 | AN30: 12 | AO30: 0 | AQ30: 46049 | AR30: TERÇA-FEIRA | AS30: GESPI - REFEITORIO | AT30: 100 | AU30: 12 | AV30: 0 | AX30: 46049 | AY30: TERÇA-FEIRA | AZ30: FALTOU | BE30: 46049 | BF30: TERÇA-FEIRA | BG30: ANGELA CID | BL30: 46049 | BM30: TERÇA-FEIRA | BN30: FALTOU | BS30: 46049 | BT30: TERÇA-FEIRA | BZ30: 46049 | CA30: TERÇA-FEIRA | CB30: ANGELA CID | CC30: 100 | CD30: 12 | CG30: 46049 | CH30: TERÇA-FEIRA | CI30: GESPI - REFEITORIO | CJ30: 100 | CK30: 12 | CL30: 0 | CN30: 46049 | CO30: TERÇA-FEIRA | CU30: 46049 | CV30: TERÇA-FEIRA | DB30: 46049 | DC30: TERÇA-FEIRA | DI30: 46049 | DJ30: TERÇA-FEIRA | DP30: 46049 | DQ30: TERÇA-FEIRA | DW30: 46049 | DX30: TERÇA-FEIRA
A31: 46050 | B31: QUARTA-FEIRA | C31: GESPI - REFEITORIO | D31: 180 | E31: 15 | F31: 19 | H31: 46050 | I31: QUARTA-FEIRA | J31: GESPI - REFEITORIO | K31: 250 | L31: 20.5 | M31: 0 | O31: 46050 | P31: QUARTA-FEIRA | V31: 46050 | W31: QUARTA-FEIRA | X31: ANGELA CID | Y31: 100 | Z31: 12.6 | AA31: 0 | AC31: 46050 | AD31: QUARTA-FEIRA | AE31: GESPI - REFEITORIO | AF31: 160 | AG31: 12 | AH31: 0 | AJ31: 46050 | AK31: QUARTA-FEIRA | AL31: ANGELA CID | AM31: 250 | AN31: 12 | AO31: 0 | AQ31: 46050 | AR31: QUARTA-FEIRA | AS31: GESPI - REFEITORIO | AT31: 100 | AU31: 12 | AV31: 0 | AX31: 46050 | AY31: QUARTA-FEIRA | AZ31: ANGELA CID | BA31: 100 | BB31: 12 | BC31: 0 | BE31: 46050 | BF31: QUARTA-FEIRA | BG31: ANGELA CID | BL31: 46050 | BM31: QUARTA-FEIRA | BN31: GESPI - REFEITORIO | BO31: 100 | BP31: 12 | BQ31: 0 | BS31: 46050 | BT31: QUARTA-FEIRA | BZ31: 46050 | CA31: QUARTA-FEIRA | CB31: ANGELA CID | CC31: 100 | CD31: 12 | CG31: 46050 | CH31: QUARTA-FEIRA | CI31: GESPI - REFEITORIO | CJ31: 100 | CK31: 12 | CL31: 0 | CN31: 46050 | CO31: QUARTA-FEIRA | CU31: 46050 | CV31: QUARTA-FEIRA | DB31: 46050 | DC31: QUARTA-FEIRA | DI31: 46050 | DJ31: QUARTA-FEIRA | DP31: 46050 | DQ31: QUARTA-FEIRA | DW31: 46050 | DX31: QUARTA-FEIRA
A32: 46051 | B32: QUINTA-FEIRA | C32: GESPI - REFEITORIO | D32: 180 | E32: 15 | F32: 19 | H32: 46051 | I32: QUINTA-FEIRA | J32: GESPI - REFEITORIO | K32: 250 | L32: 20.5 | M32: 0 | O32: 46051 | P32: QUINTA-FEIRA | V32: 46051 | W32: QUINTA-FEIRA | X32: ANGELA CID | Y32: 100 | Z32: 12.6 | AA32: 0 | AC32: 46051 | AD32: QUINTA-FEIRA | AE32: GESPI - REFEITORIO | AF32: 160 | AG32: 13 | AH32: 0 | AJ32: 46051 | AK32: QUINTA-FEIRA | AL32: ANGELA CID | AM32: 250 | AN32: 13 | AO32: 0 | AQ32: 46051 | AR32: QUINTA-FEIRA | AS32: GESPI - REFEITORIO | AT32: 100 | AU32: 13 | AV32: 0 | AX32: 46051 | AY32: QUINTA-FEIRA | AZ32: ANGELA CID | BA32: 100 | BB32: 13 | BC32: 0 | BE32: 46051 | BF32: QUINTA-FEIRA | BG32: ANGELA CID | BL32: 46051 | BM32: QUINTA-FEIRA | BN32: GESPI - REFEITORIO | BO32: 100 | BP32: 13 | BQ32: 0 | BS32: 46051 | BT32: QUINTA-FEIRA | BZ32: 46051 | CA32: QUINTA-FEIRA | CB32: ANGELA CID | CC32: 100 | CD32: 13 | CG32: 46051 | CH32: QUINTA-FEIRA | CI32: FALTOU | CJ32: 0 | CK32: 0 | CL32: 0 | CN32: 46051 | CO32: QUINTA-FEIRA | CU32: 46051 | CV32: QUINTA-FEIRA | DB32: 46051 | DC32: QUINTA-FEIRA | DI32: 46051 | DJ32: QUINTA-FEIRA | DP32: 46051 | DQ32: QUINTA-FEIRA | DW32: 46051 | DX32: QUINTA-FEIRA
A33: 46052 | B33: SEXTA-FEIRA | C33: GESPI - REFEITORIO | D33: 180 | E33: 15 | F33: 19 | H33: 46052 | I33: SEXTA-FEIRA | J33: GESPI - REFEITORIO | K33: 250 | L33: 20.5 | M33: 0 | O33: 46052 | P33: SEXTA-FEIRA | V33: 46052 | W33: SEXTA-FEIRA | X33: ANGELA CID | Y33: 100 | Z33: 12.6 | AA33: 0 | AC33: 46052 | AD33: SEXTA-FEIRA | AE33: GESPI - REFEITORIO | AF33: 160 | AG33: 13 | AH33: 0 | AJ33: 46052 | AK33: SEXTA-FEIRA | AL33: ANGELA CID | AM33: 250 | AN33: 13 | AO33: 0 | AQ33: 46052 | AR33: SEXTA-FEIRA | AS33: GESPI - REFEITORIO | AT33: 100 | AU33: 13 | AV33: 0 | AX33: 46052 | AY33: SEXTA-FEIRA | AZ33: ANGELA CID | BA33: 100 | BB33: 13 | BC33: 0 | BE33: 46052 | BF33: SEXTA-FEIRA | BG33: ANGELA CID | BL33: 46052 | BM33: SEXTA-FEIRA | BN33: GESPI - REFEITORIO | BO33: 100 | BP33: 13 | BQ33: 0 | BS33: 46052 | BT33: SEXTA-FEIRA | BZ33: 46052 | CA33: SEXTA-FEIRA | CB33: ANGELA CID | CC33: 100 | CD33: 13 | CG33: 46052 | CH33: SEXTA-FEIRA | CI33: GESPI - REFEITORIO | CJ33: 100 | CK33: 13 | CL33: 0 | CN33: 46052 | CO33: SEXTA-FEIRA | CU33: 46052 | CV33: SEXTA-FEIRA | DB33: 46052 | DC33: SEXTA-FEIRA | DI33: 46052 | DJ33: SEXTA-FEIRA | DP33: 46052 | DQ33: SEXTA-FEIRA | DW33: 46052 | DX33: SEXTA-FEIRA
A34: 46053 | B34: SÁBADO | C34: GESPI - REFEITORIO | D34: 180 | E34: 15 | F34: 19 | H34: 46053 | I34: SÁBADO | J34: GESPI - REFEITORIO | K34: 250 | L34: 20.5 | M34: 0 | O34: 46053 | P34: SÁBADO | V34: 46053 | W34: SÁBADO | AC34: 46053 | AD34: SÁBADO | AJ34: 46053 | AK34: SÁBADO | AQ34: 46053 | AR34: SÁBADO | AS34: GESPI - REFEITORIO | AT34: 100 | AU34: 13 | AV34: 0 | AX34: 46053 | AY34: SÁBADO | BE34: 46053 | BF34: SÁBADO | BL34: 46053 | BM34: SÁBADO | BN34: GESPI - REFEITORIO | BO34: 100 | BP34: 13 | BQ34: 0 | BS34: 46053 | BT34: SÁBADO | BZ34: 46053 | CA34: SÁBADO | CG34: 46053 | CH34: SÁBADO | CN34: 46053 | CO34: SÁBADO | CU34: 46053 | CV34: SÁBADO | DB34: 46053 | DC34: SÁBADO | DI34: 46053 | DJ34: SÁBADO | DP34: 46053 | DQ34: SÁBADO | DW34: 46053 | DX34: SÁBADO
A35: 46054 | B35: DOMINGO | C35: GESPI - REFEITORIO | D35: 180 | E35: 15 | F35: 19 | H35: 46054 | I35: DOMINGO | J35: GESPI - REFEITORIO | K35: 250 | L35: 20.5 | M35: 0 | O35: 46054 | P35: DOMINGO | V35: 46054 | W35: DOMINGO | AC35: 46054 | AD35: DOMINGO | AJ35: 46054 | AK35: DOMINGO | AQ35: 46054 | AR35: DOMINGO | AX35: 46054 | AY35: DOMINGO | BE35: 46054 | BF35: DOMINGO | BL35: 46054 | BM35: DOMINGO | BN35: GESPI - REFEITORIO | BO35: 100 | BP35: 13 | BQ35: 0 | BS35: 46054 | BT35: DOMINGO | BZ35: 46054 | CA35: DOMINGO | CG35: 46054 | CH35: DOMINGO | CN35: 46054 | CO35: DOMINGO | CU35: 46054 | CV35: DOMINGO | DB35: 46054 | DC35: DOMINGO | DI35: 46054 | DJ35: DOMINGO | DP35: 46054 | DQ35: DOMINGO | DW35: 46054 | DX35: DOMINGO
A36: 46055 | B36: SEGUNDA-FEIRA | C36: GESPI - REFEITORIO | D36: 180 | E36: 15 | F36: 19 | H36: 46055 | I36: SEGUNDA-FEIRA | J36: LARISSA BERLATO | K36: 250 | L36: 20.5 | M36: 0 | O36: 46055 | P36: SEGUNDA-FEIRA | V36: 46055 | W36: SEGUNDA-FEIRA | X36: ANGELA CID | Y36: 100 | Z36: 12.6 | AA36: 0 | AC36: 46055 | AD36: SEGUNDA-FEIRA | AE36: GESPI - REFEITORIO | AF36: 160 | AG36: 13 | AH36: 0 | AJ36: 46055 | AK36: SEGUNDA-FEIRA | AL36: ANGELA CID | AM36: 250 | AN36: 6.5 | AO36: 0 | AQ36: 46055 | AR36: SEGUNDA-FEIRA | AS36: GESPI - REFEITORIO | AT36: 100 | AU36: 13 | AV36: 0 | AX36: 46055 | AY36: SEGUNDA-FEIRA | AZ36: ANGELA CID | BA36: 100 | BB36: 13 | BC36: 0 | BE36: 46055 | BF36: SEGUNDA-FEIRA | BG36: ANGELA CID | BL36: 46055 | BM36: SEGUNDA-FEIRA | BN36: GESPI - REFEITORIO | BO36: 100 | BP36: 13 | BQ36: 0 | BS36: 46055 | BT36: SEGUNDA-FEIRA | BZ36: 46055 | CA36: SEGUNDA-FEIRA | CB36: ANGELA CID | CC36: 100 | CD36: 6.5 | CE36: 0 | CG36: 46055 | CH36: SEGUNDA-FEIRA | CI36: GESPI - REFEITORIO | CJ36: 100 | CK36: 13 | CL36: 0 | CN36: 46055 | CO36: SEGUNDA-FEIRA | CU36: 46055 | CV36: SEGUNDA-FEIRA | DB36: 46055 | DC36: SEGUNDA-FEIRA | DI36: 46055 | DJ36: SEGUNDA-FEIRA | DP36: 46055 | DQ36: SEGUNDA-FEIRA | DW36: 46055 | DX36: SEGUNDA-FEIRA
A37: 46056 | B37: TERÇA-FEIRA | C37: GESPI - REFEITORIO | D37: 180 | E37: 15 | F37: 19 | H37: 46056 | I37: TERÇA-FEIRA | J37: GESPI - REFEITORIO | K37: 250 | L37: 20.5 | M37: 0 | O37: 46056 | P37: TERÇA-FEIRA | V37: 46056 | W37: TERÇA-FEIRA | X37: ANGELA CID | Y37: 100 | Z37: 12.6 | AA37: 10 | AC37: 46056 | AD37: TERÇA-FEIRA | AE37: GESPI - REFEITORIO | AF37: 160 | AG37: 13 | AH37: 0 | AJ37: 46056 | AK37: TERÇA-FEIRA | AL37: ANGELA CID | AM37: 250 | AN37: 0 | AO37: 10 | AQ37: 46056 | AR37: TERÇA-FEIRA | AS37: GESPI - REFEITORIO | AT37: 100 | AU37: 13 | AV37: 0 | AX37: 46056 | AY37: TERÇA-FEIRA | AZ37: ANGELA CID | BA37: 100 | BB37: 13 | BC37: 10 | BE37: 46056 | BF37: TERÇA-FEIRA | BG37: ANGELA CID | BL37: 46056 | BM37: TERÇA-FEIRA | BN37: GESPI - REFEITORIO | BO37: 100 | BP37: 13 | BQ37: 0 | BS37: 46056 | BT37: TERÇA-FEIRA | BZ37: 46056 | CA37: TERÇA-FEIRA | CB37: ANGELA CID | CC37: 100 | CD37: 0 | CE37: 10 | CG37: 46056 | CH37: TERÇA-FEIRA | CI37: GESPI - REFEITORIO | CJ37: 100 | CK37: 13 | CL37: 0 | CN37: 46056 | CO37: TERÇA-FEIRA | CP37: ANGELA CID | CQ37: 135 | CR37: 13 | CS37: 10 | CU37: 46056 | CV37: TERÇA-FEIRA | DB37: 46056 | DC37: TERÇA-FEIRA | DI37: 46056 | DJ37: TERÇA-FEIRA | DP37: 46056 | DQ37: TERÇA-FEIRA | DW37: 46056 | DX37: TERÇA-FEIRA
A38: 46057 | B38: QUARTA-FEIRA | C38: GESPI - REFEITORIO | D38: 180 | E38: 15 | F38: 19 | H38: 46057 | I38: QUARTA-FEIRA | J38: GESPI - REFEITORIO | K38: 250 | L38: 20.5 | M38: 0 | O38: 46057 | P38: QUARTA-FEIRA | V38: 46057 | W38: QUARTA-FEIRA | X38: ANGELA CID | Y38: 100 | Z38: 12.6 | AA38: 10 | AC38: 46057 | AD38: QUARTA-FEIRA | AE38: GESPI - REFEITORIO | AF38: 160 | AG38: 13 | AH38: 0 | AJ38: 46057 | AK38: QUARTA-FEIRA | AL38: ANGELA CID | AM38: 250 | AN38: 0 | AO38: 10 | AQ38: 46057 | AR38: QUARTA-FEIRA | AS38: GESPI - REFEITORIO | AT38: 100 | AU38: 13 | AV38: 0 | AX38: 46057 | AY38: QUARTA-FEIRA | AZ38: ANGELA CID | BA38: 100 | BB38: 0 | BC38: 10 | BE38: 46057 | BF38: QUARTA-FEIRA | BL38: 46057 | BM38: QUARTA-FEIRA | BN38: GESPI - REFEITORIO | BO38: 100 | BP38: 13 | BQ38: 0 | BS38: 46057 | BT38: QUARTA-FEIRA | BZ38: 46057 | CA38: QUARTA-FEIRA | CB38: ANGELA CID | CC38: 100 | CD38: 0 | CE38: 10 | CG38: 46057 | CH38: QUARTA-FEIRA | CI38: GESPI - REFEITORIO | CJ38: 100 | CK38: 13 | CL38: 0 | CN38: 46057 | CO38: QUARTA-FEIRA | CP38: ANGELA CID | CQ38: 135 | CR38: 13 | CS38: 10 | CU38: 46057 | CV38: QUARTA-FEIRA | DB38: 46057 | DC38: QUARTA-FEIRA | DI38: 46057 | DJ38: QUARTA-FEIRA | DP38: 46057 | DQ38: QUARTA-FEIRA | DW38: 46057 | DX38: QUARTA-FEIRA
A39: 46058 | B39: QUINTA-FEIRA | C39: GESPI - REFEITORIO | D39: 180 | E39: 15 | F39: 19 | H39: 46058 | I39: QUINTA-FEIRA | J39: GESPI - REFEITORIO | K39: 250 | L39: 20.5 | M39: 0 | O39: 46058 | P39: QUINTA-FEIRA | V39: 46058 | W39: QUINTA-FEIRA | X39: ANGELA CID | Y39: 100 | Z39: 12.6 | AA39: 10 | AC39: 46058 | AD39: QUINTA-FEIRA | AE39: GESPI - REFEITORIO | AF39: 160 | AG39: 13 | AH39: 0 | AJ39: 46058 | AK39: QUINTA-FEIRA | AL39: ANGELA CID | AM39: 250 | AN39: 0 | AO39: 10 | AQ39: 46058 | AR39: QUINTA-FEIRA | AS39: GESPI - REFEITORIO | AT39: 100 | AU39: 13 | AV39: 0 | AX39: 46058 | AY39: QUINTA-FEIRA | AZ39: ANGELA CID | BA39: 100 | BB39: 0 | BC39: 10 | BE39: 46058 | BF39: QUINTA-FEIRA | BL39: 46058 | BM39: QUINTA-FEIRA | BN39: GESPI - REFEITORIO | BO39: 100 | BP39: 13 | BQ39: 0 | BS39: 46058 | BT39: QUINTA-FEIRA | BZ39: 46058 | CA39: QUINTA-FEIRA | CB39: ANGELA CID | CC39: 100 | CD39: 0 | CE39: 10 | CG39: 46058 | CH39: QUINTA-FEIRA | CI39: GESPI - REFEITORIO | CJ39: 100 | CK39: 13 | CL39: 0 | CN39: 46058 | CO39: QUINTA-FEIRA | CP39: ANGELA CID | CQ39: 135 | CR39: 13 | CS39: 10 | CU39: 46058 | CV39: QUINTA-FEIRA | DB39: 46058 | DC39: QUINTA-FEIRA | DI39: 46058 | DJ39: QUINTA-FEIRA | DP39: 46058 | DQ39: QUINTA-FEIRA | DW39: 46058 | DX39: QUINTA-FEIRA
A40: 46059 | B40: SEXTA-FEIRA | C40: GESPI - REFEITORIO | D40: 180 | E40: 15 | F40: 19 | H40: 46059 | I40: SEXTA-FEIRA | J40: GESPI - REFEITORIO | K40: 250 | L40: 20.5 | M40: 0 | O40: 46059 | P40: SEXTA-FEIRA | V40: 46059 | W40: SEXTA-FEIRA | X40: ANGELA CID | Y40: 120 | Z40: 12.6 | AA40: 10 | AC40: 46059 | AD40: SEXTA-FEIRA | AE40: GESPI - REFEITORIO | AF40: 180 | AG40: 13 | AH40: 0 | AJ40: 46059 | AK40: SEXTA-FEIRA | AL40: ANGELA CID | AM40: 250 | AN40: 0 | AO40: 10 | AQ40: 46059 | AR40: SEXTA-FEIRA | AS40: GESPI - REFEITORIO | AT40: 120 | AU40: 13 | AV40: 0 | AX40: 46059 | AY40: SEXTA-FEIRA | AZ40: ANGELA CID | BA40: 120 | BB40: 0 | BC40: 10 | BE40: 46059 | BF40: SEXTA-FEIRA | BL40: 46059 | BM40: SEXTA-FEIRA | BN40: GESPI - REFEITORIO | BO40: 120 | BP40: 13 | BQ40: 0 | BS40: 46059 | BT40: SEXTA-FEIRA | BZ40: 46059 | CA40: SEXTA-FEIRA | CB40: ANGELA CID | CC40: 120 | CD40: 0 | CE40: 10 | CG40: 46059 | CH40: SEXTA-FEIRA | CI40: FALTOU | CJ40: 0 | CK40: 0 | CL40: 0 | CN40: 46059 | CO40: SEXTA-FEIRA | CP40: ANGELA CID | CQ40: 135 | CR40: 13 | CS40: 10 | CU40: 46059 | CV40: SEXTA-FEIRA | DB40: 46059 | DC40: SEXTA-FEIRA | DI40: 46059 | DJ40: SEXTA-FEIRA | DP40: 46059 | DQ40: SEXTA-FEIRA | DW40: 46059 | DX40: SEXTA-FEIRA
A41: 46060 | B41: SÁBADO | C41: GESPI - REFEITORIO | D41: 180 | E41: 15 | F41: 19 | H41: 46060 | I41: SÁBADO | J41: GESPI - REFEITORIO | K41: 250 | L41: 20.5 | M41: 0 | O41: 46060 | P41: SÁBADO | V41: 46060 | W41: SÁBADO | AC41: 46060 | AD41: SÁBADO | AJ41: 46060 | AK41: SÁBADO | AQ41: 46060 | AR41: SÁBADO | AX41: 46060 | AY41: SÁBADO | BE41: 46060 | BF41: SÁBADO | BL41: 46060 | BM41: SÁBADO | BN41: GESPI - REFEITORIO | BO41: 120 | BP41: 13 | BQ41: 0 | BS41: 46060 | BT41: SÁBADO | BZ41: 46060 | CA41: SÁBADO | CG41: 46060 | CH41: SÁBADO | CN41: 46060 | CO41: SÁBADO | CP41: CLÍNICA DGM | CQ41: 135 | CR41: 13 | CS41: 0 | CU41: 46060 | CV41: SÁBADO | DB41: 46060 | DC41: SÁBADO | DI41: 46060 | DJ41: SÁBADO | DP41: 46060 | DQ41: SÁBADO | DW41: 46060 | DX41: SÁBADO
...

Sheet PAGAMENTOS
A1: COLABORADOR | C1: CRISTIANO MATIAS DA SILVA | G1: VALOR PAGO (DIÁRIAS + VT + VA) | I1: =SUM(B6:B199) -> 12796 | L1: COLABORADOR | N1: JOSE CARLOS MONTELES CARVALHO | R1: VALOR PAGO (DIÁRIAS + VT + VA) | T1: =SUM(M6:M202) -> 0 | W1: COLABORADOR | Y1: LUCAS HENRIQUE ALBERNAZ | AC1: VALOR PAGO (DIÁRIAS + VT + VA) | AE1: =SUM(X6:X204) -> 6312.6 | AH1: COLABORADOR | AJ1: ROGER ARMANDO SEQUERA RIVAS | AN1: VALOR PAGO (DIÁRIAS + VT + VA) | AP1: =SUM(AI6:AI202) -> 10297 | AS1: COLABORADOR | AU1: VITOR HUGO BRAGA | AY1: VALOR PAGO (DIÁRIAS + VT + VA) | BA1: =SUM(AT6:AT202) -> 13789.5 | BD1: COLABORADOR | BF1: DAVI FERREIRA DA SILVA | BJ1: VALOR PAGO (DIÁRIAS + VT + VA) | BL1: =SUM(BE6:BE199) -> 3571 | BO1: COLABORADOR | BQ1: VINICIUS OLIVEIRA COSTA ROMANO | BU1: VALOR PAGO (DIÁRIAS + VT + VA) | BW1: =SUM(BP6:BP200) -> 6565.5 | BZ1: COLABORADOR | CB1: PEDRO EDNEI BATISTA PEREIRA | CF1: VALOR PAGO (DIÁRIAS + VT + VA) | CH1: =SUM(CA6:CA200) -> 6996 | CK1: COLABORADOR | CM1: MAICON WILLIAN | CQ1: VALOR PAGO (DIÁRIAS + VT + VA) | CS1: =SUM(CL6:CL200) -> 272 | CV1: COLABORADOR | CX1: FABRICIO FERREIRA DA SILVA | DB1: VALOR PAGO (DIÁRIAS + VT + VA) | DD1: =SUM(CW6:CW200) -> 5205.5 | DG1: COLABORADOR | DI1: MURILO CAIQUE DE LIMA CECIM | DM1: VALOR PAGO (DIÁRIAS + VT + VA) | DO1: =SUM(DH6:DH200) -> 1474 | DR1: COLABORADOR | DT1: PAULO CESAR BITENCOURT DE SOUSA | DX1: VALOR PAGO (DIÁRIAS + VT + VA) | DZ1: =SUM(DS6:DS200) -> 7081 | EC1: COLABORADOR | EE1: LEONARDO OLIVEIRA SANTOS | EI1: VALOR PAGO (DIÁRIAS + VT + VA) | EK1: =SUM(ED6:ED200) -> 3774 | EN1: COLABORADOR | EP1: MATHEUS ANTONIO BARBOSA DOS SANTOS | ET1: VALOR PAGO (DIÁRIAS + VT + VA) | EV1: =SUM(EO6:EO200) -> 7581 | EY1: COLABORADOR | FA1: RENAN ANDLER ARAÚJO SIMEÃO | FE1: VALOR PAGO (DIÁRIAS + VT + VA) | FG1: =SUM(EZ6:EZ200) -> 723 | FJ1: COLABORADOR | FL1: MARCOS VINICIUS BARBOSA CARDOSO | FP1: VALOR PAGO (DIÁRIAS + VT + VA) | FR1: =SUM(FK6:FK200) -> 3471 | FU1: COLABORADOR | FW1: JOSUÉ DIAS DE ANDRADE | GA1: VALOR PAGO (DIÁRIAS + VT + VA) | GC1: =SUM(FV6:FV200) -> 2326
A2: CHAVE PIX | C2: 12 99226-3090 | G2: SALDO | I2: =DIÁRIAS!D370-PAGAMENTOS!I1 -> 180 | L2: CHAVE PIX | N2: 6500874374 | R2: SALDO | T2: =DIÁRIAS!R370-PAGAMENTOS!T1 -> 0 | W2: CHAVE PIX | Y2: 12982381942 | AC2: SALDO | AE2: =DIÁRIAS!Y371-PAGAMENTOS!AE1 -> 120 | AH2: CHAVE PIX | AJ2: 710.616.372-47 | AN2: SALDO | AP2: =DIÁRIAS!AF370-PAGAMENTOS!AP1 -> 180 | AS2: CHAVE PIX | AU2: 509.136.448-03 | AY2: SALDO | BA2: =DIÁRIAS!AM370-PAGAMENTOS!BA1 -> 250 | BD2: CHAVE PIX | BF2: 45194923864 | BJ2: SALDO | BL2: =DIÁRIAS!AT370-PAGAMENTOS!BL1 -> -65 | BO2: CHAVE PIX | BQ2: 12974100682 | BU2: SALDO | BW2: =DIÁRIAS!BA371-PAGAMENTOS!BW1 -> 120 | BZ2: CHAVE PIX | CB2: 12 98808-4011 | CF2: SALDO | CH2: =DIÁRIAS!BO370-PAGAMENTOS!CH1 -> 0 | CK2: CHAVE PIX | CQ2: SALDO | CS2: =DIÁRIAS!BV370-PAGAMENTOS!CS1 -> -48 | CV2: CHAVE PIX | DB2: SALDO | DD2: =DIÁRIAS!CC371-PAGAMENTOS!DD1 -> 120 | DG2: CHAVE PIX | DM2: SALDO | DO2: =DIÁRIAS!CJ370-PAGAMENTOS!DO1 -> -13 | DR2: CHAVE PIX | DX2: SALDO | DZ2: =DIÁRIAS!CQ370-PAGAMENTOS!DZ1 -> 180 | EC2: CHAVE PIX | EE2: 57955684818 | EI2: SALDO | EK2: =DIÁRIAS!CX370-PAGAMENTOS!EK1 -> 120 | EN2: CHAVE PIX | EP2: 393.380.918-56 | ET2: SALDO | EV2: =DIÁRIAS!DE372-PAGAMENTOS!EV1 -> 200 | EY2: CHAVE PIX | FE2: SALDO | FG2: =DIÁRIAS!DL370-PAGAMENTOS!FG1 -> 0 | FJ2: CHAVE PIX | FP2: SALDO | FR2: =DIÁRIAS!DS372-PAGAMENTOS!FR1 -> 120 | FU2: CHAVE PIX | FW2: 12 98812-8575 | GA2: SALDO | GC2: =DIÁRIAS!DZ370-PAGAMENTOS!GC1 -> 120
A4: PAGAMENTOS | E4: REEMBOLSOS | L4: PAGAMENTOS | P4: REEMBOLSOS | W4: PAGAMENTOS | AA4: REEMBOLSOS | EXTRAS | AH4: PAGAMENTOS | AL4: REEMBOLSOS | AS4: PAGAMENTOS | AW4: REEMBOLSOS | BD4: PAGAMENTOS | BH4: REEMBOLSOS | BO4: PAGAMENTOS | BS4: REEMBOLSOS | BZ4: PAGAMENTOS | CD4: REEMBOLSOS | CK4: PAGAMENTOS | CO4: REEMBOLSOS | CV4: PAGAMENTOS | CZ4: REEMBOLSOS / EXTRAS | DG4: PAGAMENTOS | DK4: REEMBOLSOS | DR4: PAGAMENTOS | DV4: REEMBOLSOS | EC4: PAGAMENTOS | EG4: REEMBOLSOS / EXTRAS | EN4: PAGAMENTOS | ER4: REEMBOLSOS | EY4: PAGAMENTOS | FC4: REEMBOLSOS | FJ4: PAGAMENTOS | FN4: REEMBOLSOS | FU4: PAGAMENTOS | FY4: REEMBOLSOS
A5: DATA PG | B5: VALOR | C5: DESCRIÇÃO | E5: DATA | F5: VALOR | G5: DESCRIÇÃO | H5: CENTRO DE CUSTO | I5: DATA PG | J5: STATUS | L5: DATA PG | M5: VALOR | N5: DESCRIÇÃO | P5: DATA | Q5: VALOR | R5: DESCRIÇÃO | S5: CENTRO DE CUSTO | T5: DATA PG | U5: STATUS | W5: DATA PG | X5: VALOR | Y5: DESCRIÇÃO | AA5: DATA | AB5: VALOR | AC5: DESCRIÇÃO | AD5: CENTRO DE CUSTO | AE5: DATA PG | AF5: STATUS | AH5: DATA PG | AI5: VALOR | AJ5: DESCRIÇÃO | AL5: DATA | AM5: VALOR | AN5: DESCRIÇÃO | AO5: CENTRO DE CUSTO | AP5: DATA PG | AQ5: STATUS | AS5: DATA PG | AT5: VALOR | AU5: DESCRIÇÃO | AW5: DATA | AX5: VALOR | AY5: DESCRIÇÃO | AZ5: CENTRO DE CUSTO | BA5: DATA PG | BB5: STATUS | BD5: DATA PG | BE5: VALOR | BF5: DESCRIÇÃO | BH5: DATA | BI5: VALOR | BJ5: DESCRIÇÃO | BK5: CENTRO DE CUSTO | BL5: DATA PG | BM5: STATUS | BO5: DATA PG | BP5: VALOR | BQ5: DESCRIÇÃO | BS5: DATA | BT5: VALOR | BU5: DESCRIÇÃO | BV5: CENTRO DE CUSTO | BW5: DATA PG | BX5: STATUS | BZ5: DATA PG | CA5: VALOR | CB5: DESCRIÇÃO | CD5: DATA | CE5: VALOR | CF5: DESCRIÇÃO | CG5: CENTRO DE CUSTO | CH5: DATA PG | CI5: STATUS | CK5: DATA PG | CL5: VALOR | CM5: DESCRIÇÃO | CO5: DATA | CP5: VALOR | CQ5: DESCRIÇÃO | CR5: CENTRO DE CUSTO | CS5: DATA PG | CT5: STATUS | CV5: DATA PG | CW5: VALOR | CX5: DESCRIÇÃO | CZ5: DATA | DA5: VALOR | DB5: DESCRIÇÃO | DC5: CENTRO DE CUSTO | DD5: DATA PG | DE5: STATUS | DG5: DATA PG | DH5: VALOR | DI5: DESCRIÇÃO | DK5: DATA | DL5: VALOR | DM5: DESCRIÇÃO | DN5: CENTRO DE CUSTO | DO5: DATA PG | DP5: STATUS | DR5: DATA PG | DS5: VALOR | DT5: DESCRIÇÃO | DV5: DATA | DW5: VALOR | DX5: DESCRIÇÃO | DY5: CENTRO DE CUSTO | DZ5: DATA PG | EA5: STATUS | EC5: DATA PG | ED5: VALOR | EE5: DESCRIÇÃO | EG5: DATA | EH5: VALOR | EI5: DESCRIÇÃO | EJ5: CENTRO DE CUSTO | EK5: DATA PG | EL5: STATUS | EN5: DATA PG | EO5: VALOR | EP5: DESCRIÇÃO | ER5: DATA | ES5: VALOR | ET5: DESCRIÇÃO | EU5: CENTRO DE CUSTO | EV5: DATA PG | EW5: STATUS | EY5: DATA PG | EZ5: VALOR | FA5: DESCRIÇÃO | FC5: DATA | FD5: VALOR | FE5: DESCRIÇÃO | FF5: CENTRO DE CUSTO | FG5: DATA PG | FH5: STATUS | FJ5: DATA PG | FK5: VALOR | FL5: DESCRIÇÃO | FN5: DATA | FO5: VALOR | FP5: DESCRIÇÃO | FQ5: CENTRO DE CUSTO | FR5: DATA PG | FS5: STATUS | FU5: DATA PG | FV5: VALOR | FW5: DESCRIÇÃO | FY5: DATA | FZ5: VALOR | GA5: DESCRIÇÃO | GB5: CENTRO DE CUSTO | GC5: DATA PG | GD5: STATUS
A6: 46024 | B6: 170 | C6: VT + VA 05.01 a 09.01 | E6: 46024 | F6: 15 | G6: VALE TRANSPORTE | H6: GESPI - REFEITORIO | I6: 46027 | J6: PAGO | W6: 46027 | X6: 120 | Y6: Diária 05.01 | AA6: 46039 | AB6: =63-22.2 -> 40.8 | AC6: UBER | AD6: ESCRITÓRIO | AE6: 46039 | AF6: PAGO | AH6: 46027 | AI6: 180 | AJ6: Diária 05.01 | AL6: 46031 | AM6: 20.95 | AN6: UBER | AO6: ESCRITÓRIO | AP6: 46036 | AQ6: PAGO | AS6: 46027 | AT6: 250 | AU6: DIÁRIA 05.01 | AW6: 46027 | AX6: 19.5 | AY6: UBER | AZ6: GATTAI - ROBSON | BA6: 46027 | BB6: PAGO | BD6: 46024 | BE6: 60 | BF6: VT 05.01 a 09.01 | BH6: 46375 | BI6: 100 | BJ6: BÔNUS TRABALHO NOTURNO | BK6: GESPI - ENGENHARIA | BL6: 46042 | BM6: PAGO | BO6: 46027 | BP6: 120 | BQ6: DIÁRIA 05.01 | BS6: 46027 | BT6: 9.1 | BU6: UBER | BV6: GATTAI - ROBSON | BW6: 46036 | BX6: PAGO | BZ6: 46024 | CA6: 60 | CB6: VT 05.01 a 09.01 | CD6: 46035 | CE6: 250 | CF6: BÔNUS TRABALHO NOTURNO | CG6: GESPI - SALA DE CONTROLE | CH6: 46049 | CI6: PAGO | CK6: 46024 | CL6: 60 | CM6: VT 05.01 a 09.01 | CV6: 46036 | CW6: 60 | CX6: VT 12.01 A 16.01 | CZ6: 46044 | DA6: =100/2 -> 50 | DB6: TRABHALHOU ATÉ 22H | DC6: CLINICA DGM | DD6: 46058 | DE6: PAGO | DG6: 46042 | DH6: 200 | DI6: DIÁRIAS | DR6: 46059 | DS6: 392 | DT6: 3 DIARIAS + 3 VT + 3 CAFÉ | DV6: 46069 | DW6: 15 | DX6: VALE TRANSPORTE | DY6: GESPI - REFEITORIO | DZ6: 46077 | EA6: PAGO | EC6: 46066 | ED6: 63 | EE6: VT 16.02 a 20.02 | EG6: 46082 | EH6: 155 | EI6: DIÁRIA EXTRA | EJ6: GESPI - REFEITORIO | EK6: 46086 | EL6: PAGO | EN6: 46066 | EO6: 63 | EP6: VT 16.02 a 20.02 | ER6: 46075 | ES6: 300 | ET6: DIÁRIA EXTRA | EU6: GESPI - REFEITORIO | EV6: 46086 | EW6: PAGO | EY6: 46066 | EZ6: 63 | FA6: VT 16.02 a 20.02 | FJ6: 46080 | FK6: 65 | FL6: VT | FN6: 46081 | FO6: 120 | FP6: DIÁRIA EXTRA | FQ6: GESPI - REFEITORIO | FR6: 46086 | FS6: PAGO | FU6: 46086 | FV6: 65 | FY6: 46082 | FZ6: 155 | GA6: DIÁRIA EXTRA
A7: 46027 | B7: 608 | C7: DIÁRIAS 02.01 a 05.01 | E7: 46025 | F7: 15 | G7: VALE TRANSPORTE | H7: GESPI - REFEITORIO | I7: 46027 | J7: PAGO | W7: 46036 | X7: 60 | Y7: VT 12.01 a 16.01 | AA7: 46042 | AB7: 50 | AC7: TRABALHOU ATÉ 22H | AD7: CLÍNICA DGM | AE7: 46058 | AF7: PAGO | AH7: 46036 | AI7: 60 | AJ7: VT 12.01 A 16.01 | AL7: 46064 | AM7: =12*20 -> 240 | AN7: DIFERENÇA $ DIÁRIA (12X20) | AO7: GESPI - ENGENHARIA | AP7: 46064 | AQ7: PAGO | AS7: 46036 | AT7: 60 | AU7: VT 12.01 a 16.01 | AW7: 46031 | AX7: 25.16 | AY7: UBER | AZ7: GATTAI - ROBSON | BA7: 46039 | BB7: PAGO | BD7: 46027 | BE7: 212 | BF7: DIÁRIAS 02.01 e 05.01 | BH7: 46064 | BI7: =12*20 -> 240 | BJ7: DIFERENÇA $ DIÁRIAS | BK7: GESPI - ENGENHARIA | BL7: 46064 | BM7: PAGO | BO7: 46036 | BP7: 30 | BQ7: VT 12.01 a 16.01 | BS7: 46031 | BT7: 16.32 | BU7: UBER | BV7: ESCRITÓRIO | BW7: 46036 | BX7: PAGO | BZ7: 46027 | CA7: 324 | CB7: Diárias 02.01 a 05.01 | CK7: 46027 | CL7: 212 | CM7: Diárias 02.10 e 05.01 | CV7: 46039 | CW7: 60 | CX7: VT 19.01 A 23.01 | CZ7: 46064 | DA7: 220 | DB7: DIFERENÇA $ DIÁRIAS | DC7: ANGELA CID | DD7: 46064 | DE7: PAGO | DG7: 46042 | DH7: 60 | DI7: VT 19.01 A 23.01 | DR7: 46059 | DS7: 50 | DT7: CAFÉ 09.02 a 13.02 | DV7: 46070 | DW7: 15 | DX7: VALE TRANSPORTE | DY7: GESPI - REFEITORIO | DZ7: 46077 | EA7: PAGO | EC7: 46071 | ED7: 98 | EE7: SALDO VT + CAFÉ | EN7: 46071 | EO7: 114 | EP7: VT + Café 16.02 a 20.02 | ER7: 46078 | ES7: 100 | ET7: 1/2 DIÁRIA | EU7: CLINICA DGM | EV7: 46086 | EW7: PAGO | EY7: 46071 | EZ7: 10 | FA7: Saldo CAFÉ 16.02 a 20.02 | FJ7: 46084 | FK7: 40 | FL7: CAFÉ | FN7: 46082 | FO7: 155 | FP7: DIÁRIA EXTRA | FQ7: GESPI - REFEITORIO | FR7: 46086 | FS7: PAGO | FU7: 46086 | FV7: 678
A8: 46034 | B8: 170 | C8: VT + VA 12.01 a 16.01 | E8: 46027 | F8: 15 | G8: VALE TRANSPORTE | H8: GESPI - REFEITORIO | I8: 46042 | J8: PAGO | W8: 46039 | X8: =12.6*5 -> 63 | Y8: VT 19.01 A 23.01 | AA8: 46062 | AB8: =12*20 -> 240 | AC8: DIFERENÇA $ DIÁRIA | AD8: ANGELA CID | AE8: 46062 | AF8: PAGO | AH8: 46039 | AI8: 60 | AJ8: VT 19.01 A 23.01 | AS8: 46039 | AT8: 60 | AU8: VT 19.01 A 23.01 | AW8: 46023 | AX8: 100 | AY8: LASER 6/12 | AZ8: ESCRITÓRIO | BA8: 46042 | BB8: PAGO | BD8: 46034 | BE8: 60 | BF8: VT 12.01 A 16.01 | BO8: 46039 | BP8: 60 | BQ8: VT 19.01 A 23.01 | BS8: 46034 | BT8: 16.1 | BU8: UBER | BV8: ESCRITÓRIO | BW8: 46036 | BX8: PAGO | BZ8: 46034 | CA8: 60 | CB8: VT 12.01 a 16.01 | CV8: 46042 | CW8: 476 | CX8: DIÁRIAS 14.01 A 20.01 | CZ8: 46043 | DA8: 50 | DB8: TRABALHOU ATÉ 22H | DC8: CLÍNICA DGM | DD8: 46064 | DE8: PAGO | DG8: 46045 | DH8: 60 | DI8: VT 26.01 a 30.01 | DR8: 46059 | DS8: 63 | DT8: VT 09.02 a 13.02 | DV8: 46071 | DW8: 15 | DX8: VALE TRANSPORTE | DY8: GESPI - REFEITORIO | DZ8: 46077 | EA8: PAGO | EC8: 46073 | ED8: 840 | EE8: DIÁRIAS 06.02 a 20.02 | EN8: 46073 | EO8: 1080 | EP8: DIÁRIAS10.02 a 20.02 | ER8: 46081 | ES8: 200 | ET8: DIÁRIA EXTRA | EU8: GESPI - REFEITORIO | EV8: 46086 | EW8: PAGO | EY8: 46073 | EZ8: 600 | FA8: DIÁRIAS10.02 a 20.02 | FJ8: 46086 | FK8: 1433 | FL8: 11 DIÁRIAS | FN8: 46085 | FO8: 60 | FP8: 1/2 DIÁRIA | FQ8: CLINICA | FR8: 46086 | FS8: PAGO | FU8: 46094 | FV8: 65
A9: 46039 | B9: 170 | C9: VT 12.01 a 16.01 | E9: 46028 | F9: 15 | G9: VALE TRANSPORTE | H9: GESPI - REFEITORIO | I9: 46042 | J9: PAGO | W9: 46042 | X9: 1183 | Y9: DIÁRIAS 06.01 A 20.01 | AH9: 46042 | AI9: 1840 | AJ9: DIÁRIAS 06.01 A 20.01 | AS9: 46042 | AT9: 2488 | AU9: DIÁRIAS 06.01 A 20.01 | AW9: 46035 | AX9: 375 | AY9: BÔNUS TRABALHO NOTURNO | AZ9: GESPI - SALA DE CONTROLE | BA9: 46052 | BB9: PAGO | BD9: 46036 | BE9: 75 | BF9: VALE DIÁRIAS | BO9: 46042 | BP9: 1180 | BQ9: DIÁRIAS 06.01 A 20.01 | BS9: 46034 | BT9: 11.92 | BU9: UBER | BV9: ESCRITÓRIO | BW9: 46036 | BX9: PAGO | BZ9: 46039 | CA9: 60 | CB9: VT 19.01 a 23.01 | CV9: 46045 | CW9: 60 | CX9: VT 26.01 a 30.01 | CZ9: 46045 | DA9: 50 | DB9: TRABALHOU ATÉ 22H | DC9: CLÍNICA DGM | DD9: 46064 | DE9: PAGO | DG9: 46052 | DH9: 60 | DI9: VT 02.02 a 06.02 | DR9: 46066 | DS9: 63 | DT9: VT 16.02 a 20.02 | DV9: 46072 | DW9: 15 | DX9: VALE TRANSPORTE | DY9: GESPI - REFEITORIO | DZ9: 46077 | EA9: PAGO | EC9: 46073 | ED9: 50 | EE9: CAFÉ 23.02 a 27.02 | EN9: 46073 | EO9: 115 | EP9: VT + CAFÉ 24.02 a 27.02 | ER9: 46085 | ES9: 100 | ET9: 1/2 DIÁRIA | EU9: CLINICA DGM | EV9: 46086 | EW9: PAGO | EY9: 46073 | EZ9: 50 | FA9: VT + CAFÉ 24.02 a 27.02 | FJ9: 46094 | FK9: 65 | FN9: 46101 | FO9: =4*60 -> 240 | FP9: LIMPEZA CLINICA | FQ9: CLINICA | FR9: 46101 | FU9: 46101 | FV9: 65 | FW9: VT
A10: 46042 | B10: 1766 | C10: DIÁRIAS 06.01 a 20.01 | E10: 46029 | F10: 15 | G10: VALE TRANSPORTE | H10: GESPI - REFEITORIO | I10: 46042 | J10: PAGO | W10: 46045 | X10: 63 | Y10: VT + VA 26.01 a 30.01 | AH10: 46045 | AI10: 60 | AJ10: VT + VA 26.01 a 30.01 | AS10: 46052 | AT10: 250 | AU10: DIÁRIA 13.01 | AW10: 46042 | AX10: =250/2 -> 125 | AY10: TRABALHOU ATÉ 22H | AZ10: CLÍNICA DGM | BA10: 46058 | BB10: PAGO | BD10: 46039 | BE10: 60 | BF10: VT 19.01 A 23.01 | BO10: 46045 | BP10: 60 | BQ10: VT 26.01 a 30.01 | BS10: 46035 | BT10: 17.85 | BU10: UBER | BV10: ESCRITÓRIO | BW10: 46036 | BX10: PAGO | BZ10: 46042 | CA10: 988 | CB10: DIÁRIAS 06.01 A 20.01 | CV10: 46052 | CW10: 60 | CX10: VT 02.02 a 06.02 | CZ10: 46078 | DA10: 60 | DB10: 1/2 DIÁRIA | DC10: CLINICA DGM | DD10: 46086 | DE10: PAGO | DG10: 46058 | DH10: 1094 | DI10: DIÁRIAS 21.01 a 05.02 | DR10: 46064 | DS10: 60 | DT10: DIFERENCA DIARIAS | DV10: 46073 | DW10: 15 | DX10: VALE TRANSPORTE | DY10: GESPI - REFEITORIO | DZ10: 46077 | EA10: PAGO | EC10: 46084 | ED10: 40 | EE10: CAFÉ 23.02 a 27.02 | EN10: 46077 | EO10: 720 | EP10: SALDO DIÁRIAS | FJ10: 46098 | FK10: 50 | FU10: 46101 | FV10: 1453 | FW10: 12 DIÁRIAS
A11: 46045 | B11: 170 | C11: VT + VA 26.01 a 30.01 | E11: 46031 | F11: 15 | G11: VALE TRANSPORTE | H11: GESPI - SALA DE CONTROLE | I11: 46042 | J11: PAGO | W11: 46052 | X11: 63 | Y11: VT + VA 02.02 a 06.02 | AH11: 46052 | AI11: 60 | AJ11: VT + VA 02.02 a 06.02 | AS11: 46045 | AT11: 60 | AU11: VT 26.01 a 30.01 | AW11: 46043 | AX11: =250/2 -> 125 | AY11: TRABALHOU ATÉ 22H | AZ11: CLÍNICA DGM | BA11: 46058 | BB11: PAGO | BD11: 46042 | BE11: 913 | BF11: DIÁRIAS 06.01 A 20.01 | BO11: 46052 | BP11: 60 | BQ11: VT 02.02 a 06.02 | BS11: 46036 | BT11: 9 | BU11: UBER | BV11: ESCRITÓRIO | BW11: 46036 | BX11: PAGO | BZ11: 46045 | CA11: 60 | CB11: VT 26.01 a 30.01 | CV11: 46058 | CW11: 1088.5 | CX11: DIÁRIAS 21.01 a 05.02 | DR11: 46073 | DS11: 1867 | DT11: DIÁRIAS 06.02 a 20.02 | DV11: 46076 | DW11: 15 | DX11: VALE TRANSPORTE | DY11: GESPI - REFEITORIO | DZ11: 46077 | EA11: PAGO | EC11: 46086 | ED11: 50 | EE11: CAFÉ 09.03 a 13.03 | EN11: 46080 | EO11: 65 | EP11: VT | FJ11: 46101 | FK11: 1703
A12: 46052 | B12: 170 | C12: VT + VA 02.02 a 06.02 | E12: 46035 | F12: 15 | G12: VALE TRANSPORTE | H12: GESPI - REFEITORIO | I12: 46042 | J12: PAGO | W12: 46057 | X12: 40 | Y12: CAFÉ 02.02 a 06.02 | AH12: 46058 | AI12: 1927 | AJ12: DIÁRIAS 21.01 a 06.02 | AS12: 46052 | AT12: 60 | AU12: VT 02.02 a 06.02 | AW12: 46044 | AX12: =250/2 -> 125 | AY12: TRABALHOU ATÉ 22H | AZ12: CLÍNICA DGM | BA12: 46058 | BB12: PAGO | BD12: 46045 | BE12: 60 | BF12: VT 26.01 a 30.01 | BO12: 46057 | BP12: 6 | BQ12: SALDO CAFÉ | BS12: 46058 | BT12: =10*20 -> 200 | BU12: DIFERENÇA $ DIÁRIA | BV12: ANGELA CID | BW12: 46062 | BX12: PAGO | BZ12: 46052 | CA12: 60 | CB12: VT 02.02 a 06.02 | CV12: 46059 | CW12: 50 | CX12: CAFÉ 09.02 a 13.02 | DR12: 46073 | DS12: 65 | DT12: VT 23.02 a 27.02 | DV12: 46077 | DW12: 15 | DX12: VALE TRANSPORTE | DY12: GESPI - REFEITORIO | DZ12: 46077 | EA12: PAGO | EC12: 46086 | ED12: 1213 | EE12: 11 DIÁRIAS | EN12: 46084 | EO12: 40 | FJ12: 46101 | FK12: 65
A13: 46057 | B13: 68 | C13: VT + VA 31.01 e 01.02 | E13: 46036 | F13: 15 | G13: VALE TRANSPORTE | H13: GESPI - REFEITORIO | I13: 46042 | J13: PAGO | W13: 46058 | X13: 1200 | Y13: DIÁRIAS 21.01 a 06.02 | AH13: 46059 | AI13: 63 | AJ13: VT 09.02 a 13.02 | AS13: 46058 | AT13: 2988.5 | AU13: DIÁRIAS 21.01 a 05.01 | AW13: 46045 | AX13: =250/2 -> 125 | AY13: TRABALHOU ATÉ 22H | AZ13: CLÍNICA DGM | BA13: 46062 | BB13: PAGO | BD13: 46052 | BE13: 60 | BF13: VT 02.02 a 06.02 | BO13: 46058 | BP13: 978 | BQ13: DIÁRIAS 21.01 a 05.02 | BT13: 100 | BU13: BONUS | BV13: GESPI - REFEITORIO | BW13: 46101 | BX13: PAGO | BZ13: 46057 | CA13: 26 | CB13: VT 31.01 e 01.02 | CV13: 46066 | CW13: 60 | CX13: VT 16.02 a 20.02 | DR13: 46080 | DS13: 65 | DT13: VT 02.03 a 06.03 | DV13: 46078 | DW13: 15 | DX13: VALE TRANSPORTE | DY13: GESPI - REFEITORIO | DZ13: 46077 | EA13: PAGO | EC13: 46098 | ED13: 50 | EE13: CAFÉ | EN13: 46086 | EO13: 65 | EP13: VT 09.03 a 13.03 | FJ13: 46101 | FK13: 50
A14: 46058 | B14: 2520 | C14: DIÁRIAS 21.01 a 05.02 | E14: 46037 | F14: 15 | G14: VALE TRANSPORTE | H14: GESPI - REFEITORIO | I14: 46042 | J14: PAGO | W14: 46059 | X14: 63 | Y14: VT 09.02 a 13.02 | AH14: 46066 | AI14: 63 | AJ14: VT 16.02 a 20.02 | AS14: 46059 | AT14: 60 | AU14: CAFÉ 09.02 a 13.02 | AW14: 46023 | AX14: 100 | AY14: LASER 7/12 | AZ14: ESCRITÓRIO | BA14: 46073 | BB14: PAGO | BD14: 46058 | BE14: 1208 | BF14: DIÁRIAS 21.01 a 05.02 | BO14: 46062 | BP14: 63 | BQ14: VT 09.02 a 13.02 | BS14: 46101 | BT14: 50 | BU14: LIMPEZA CARRO | BV14: ESCRITÓRIO | BW14: 46101 | BX14: PAGO | BZ14: 46058 | CA14: 1183 | CB14: DIÁRIAS 21.01 a 05.02 | CV14: 46073 | CW14: 781 | CX14: DIÁRIAS 06.02 a 20.02 | DR14: 46080 | DS14: 26 | DT14: VT 21.02 e 22.02 | DV14: 46079 | DW14: 15 | DX14: VALE TRANSPORTE | DY14: GESPI - REFEITORIO | DZ14: 46077 | EA14: PAGO | EC14: 46101 | ED14: 50 | EE14: CAFÉ | EN14: 46086 | EO14: 50 | EP14: CAFÉ 09.03 a 13.03
A15: 46059 | B15: 170 | C15: VT + VA 09.02 a 13.02 | E15: 46038 | F15: 15 | G15: VALE TRANSPORTE | H15: GESPI - REFEITORIO | I15: 46042 | J15: PAGO | W15: 46059 | X15: 50 | Y15: CAFÉ 09.02 a 13.02 | AH15: 46073 | AI15: 1984 | AJ15: DIÁRIAS 06.02 a 20.02 | AS15: 46071 | AT15: 30 | AU15: CAFÉ 18.02 a 20.02 | AW15: 46023 | AX15: 100 | AY15: LASER 8/12 | AZ15: ESCRITÓRIO | BA15: 46101 | BB15: PAGO | BD15: 46059 | BE15: 63 | BF15: VT 09.02 a 13.02 | BO15: 46059 | BP15: 50 | BQ15: CAFÉ 09.02 a 13.02 | BZ15: 46059 | CA15: 63 | CB15: VT 09.02 a 13.02 | CV15: 46073 | CW15: 50 | CX15: CAFÉ 24.02 a 27.02 | DR15: 46080 | DS15: 148 | DT15: Diária + Transporte 10.02 | DV15: 46080 | DW15: 15 | DX15: VALE TRANSPORTE | DY15: GESPI - REFEITORIO | DZ15: 46077 | EA15: PAGO | EC15: 46101 | ED15: 1320 | EE15: 11 DIÁRIAS | EN15: 46086 | EO15: 2400 | EP15: 13 DIÁRIAS
